Workbook

Sheet README
A1: ANTEPARO — CALL SHEET
A2: Run 20260903T230309Z-e5fb2e · generated 2026-09-03 · 54 leads ≥ R$200k · 17 pooling leads (R$100–200k) · 40 source documents · 32 cases
A4: WHAT EACH ROW IS
A5: One company × one recovery case. The company holds class III (trade) credit against the debtor, admitted in the court's own creditor list. All establishments of the company (same 8-digit CNPJ root) are summed.
A7: THE NUMBER
A8: 'Class III face' is the admitted value AS PRINTED in the court document — what the company is OWED, updated only to the filing date (art. 9 II). It is NOT what will be paid.
A9: 'OUR QUOTE' is a model: face → assumed plan terms → discounted at the investor IRR → fund price → our share. Edit the Assumptions tab. It is not court data.
A11: PROOF OF CLAIM (green columns)
A12: Click 'PROOF: source document', go to the page/row listed, and read the value as printed. If a seller asks 'how did you get this?', that link is the answer.
A13: 'Reconciled' = OK means the document's extracted class totals matched its own printed totals within 0.5%. OK_NO_TOTALS means the document prints no totals — the number was read from its own row but could not be cross-checked; quote with that caveat.
A15: DECISION-MAKER
A16: From the Receita Federal partner register (sócio-administrador / administrador / diretor / presidente). Phone and email are the company's registry contact. Confidence LOW = registry only; nothing here was guessed or looked up from memory.
... A22: Individuals (CPF), banks (CNAE 64–66), public entities, inactive companies, foreign-currency claims, extraconcursal sections, quarantined documents. They remain in the CSV tables with flags.

Sheet Assumptions
A1: PRICING ASSUMPTIONS — edit the yellow cells; every quote on the call sheet recalculates
A3: Target investor IRR (annual) | B3: 0.25 | F3: Fund price = face × recovery% ÷ (1+IRR)^(years to payment). A fund needing 25% IRR on a plan paying 30% over years 3–10 pays ~8 cents, not 25 — check the 7 buyers' real numbers against this.
A4: Buy price as share of fund price (we pay 60% → 0.60) | B4: 0.6 | F4: Our quote = fund price × this share. The doc rule is 60% of mandate price; expected 55–70% once Gate 6 data exists.
A6: Plan status | B6: Class III recovery % of face | C6: Grace (years) | D6: Term (years) | E6: Note
A7: CONFIRMED | B7: 0.4 | C7: 2 | D7: 8 | E7: A plan/homologation document exists for the case. ASSUMED terms until plan parsing lands — replace with the plan's own class III terms.
A8: ESTIMATED | B8: 0.3 | C8: 2 | D8: 8 | E8: No plan document found; case is live in DataJud. ASSUMED typical Brazilian class III terms.
A9: UNKNOWN | B9: 0.25 | C9: 3 | D9: 8 | E9: Case not matched to DataJud. ASSUMED, conservative.
A10: CONVERTED_TO_BANKRUPTCY | B10: 0.05 | C10: 4 | D10: 4 | E10: Falência decreed. Class III ranks behind labour and secured; assume near-zero.
A13: Everything in this tab is an ASSUMPTION, not court data. The face value on the call sheet IS court data — it links to the page.

Sheet Call List
A1: Rank | B1: Status | C1: Owner | D1: Attempts | E1: Last touch | F1: Next action | G1: Next date | H1: Notes | I1: Company (RFB) | J1: Name as printed | K1: CNPJ root | L1: Establishment CNPJs | M1: Class III face (R$) | N1: Claims | O1: Plan status | P1: Stage | Q1: Case filed | R1: Years since filing | S1: Est. recovery % | T1: Years to payment (est.) | U1: Fund price @ IRR (R$) | V1: Fund price (cents) | W1: OUR QUOTE (R$) | X1: Quote (cents) | Y1: Debtor | Z1: Case number | AA1: Court | AB1: Administrator (site) | AC1: Decision-maker | AD1: Role | AE1: Phone | AF1: Phone 2 | AG1: Email | AH1: UF | AI1: City | AJ1: CNAE | AK1: Porte | AL1: Situação | AM1: PROOF: source document | AN1: Page / row | AO1: Value as printed | AP1: Which list | AQ1: Published | AR1: Reconciled | AS1: Data flags | AT1: Doc id
A2: 1 | B2: NEW | D2: 0 | I2: TAG INDUSTRIA E LAMINACAO LTDA | J2: TAG INDUSTRIA E LAMINACAO LTDA | K2: 33233778 | L2: 33233778000108 | M2: 64713515 | N2: 2 | O2: UNKNOWN | R2: =IF(Q2="","",ROUND((TODAY()-Q2)/365.25,1)) | S2: =VLOOKUP(O2,Assumptions!$A$7:$E$10,2,FALSE) | T2: =MAX(0.5,VLOOKUP(O2,Assumptions!$A$7:$E$10,3,FALSE)+VLOOKUP(O2,Assumptions!$A$7:$E$10,4,FALSE)/2-IF(R2="",0,R2)) | U2: =M2*S2/(1+Assumptions!$B$3)^T2 | V2: =IF(M2=0,"",ROUND(U2/M2*100,1)) | W2: =U2*Assumptions!$B$4 | X2: =IF(M2=0,"",ROUND(W2/M2*100,1)) | Y2: Conduscabos Brasil Indústria Comércio de | Z2: 8005129-09.2023.8.05.0039 | AB2: assistjud.com.br | AC2: TIAGO RODRIGO DETTILIO | AD2: Administrador | AE2: (11) 4463-4833 | AH2: SP | AI2: SAO PAULO | AJ2: Outras atividades profissionais, científicas e técnicas não especificadas anteriormente | AK2: DEMAIS | AL2: ATIVA | AM2: https://assistjud.com.br/wp-content/uploads/elementor/forms/65098c80a5824.pdf | AN2: p10 r4; p19 r8 | AO2: p10: R$ 32.731.819,08; p19: R$ 31.981.695,98 | AP2: AJ_LIST | AQ2: 2023-09-18 | AR2: OK_NO_TOTALS | AS2: ROWS:p10r4,p19r8 UNRECONCILED_SOURCE | AT2: a0ae32a59c29
A3: 2 | B3: NEW | D3: 0 | J3: FUNDO DE INVESTIMENTO EM DIREITOS CREDITÓRIOS NÃO PADRONIZADOS MULTISSETORIA L BS NP | K3: 12428086 | L3: 12428086000137 | M3: 14857605 | N3: 3 | O3: UNKNOWN | R3: =IF(Q3="","",ROUND((TODAY()-Q3)/365.25,1)) | S3: =VLOOKUP(O3,Assumptions!$A$7:$E$10,2,FALSE) | T3: =MAX(0.5,VLOOKUP(O3,Assumptions!$A$7:$E$10,3,FALSE)+VLOOKUP(O3,Assumptions!$A$7:$E$10,4,FALSE)/2-IF(R3="",0,R3)) | U3: =M3*S3/(1+Assumptions!$B$3)^T3 | V3: =IF(M3=0,"",ROUND(U3/M3*100,1)) | W3: =U3*Assumptions!$B$4 | X3: =IF(M3=0,"",ROUND(W3/M3*100,1)) | Y3: Conduscabos Brasil Indústria Comércio de | Z3: 8005129-09.2023.8.05.0039 | AB3: assistjud.com.br | AM3: https://assistjud.com.br/wp-content/uploads/elementor/forms/65098c80a5824.pdf | AN3: p7 r8; p10 r1; p18 r2 | AO3: p7: R$ 10.954.112,61; p10: R$ 1.455.516,44; p18: R$ 2.447.975,63 | AP3: AJ_LIST | AQ3: 2023-09-18 | AR3: OK_NO_TOTALS | AS3: ROWS:p7r8,p10r1,p18r2 UNRECONCILED_SOURCE | AT3: a0ae32a59c29
A4: 3 | B4: NEW | D4: 0 | I4: FRESENIUS MEDICAL CARE LTDA | J4: FRESENIUS MEDICAL CARE LTDA | K4: 01440590 | L4: 01440590000136 | M4: 14567734 | N4: 1 | O4: UNKNOWN | R4: =IF(Q4="","",ROUND((TODAY()-Q4)/365.25,1)) | S4: =VLOOKUP(O4,Assumptions!$A$7:$E$10,2,FALSE) | T4: =MAX(0.5,VLOOKUP(O4,Assumptions!$A$7:$E$10,3,FALSE)+VLOOKUP(O4,Assumptions!$A$7:$E$10,4,FALSE)/2-IF(R4="",0,R4)) | U4: =M4*S4/(1+Assumptions!$B$3)^T4 | V4: =IF(M4=0,"",ROUND(U4/M4*100,1)) | W4: =U4*Assumptions!$B$4 | X4: =IF(M4=0,"",ROUND(W4/M4*100,1)) | Z4: (not found in document) | AB4: bernardobicalho.com.br | AC4: ANA LUCIA ZENKNER PERCIA | AD4: Administrador | AE4: (19) 3847-9700 | AF4: (19) 3847-9700 | AH4: SP | AI4: JAGUARIUNA | AJ4: Fabricação de medicamentos alopáticos para uso humano | AK4: DEMAIS | AL4: ATIVA | AM4: http://bernardobicalho.com.br/login/app/documents/Rela%C3%A7%C3%A3o%20de%20Credores/6.%20RVC-%20Nutricium%20-%20simplificada.pdf | AN4: p3 r16 | AO4: p3: R$ 14.567.733,99 | AP4: AJ_LIST | AR4: OK | AS4: CASE_NUMBER_MISSING ROWS:p3r16 | AT4: 6a92d74da333
A5: 4 | B5: NEW | D5: 0 | I5: VINICOLA CAMPESTRE LTDA | J5: VINICOLA CAMPESTRE LTDA | K5: 98521909 | L5: 98521909000190, 98521909000270 | M5: 13980346 | N5: 2 | O5: UNKNOWN | R5: =IF(Q5="","",ROUND((TODAY()-Q5)/365.25,1)) | S5: =VLOOKUP(O5,Assumptions!$A$7:$E$10,2,FALSE) | T5: =MAX(0.5,VLOOKUP(O5,Assumptions!$A$7:$E$10,3,FALSE)+VLOOKUP(O5,Assumptions!$A$7:$E$10,4,FALSE)/2-IF(R5="",0,R5)) | U5: =M5*S5/(1+Assumptions!$B$3)^T5 | V5: =IF(M5=0,"",ROUND(U5/M5*100,1)) | W5: =U5*Assumptions!$B$4 | X5: =IF(M5=0,"",ROUND(W5/M5*100,1)) | Y5: ARRUDA & MELO COMERCIO E DISTRIBUICAO DE ALIMENTOS E BEBIDAS LTDA | Z5: 0008526-45.2025.8.17.2001 | AB5: diligence.adm.br | AC5: CESAR AUGUSTO ZANOTTO | AD5: Sócio-Administrador | AE5: (54) 3511-6050 | AF5: (54) 3511-6052 | AH5: RS | AI5: CAMPESTRE DA SERRA | AJ5: Fabricação de vinho | AK5: DEMAIS | AL5: ATIVA | AM5: https://diligence.adm.br/wp-content/uploads/2025/06/Edital-1a-Lista-de-Credores.pdf | AN5: p5 r60; p5 r61 | AO5: p5: R$ 4.421.862,65; p5: R$ 9.558.482,85 | AP5: DEBTOR_LIST | AQ5: 2025-06-10 | AR5: OK | AS5: ROWS:p5r60,p5r61 | AT5: 1658892fa167
A6: 5 | B6: NEW | D6: 0 | I6: ALBAUGH AGRO BRASIL LTDA. | J6: ALBAUGH AGRO BRASIL LTDA | K6: 01789121 | L6: 01789121000470, 01789121000984, 01789121001107 | M6: 11525550 | N6: 1 | O6: UNKNOWN | R6: =IF(Q6="","",ROUND((TODAY()-Q6)/365.25,1)) | S6: =VLOOKUP(O6,Assumptions!$A$7:$E$10,2,FALSE) | T6: =MAX(0.5,VLOOKUP(O6,Assumptions!$A$7:$E$10,3,FALSE)+VLOOKUP(O6,Assumptions!$A$7:$E$10,4,FALSE)/2-IF(R6="",0,R6)) | U6: =M6*S6/(1+Assumptions!$B$3)^T6 | V6: =IF(M6=0,"",ROUND(U6/M6*100,1)) | W6: =U6*Assumptions!$B$4 | X6: =IF(M6=0,"",ROUND(W6/M6*100,1)) | Y6: SOJAL COMERCIAL AGRICOLA | Z6: 0804401-51.2025.8.14.0039 | AB6: lrflideres.com.br | AC6: CESAR EMILIANO ROJAS RUIZ | AD6: Administrador | AE6: (11) 3076-4243 | AH6: SP | AI6: SAO PAULO | AJ6: Fabricação de defensivos agrícolas | AK6: DEMAIS | AL6: ATIVA | AM6: https://lrflideres.com.br/wp-content/plugins/download-attachments/includes/download.php?id=6879 | AN6: p1 r4 | AO6: p1: R$ 11.525.550,26 | AP6: AJ_LIST | AQ6: 2026-01-15 | AR6: OK | AS6: ROWS:p1r4 | AT6: c56751547323
A7: 6 | B7: NEW | D7: 0 | I7: ADDIANTE S.A | J7: ADDIANTE S.A | K7: 48430290 | L7: 48430290000130 | M7: 7135517 | N7: 1 | O7: UNKNOWN | R7: =IF(Q7="","",ROUND((TODAY()-Q7)/365.25,1)) | S7: =VLOOKUP(O7,Assumptions!$A$7:$E$10,2,FALSE) | T7: =MAX(0.5,VLOOKUP(O7,Assumptions!$A$7:$E$10,3,FALSE)+VLOOKUP(O7,Assumptions!$A$7:$E$10,4,FALSE)/2-IF(R7="",0,R7)) | U7: =M7*S7/(1+Assumptions!$B$3)^T7 | V7: =IF(M7=0,"",ROUND(U7/M7*100,1)) | W7: =U7*Assumptions!$B$4 | X7: =IF(M7=0,"",ROUND(W7/M7*100,1)) | Y7: SOJAL COMERCIAL AGRICOLA | Z7: 0804401-51.2025.8.14.0039 | AB7: lrflideres.com.br | AC7: FABIO ROBERTO LEITE | AD7: Presidente | AE7: (41) 9571-0152 | AH7: PR | AI7: CURITIBA | AJ7: Locação de outros meios de transporte não especificados anteriormente, sem condutor | AK7: DEMAIS | AL7: ATIVA | AM7: https://lrflideres.com.br/wp-content/plugins/download-attachments/includes/download.php?id=6879 | AN7: p1 r2 | AO7: p1: R$ 7.135.516,97 | AP7: AJ_LIST | AQ7: 2026-01-15 | AR7: OK | AS7: ROWS:p1r2 | AT7: c56751547323
A8: 7 | B8: NEW | D8: 0 | I8: SOLUS DO BRASIL LTDA | J8: SOLUS INDUSTRIA QUIMICA LTDA | K8: 21203489 | L8: 21203489000764, 21203489000926 | M8: 7058181.5 | N8: 1 | O8: UNKNOWN | R8: =IF(Q8="","",ROUND((TODAY()-Q8)/365.25,1)) | S8: =VLOOKUP(O8,Assumptions!$A$7:$E$10,2,FALSE) | T8: =MAX(0.5,VLOOKUP(O8,Assumptions!$A$7:$E$10,3,FALSE)+VLOOKUP(O8,Assumptions!$A$7:$E$10,4,FALSE)/2-IF(R8="",0,R8)) | U8: =M8*S8/(1+Assumptions!$B$3)^T8 | V8: =IF(M8=0,"",ROUND(U8/M8*100,1)) | W8: =U8*Assumptions!$B$4 | X8: =IF(M8=0,"",ROUND(W8/M8*100,1)) | Y8: SOJAL COMERCIAL AGRICOLA | Z8: 0804401-51.2025.8.14.0039 | AB8: lrflideres.com.br | AC8: ANDERSON JOSE FAUSTINO | AD8: Administrador | AE8: (43) 3162-2715 | AH8: PR | AI8: APUCARANA | AJ8: Fabricação de defensivos agrícolas | AK8: DEMAIS | AL8: ATIVA | AM8: https://lrflideres.com.br/wp-content/plugins/download-attachments/includes/download.php?id=6879 | AN8: p2 r10 | AO8: p2: R$ 7.058.181,50 | AP8: AJ_LIST | AQ8: 2026-01-15 | AR8: OK | AS8: ROWS:p2r10 | AT8: c56751547323
A9: 8 | B9: NEW | D9: 0 | I9: NORTESUL COMERCIAL AGRICOLA LTDA EM RECUPERACAO JUDICIAL | J9: NORTESUL COMERCIAL AGRICOLA LTDA | K9: 15626673 | L9: 15626673000129, 15626673000390, 15626673000552 | M9: 6258845.3 | N9: 1 | O9: UNKNOWN | R9: =IF(Q9="","",ROUND((TODAY()-Q9)/365.25,1)) | S9: =VLOOKUP(O9,Assumptions!$A$7:$E$10,2,FALSE) | T9: =MAX(0.5,VLOOKUP(O9,Assumptions!$A$7:$E$10,3,FALSE)+VLOOKUP(O9,Assumptions!$A$7:$E$10,4,FALSE)/2-IF(R9="",0,R9)) | U9: =M9*S9/(1+Assumptions!$B$3)^T9 | V9: =IF(M9=0,"",ROUND(U9/M9*100,1)) | W9: =U9*Assumptions!$B$4 | X9: =IF(M9=0,"",ROUND(W9/M9*100,1)) | Y9: SOJAL COMERCIAL AGRICOLA | Z9: 0804401-51.2025.8.14.0039 | AB9: lrflideres.com.br | AC9: JULIANO MENDES DOS SANTOS | AD9: Sócio-Administrador | AE9: (63) 3602-4239 | AH9: TO | AI9: PALMAS | AJ9: Comércio atacadista de matérias-primas agrícolas não especificadas anteriormente | AK9: DEMAIS | AL9: ATIVA | AM9: https://lrflideres.com.br/wp-content/plugins/download-attachments/includes/download.php?id=6879 | AN9: p2 r5 | AO9: p2: R$ 6.258.845,34 | AP9: AJ_LIST | AQ9: 2026-01-15 | AR9: OK | AS9: ROWS:p2r5 | AT9: c56751547323
A10: 9 | B10: NEW | D10: 0 | J10: FARM TECH IBBA I FIDC | K10: 47151680 | L10: 31652424000164, 47151680000108 | M10: 5767665.6 | N10: 1 | O10: UNKNOWN | R10: =IF(Q10="","",ROUND((TODAY()-Q10)/365.25,1)) | S10: =VLOOKUP(O10,Assumptions!$A$7:$E$10,2,FALSE) | T10: =MAX(0.5,VLOOKUP(O10,Assumptions!$A$7:$E$10,3,FALSE)+VLOOKUP(O10,Assumptions!$A$7:$E$10,4,FALSE)/2-IF(R10="",0,R10)) | U10: =M10*S10/(1+Assumptions!$B$3)^T10 | V10: =IF(M10=0,"",ROUND(U10/M10*100,1)) | W10: =U10*Assumptions!$B$4 | X10: =IF(M10=0,"",ROUND(W10/M10*100,1)) | Y10: SOJAL COMERCIAL AGRICOLA | Z10: 0804401-51.2025.8.14.0039 | AB10: lrflideres.com.br | AM10: https://lrflideres.com.br/wp-content/plugins/download-attachments/includes/download.php?id=6879 | AN10: p1 r13 | AO10: p1: R$ 5.767.665,60 | AP10: AJ_LIST | AQ10: 2026-01-15 | AR10: OK | AS10: MULTI_ROOT ROWS:p1r13 | AT10: c56751547323
A11: 10 | B11: NEW | D11: 0 | I11: JF PASQUA CONDUTORES ELETRICOS LTDA | J11: JF PASQUA CONDUTORES ELETRICOS LTDA | K11: 03981899 | L11: 03981899000169 | M11: 4940520.9 | N11: 2 | O11: UNKNOWN | R11: =IF(Q11="","",ROUND((TODAY()-Q11)/365.25,1)) | S11: =VLOOKUP(O11,Assumptions!$A$7:$E$10,2,FALSE) | T11: =MAX(0.5,VLOOKUP(O11,Assumptions!$A$7:$E$10,3,FALSE)+VLOOKUP(O11,Assumptions!$A$7:$E$10,4,FALSE)/2-IF(R11="",0,R11)) | U11: =M11*S11/(1+Assumptions!$B$3)^T11 | V11: =IF(M11=0,"",ROUND(U11/M11*100,1)) | W11: =U11*Assumptions!$B$4 | X11: =IF(M11=0,"",ROUND(W11/M11*100,1)) | Y11: Conduscabos Brasil Indústria Comércio de | Z11: 8005129-09.2023.8.05.0039 | AB11: assistjud.com.br | AC11: REGINA MARIA PASQUA SANTOS | AD11: Administrador | AE11: (35) 3559-6789 | AH11: MG | AI11: GUAXUPE | AJ11: Metalurgia do cobre | AK11: DEMAIS | AL11: ATIVA | AM11: https://assistjud.com.br/wp-content/uploads/elementor/forms/65098c80a5824.pdf | AN11: p8 r4; p18 r6 | AO11: p8: R$ 2.217.364,91; p18: R$ 2.723.156,00 | AP11: AJ_LIST | AQ11: 2023-09-18 | AR11: OK_NO_TOTALS | AS11: ROWS:p8r4,p18r6 UNRECONCILED_SOURCE | AT11: a0ae32a59c29
A12: 11 | B12: NEW | D12: 0 | I12: COMPANHIA DE AGUA E ESGOTOS DA PARAIBA CAGEPA | J12: COMPANHIA DE ÁGUA E ESGOTOS DA PARAIBA CAGEPA | K12: 09123654 | L12: 09123654000187 | M12: 3641949.7 | N12: 1 | O12: UNKNOWN | R12: =IF(Q12="","",ROUND((TODAY()-Q12)/365.25,1)) | S12: =VLOOKUP(O12,Assumptions!$A$7:$E$10,2,FALSE) | T12: =MAX(0.5,VLOOKUP(O12,Assumptions!$A$7:$E$10,3,FALSE)+VLOOKUP(O12,Assumptions!$A$7:$E$10,4,FALSE)/2-IF(R12="",0,R12)) | U12: =M12*S12/(1+Assumptions!$B$3)^T12 | V12: =IF(M12=0,"",ROUND(U12/M12*100,1)) | W12: =U12*Assumptions!$B$4 | X12: =IF(M12=0,"",ROUND(W12/M12*100,1)) | Y12: DR. ALLAN DE QUEIROZ RAMOS – OAB/PB 20.574 | Z12: 0829315-43.2023.8.15.0001 | AB12: lrflideres.com.br | AC12: MARCUS VINICIUS FERNANDES NEVES | AD12: Presidente | AE12: (83) 3218-1200 | AF12: (83) 3218-1225 | AH12: PB | AI12: JOAO PESSOA | AJ12: Captação, tratamento e distribuição de água | AK12: DEMAIS | AL12: ATIVA | AM12: https://lrflideres.com.br/wp-content/plugins/download-attachments/includes/download.php?id=5828 | AN12: p3 r16 | AO12: p3: R$ 3.641.949,67 | AP12: AJ_LIST | AQ12: 2024-04-18 | AR12: OK | AS12: ROWS:p3r16 | AT12: 47e92e4db6f8
A13: 12 | B13: NEW | D13: 0 | I13: VEGETAL AGRONEGOCIOS LTDA | J13: VEGETAL AGRONEGOCIOS LTDA | K13: 05429994 | L13: 05429994001313 | M13: 3014807.2 | N13: 1 | O13: UNKNOWN | R13: =IF(Q13="","",ROUND((TODAY()-Q13)/365.25,1)) | S13: =VLOOKUP(O13,Assumptions!$A$7:$E$10,2,FALSE) | T13: =MAX(0.5,VLOOKUP(O13,Assumptions!$A$7:$E$10,3,FALSE)+VLOOKUP(O13,Assumptions!$A$7:$E$10,4,FALSE)/2-IF(R13="",0,R13)) | U13: =M13*S13/(1+Assumptions!$B$3)^T13 | V13: =IF(M13=0,"",ROUND(U13/M13*100,1)) | W13: =U13*Assumptions!$B$4 | X13: =IF(M13=0,"",ROUND(W13/M13*100,1)) | Y13: SOJAL COMERCIAL AGRICOLA | Z13: 0804401-51.2025.8.14.0039 | AB13: lrflideres.com.br | AC13: ALDAIR REMUSSI | AD13: Sócio-Administrador | AE13: (61) 3234-8485 | AH13: DF | AI13: BRASILIA | AJ13: Comércio atacadista de defensivos agrícolas, adubos, fertilizantes e corretivos do solo | AK13: DEMAIS | AL13: ATIVA | AM13: https://lrflideres.com.br/wp-content/plugins/download-attachments/includes/download.php?id=6879 | AN13: p2 r13 | AO13: p2: R$ 3.014.807,20 | AP13: AJ_LIST | AQ13: 2026-01-15 | AR13: OK | AS13: ROWS:p2r13 | AT13: c56751547323
A14: 13 | B14: NEW | D14: 0 | I14: CROMO INDUSTRIA QUIMICA S.A. | J14: CROMO INDUSTRIA QUIMICA S.A | K14: 31281962 | L14: 31281962000190, 31281962000270 | M14: 2406485.6 | N14: 1 | O14: UNKNOWN | R14: =IF(Q14="","",ROUND((TODAY()-Q14)/365.25,1)) | S14: =VLOOKUP(O14,Assumptions!$A$7:$E$10,2,FALSE) | T14: =MAX(0.5,VLOOKUP(O14,Assumptions!$A$7:$E$10,3,FALSE)+VLOOKUP(O14,Assumptions!$A$7:$E$10,4,FALSE)/2-IF(R14="",0,R14)) | U14: =M14*S14/(1+Assumptions!$B$3)^T14 | V14: =IF(M14=0,"",ROUND(U14/M14*100,1)) | W14: =U14*Assumptions!$B$4 | X14: =IF(M14=0,"",ROUND(W14/M14*100,1)) | Y14: SOJAL COMERCIAL AGRICOLA | Z14: 0804401-51.2025.8.14.0039 | AB14: lrflideres.com.br | AC14: JOSIR NEULS | AD14: Presidente | AE14: (11) 4130-8138 | AH14: RS | AI14: ESTRELA | AJ14: Fabricação de outros produtos químicos não especificados anteriormente | AK14: DEMAIS | AL14: ATIVA | AM14: https://lrflideres.com.br/wp-content/plugins/download-attachments/includes/download.php?id=6879 | AN14: p1 r11 | AO14: p1: R$ 2.406.485,64 | AP14: AJ_LIST | AQ14: 2026-01-15 | AR14: OK | AS14: ROWS:p1r11 | AT14: c56751547323
A15: 14 | B15: NEW | D15: 0 | J15: GAVEA FIDC | K15: 12910431 | L15: 12910431000174 | M15: 2327494.5 | N15: 3 | O15: UNKNOWN | R15: =IF(Q15="","",ROUND((TODAY()-Q15)/365.25,1)) | S15: =VLOOKUP(O15,Assumptions!$A$7:$E$10,2,FALSE) | T15: =MAX(0.5,VLOOKUP(O15,Assumptions!$A$7:$E$10,3,FALSE)+VLOOKUP(O15,Assumptions!$A$7:$E$10,4,FALSE)/2-IF(R15="",0,R15)) | U15: =M15*S15/(1+Assumptions!$B$3)^T15 | V15: =IF(M15=0,"",ROUND(U15/M15*100,1)) | W15: =U15*Assumptions!$B$4 | X15: =IF(M15=0,"",ROUND(W15/M15*100,1)) | Y15: Conduscabos Brasil Indústria Comércio de | Z15: 8005129-09.2023.8.05.0039 | AB15: assistjud.com.br | AM15: https://assistjud.com.br/wp-content/uploads/elementor/forms/65098c80a5824.pdf | AN15: p7 r9; p8 r18; p9 r15 | AO15: p7: R$ 775.620,94; p8: R$ 462.653,52; p9: R$ 1.089.220,04 | AP15: AJ_LIST | AQ15: 2023-09-18 | AR15: OK_NO_TOTALS | AS15: ROWS:p7r9,p8r18,p9r15 UNRECONCILED_SOURCE | AT15: a0ae32a59c29
A16: 15 | B16: NEW | D16: 0 | J16: BANCO INDUSTRIAL DO BRASIL S/A | K16: 31895683 | L16: 31895683000116 | M16: 2056998.2 | N16: 2 | O16: UNKNOWN | R16: =IF(Q16="","",ROUND((TODAY()-Q16)/365.25,1)) | S16: =VLOOKUP(O16,Assumptions!$A$7:$E$10,2,FALSE) | T16: =MAX(0.5,VLOOKUP(O16,Assumptions!$A$7:$E$10,3,FALSE)+VLOOKUP(O16,Assumptions!$A$7:$E$10,4,FALSE)/2-IF(R16="",0,R16)) | U16: =M16*S16/(1+Assumptions!$B$3)^T16 | V16: =IF(M16=0,"",ROUND(U16/M16*100,1)) | W16: =U16*Assumptions!$B$4 | X16: =IF(M16=0,"",ROUND(W16/M16*100,1)) | Y16: Conduscabos Brasil Indústria Comércio de | Z16: 8005129-09.2023.8.05.0039 | AB16: assistjud.com.br | AM16: https://assistjud.com.br/wp-content/uploads/elementor/forms/65098c80a5824.pdf | AN16: p5 r11; p17 r5 | AO16: p5: R$ 1.047.741,53; p17: R$ 1.009.256,67 | AP16: AJ_LIST | AQ16: 2023-09-18 | AR16: OK_NO_TOTALS | AS16: ROWS:p5r11,p17r5 UNRECONCILED_SOURCE VALUE_COL:Valor_Do_Crédito_2º_Edital_De_Credores | AT16: a0ae32a59c29
A17: 16 | B17: NEW | D17: 0 | I17: SEMPRE AGTECH LTDA | J17: SEMPRE AGTECH LTDA | K17: 09536120 | L17: 09536120000263 | M17: 2037617 | N17: 1 | O17: UNKNOWN | R17: =IF(Q17="","",ROUND((TODAY()-Q17)/365.25,1)) | S17: =VLOOKUP(O17,Assumptions!$A$7:$E$10,2,FALSE) | T17: =MAX(0.5,VLOOKUP(O17,Assumptions!$A$7:$E$10,3,FALSE)+VLOOKUP(O17,Assumptions!$A$7:$E$10,4,FALSE)/2-IF(R17="",0,R17)) | U17: =M17*S17/(1+Assumptions!$B$3)^T17 | V17: =IF(M17=0,"",ROUND(U17/M17*100,1)) | W17: =U17*Assumptions!$B$4 | X17: =IF(M17=0,"",ROUND(W17/M17*100,1)) | Y17: SOJAL COMERCIAL AGRICOLA | Z17: 0804401-51.2025.8.14.0039 | AB17: lrflideres.com.br | AC17: FERNANDO JOAO PREZZOTTO | AD17: Sócio-Administrador | AE17: (49) 3441-8200 | AH17: SC | AI17: CHAPECO | AJ17: Produção de sementes certificadas, exceto de forrageiras para pasto | AK17: DEMAIS | AL17: ATIVA | AM17: https://lrflideres.com.br/wp-content/plugins/download-attachments/includes/download.php?id=6879 | AN17: p2 r7 | AO17: p2: R$ 2.037.616,99 | AP17: AJ_LIST | AQ17: 2026-01-15 | AR17: OK | AS17: ROWS:p2r7 | AT17: c56751547323
A18: 17 | B18: NEW | D18: 0 | I18: FERTILIZANTES TOCANTINS S.A | J18: FERTILIZANTES TOCANTINS S.A | K18: 05571228 | L18: 05571228000155 | M18: 2016948.6 | N18: 1 | O18: UNKNOWN | R18: =IF(Q18="","",ROUND((TODAY()-Q18)/365.25,1)) | S18: =VLOOKUP(O18,Assumptions!$A$7:$E$10,2,FALSE) | T18: =MAX(0.5,VLOOKUP(O18,Assumptions!$A$7:$E$10,3,FALSE)+VLOOKUP(O18,Assumptions!$A$7:$E$10,4,FALSE)/2-IF(R18="",0,R18)) | U18: =M18*S18/(1+Assumptions!$B$3)^T18 | V18: =IF(M18=0,"",ROUND(U18/M18*100,1)) | W18: =U18*Assumptions!$B$4 | X18: =IF(M18=0,"",ROUND(W18/M18*100,1)) | Y18: SOJAL COMERCIAL AGRICOLA | Z18: 0804401-51.2025.8.14.0039 | AB18: lrflideres.com.br | AC18: DMITRY CHERNYKH | AD18: Presidente | AE18: (62) 3414-6300 | AH18: TO | AI18: PORTO NACIONAL | AJ18: Fabricação de adubos e fertilizantes, exceto organo-minerais | AK18: DEMAIS | AL18: ATIVA | AM18: https://lrflideres.com.br/wp-content/plugins/download-attachments/includes/download.php?id=6879 | AN18: p2 r1 | AO18: p2: R$ 2.016.948,56 | AP18: AJ_LIST | AQ18: 2026-01-15 | AR18: OK | AS18: ROWS:p2r1 | AT18: c56751547323
A19: 18 | B19: NEW | D19: 0 | I19: REICHENBACH EQUIPAMENTOS INDUSTRIA E COMERCIO LTDA | J19: REICHENBACH EQUIP IND.COM. LTDA | K19: 71799001 | L19: 71799001000196 | M19: 2002544.3 | N19: 1 | O19: UNKNOWN | R19: =IF(Q19="","",ROUND((TODAY()-Q19)/365.25,1)) | S19: =VLOOKUP(O19,Assumptions!$A$7:$E$10,2,FALSE) | T19: =MAX(0.5,VLOOKUP(O19,Assumptions!$A$7:$E$10,3,FALSE)+VLOOKUP(O19,Assumptions!$A$7:$E$10,4,FALSE)/2-IF(R19="",0,R19)) | U19: =M19*S19/(1+Assumptions!$B$3)^T19 | V19: =IF(M19=0,"",ROUND(U19/M19*100,1)) | W19: =U19*Assumptions!$B$4 | X19: =IF(M19=0,"",ROUND(W19/M19*100,1)) | Y19: Conduscabos Brasil Indústria Comércio de | Z19: 8005129-09.2023.8.05.0039 | AB19: assistjud.com.br | AC19: ALLAN WERNER REICHENBACH | AD19: Sócio-Administrador | AE19: (11) 4181-5054 | AH19: SP | AI19: CARAPICUIBA | AJ19: Fabricação de outras máquinas e equipamentos de uso geral não especificados anteriormente, peças e acessórios | AK19: DEMAIS | AL19: ATIVA | AM19: https://assistjud.com.br/wp-content/uploads/elementor/forms/65098c80a5824.pdf | AN19: p19 r6 | AO19: p19: R$ 2.002.544,34 | AP19: AJ_LIST | AQ19: 2023-09-18 | AR19: OK_NO_TOTALS | AS19: ROWS:p19r6 UNRECONCILED_SOURCE | AT19: a0ae32a59c29
A20: 19 | B20: NEW | D20: 0 | J20: URA AGRO FUNDO DE INVESTIMENTO EM DIREIT | K20: 25382606 | L20: 25382606000160 | M20: 1849551 | N20: 1 | O20: UNKNOWN | R20: =IF(Q20="","",ROUND((TODAY()-Q20)/365.25,1)) | S20: =VLOOKUP(O20,Assumptions!$A$7:$E$10,2,FALSE) | T20: =MAX(0.5,VLOOKUP(O20,Assumptions!$A$7:$E$10,3,FALSE)+VLOOKUP(O20,Assumptions!$A$7:$E$10,4,FALSE)/2-IF(R20="",0,R20)) | U20: =M20*S20/(1+Assumptions!$B$3)^T20 | V20: =IF(M20=0,"",ROUND(U20/M20*100,1)) | W20: =U20*Assumptions!$B$4 | X20: =IF(M20=0,"",ROUND(W20/M20*100,1)) | Y20: SOJAL COMERCIAL AGRICOLA | Z20: 0804401-51.2025.8.14.0039 | AB20: lrflideres.com.br | AM20: https://lrflideres.com.br/wp-content/plugins/download-attachments/includes/download.php?id=6879 | AN20: p2 r12 | AO20: p2: R$ 1.849.550,98 | AP20: AJ_LIST | AQ20: 2026-01-15 | AR20: OK | AS20: ROWS:p2r12 | AT20: c56751547323
A21: 20 | B21: NEW | D21: 0 | J21: RED FIDC | K21: 08632394 | L21: 08632394000102 | M21: 1841470 | N21: 2 | O21: UNKNOWN | R21: =IF(Q21="","",ROUND((TODAY()-Q21)/365.25,1)) | S21: =VLOOKUP(O21,Assumptions!$A$7:$E$10,2,FALSE) | T21: =MAX(0.5,VLOOKUP(O21,Assumptions!$A$7:$E$10,3,FALSE)+VLOOKUP(O21,Assumptions!$A$7:$E$10,4,FALSE)/2-IF(R21="",0,R21)) | U21: =M21*S21/(1+Assumptions!$B$3)^T21 | V21: =IF(M21=0,"",ROUND(U21/M21*100,1)) | W21: =U21*Assumptions!$B$4 | X21: =IF(M21=0,"",ROUND(W21/M21*100,1)) | Y21: Conduscabos Brasil Indústria Comércio de | Z21: 8005129-09.2023.8.05.0039 | AB21: assistjud.com.br | AM21: https://assistjud.com.br/wp-content/uploads/elementor/forms/65098c80a5824.pdf | AN21: p9 r10; p19 r5 | AO21: p9: R$ 1.565.337,07; p19: R$ 276.132,92 | AP21: AJ_LIST | AQ21: 2023-09-18 | AR21: OK_NO_TOTALS | AS21: ROWS:p9r10,p19r5 UNRECONCILED_SOURCE | AT21: a0ae32a59c29
A22: 21 | B22: NEW | D22: 0 | I22: DACARTO INDUSTRIA E COMERCIO DE PLASTICOS LTDA | J22: DACARTO BENVIC LTDA | K22: 62143847 | L22: 62143847000182, 62143847000263 | M22: 1624039.2 | N22: 2 | O22: UNKNOWN | R22: =IF(Q22="","",ROUND((TODAY()-Q22)/365.25,1)) | S22: =VLOOKUP(O22,Assumptions!$A$7:$E$10,2,FALSE) | T22: =MAX(0.5,VLOOKUP(O22,Assumptions!$A$7:$E$10,3,FALSE)+VLOOKUP(O22,Assumptions!$A$7:$E$10,4,FALSE)/2-IF(R22="",0,R22)) | U22: =M22*S22/(1+Assumptions!$B$3)^T22 | V22: =IF(M22=0,"",ROUND(U22/M22*100,1)) | W22: =U22*Assumptions!$B$4 | X22: =IF(M22=0,"",ROUND(W22/M22*100,1)) | Y22: Conduscabos Brasil Indústria Comércio de | Z22: 8005129-09.2023.8.05.0039 | AB22: assistjud.com.br | AC22: AMILTON DAL POZ DE ALMEIDA | AD22: Administrador | AE22: (11) 3658-9459 | AH22: SP | AI22: OSASCO | AJ22: Fabricação de artefatos de material plástico para outros usos não especificados anteriormente | AK22: DEMAIS | AL22: ATIVA | AM22: https://assistjud.com.br/wp-content/uploads/elementor/forms/65098c80a5824.pdf | AN22: p6 r12; p6 r13 | AO22: p6: R$ 534.318,75; p6: R$ 1.089.720,44 | AP22: AJ_LIST | AQ22: 2023-09-18 | AR22: OK_NO_TOTALS | AS22: ROWS:p6r12,p6r13 UNRECONCILED_SOURCE | AT22: a0ae32a59c29
A23: 22 | B23: NEW | D23: 0 | I23: KARINA PLASTICOS LTDA | J23: KARINA IND E COM DE PLASTICOS LTDA | K23: 51254159 | L23: 51254159000173 | M23: 1557723.7 | N23: 1 | O23: UNKNOWN | R23: =IF(Q23="","",ROUND((TODAY()-Q23)/365.25,1)) | S23: =VLOOKUP(O23,Assumptions!$A$7:$E$10,2,FALSE) | T23: =MAX(0.5,VLOOKUP(O23,Assumptions!$A$7:$E$10,3,FALSE)+VLOOKUP(O23,Assumptions!$A$7:$E$10,4,FALSE)/2-IF(R23="",0,R23)) | U23: =M23*S23/(1+Assumptions!$B$3)^T23 | V23: =IF(M23=0,"",ROUND(U23/M23*100,1)) | W23: =U23*Assumptions!$B$4 | X23: =IF(M23=0,"",ROUND(W23/M23*100,1)) | Y23: Conduscabos Brasil Indústria Comércio de | Z23: 8005129-09.2023.8.05.0039 | AB23: assistjud.com.br | AC23: DIANA GUEREKMEZIAN ATRA | AD23: Sócio-Administrador | AE23: (11) 2440-8477 | AF23: (11) 2463-2920 | AH23: SP | AI23: GUARULHOS | AJ23: Fabricação de resinas termoplásticas | AK23: DEMAIS | AL23: ATIVA | AM23: https://assistjud.com.br/wp-content/uploads/elementor/forms/65098c80a5824.pdf | AN23: p8 r5 | AO23: p8: R$ 1.557.723,71 | AP23: AJ_LIST | AQ23: 2023-09-18 | AR23: OK_NO_TOTALS | AS23: ROWS:p8r5 UNRECONCILED_SOURCE | AT23: a0ae32a59c29
A24: 23 | B24: NEW | D24: 0 | I24: CASA BUGRE GOIAS COMERCIO E REPRESENTACAO LTDA | J24: CASA BUGRE GOIAS COMERCIO E REPRESENTACA | K24: 20366728 | L24: 20366728000149 | M24: 1367818 | N24: 1 | O24: UNKNOWN | R24: =IF(Q24="","",ROUND((TODAY()-Q24)/365.25,1)) | S24: =VLOOKUP(O24,Assumptions!$A$7:$E$10,2,FALSE) | T24: =MAX(0.5,VLOOKUP(O24,Assumptions!$A$7:$E$10,3,FALSE)+VLOOKUP(O24,Assumptions!$A$7:$E$10,4,FALSE)/2-IF(R24="",0,R24)) | U24: =M24*S24/(1+Assumptions!$B$3)^T24 | V24: =IF(M24=0,"",ROUND(U24/M24*100,1)) | W24: =U24*Assumptions!$B$4 | X24: =IF(M24=0,"",ROUND(W24/M24*100,1)) | Y24: SOJAL COMERCIAL AGRICOLA | Z24: 0804401-51.2025.8.14.0039 | AB24: lrflideres.com.br | AC24: FLAVIO DE MEDEIROS MAIA | AD24: Sócio-Administrador | AE24: (61) 3770-0199 | AH24: GO | AI24: ANAPOLIS | AJ24: Comércio atacadista de sementes, flores, plantas e gramas | AK24: DEMAIS | AL24: ATIVA | AM24: https://lrflideres.com.br/wp-content/plugins/download-attachments/includes/download.php?id=6879 | AN24: p1 r9 | AO24: p1: R$ 1.367.817,98 | AP24: AJ_LIST | AQ24: 2026-01-15 | AR24: OK | AS24: ROWS:p1r9 | AT24: c56751547323
A25: 24 | B25: NEW | D25: 0 | I25: IBRAME INDUSTRIA BRASILEIRA DE METAIS S/A | J25: IBRAME INDUST RIA BRASILEIRA DE METAIS S | K25: 60846599 | L25: 60846599000534 | M25: 1359881.3 | N25: 2 | O25: UNKNOWN | R25: =IF(Q25="","",ROUND((TODAY()-Q25)/365.25,1)) | S25: =VLOOKUP(O25,Assumptions!$A$7:$E$10,2,FALSE) | T25: =MAX(0.5,VLOOKUP(O25,Assumptions!$A$7:$E$10,3,FALSE)+VLOOKUP(O25,Assumptions!$A$7:$E$10,4,FALSE)/2-IF(R25="",0,R25)) | U25: =M25*S25/(1+Assumptions!$B$3)^T25 | V25: =IF(M25=0,"",ROUND(U25/M25*100,1)) | W25: =U25*Assumptions!$B$4 | X25: =IF(M25=0,"",ROUND(W25/M25*100,1)) | Y25: Conduscabos Brasil Indústria Comércio de | Z25: 8005129-09.2023.8.05.0039 | AB25: assistjud.com.br | AC25: LUIZ OSVALDO PASTORE | AD25: Presidente | AE25: (47) 2101-0049 | AH25: ES | AI25: VITORIA | AJ25: Comércio atacadista de mercadorias em geral, sem predominância de alimentos ou de insumos agropecuários | AK25: DEMAIS | AL25: ATIVA | AM25: https://assistjud.com.br/wp-content/uploads/elementor/forms/65098c80a5824.pdf | AN25: p7 r11; p18 r3 | AO25: p7: R$ 815.928,78; p18: R$ 543.952,52 | AP25: AJ_LIST | AQ25: 2023-09-18 | AR25: OK_NO_TOTALS | AS25: ROWS:p7r11,p18r3 UNRECONCILED_SOURCE | AT25: a0ae32a59c29
A26: 25 | B26: NEW | D26: 0 | J26: CREDMEI SECURITIZADORA II SPE S.A | K26: 50202890 | L26: 50202890000192 | M26: 1135255.2 | N26: 1 | O26: UNKNOWN | R26: =IF(Q26="","",ROUND((TODAY()-Q26)/365.25,1)) | S26: =VLOOKUP(O26,Assumptions!$A$7:$E$10,2,FALSE) | T26: =MAX(0.5,VLOOKUP(O26,Assumptions!$A$7:$E$10,3,FALSE)+VLOOKUP(O26,Assumptions!$A$7:$E$10,4,FALSE)/2-IF(R26="",0,R26)) | U26: =M26*S26/(1+Assumptions!$B$3)^T26 | V26: =IF(M26=0,"",ROUND(U26/M26*100,1)) | W26: =U26*Assumptions!$B$4 | X26: =IF(M26=0,"",ROUND(W26/M26*100,1)) | Y26: ARRUDA & MELO COMERCIO E DISTRIBUICAO DE ALIMENTOS E BEBIDAS LTDA | Z26: 0008526-45.2025.8.17.2001 | AB26: diligence.adm.br | AM26: https://diligence.adm.br/wp-content/uploads/2025/06/Edital-1a-Lista-de-Credores.pdf | AN26: p5 r54 | AO26: p5: R$ 1.135.255,25 | AP26: DEBTOR_LIST | AQ26: 2025-06-10 | AR26: OK | AS26: ROWS:p5r54 | AT26: 1658892fa167
A27: 26 | B27: NEW | D27: 0 | I27: ARRUDA & MELO COMERCIO E DISTRIBUICAO DE ALIMENTOS E BEBIDAS LTDA - EM RECUPERACAO JUDICIAL | J27: ARRUDA & MELO COMERCIO E DISTRIBUICAO DE ALIMENTOS E BEBIDAS LTDA | K27: 21877243 | L27: 21877243000182 | M27: 1068252.9 | N27: 1 | O27: UNKNOWN | R27: =IF(Q27="","",ROUND((TODAY()-Q27)/365.25,1)) | S27: =VLOOKUP(O27,Assumptions!$A$7:$E$10,2,FALSE) | T27: =MAX(0.5,VLOOKUP(O27,Assumptions!$A$7:$E$10,3,FALSE)+VLOOKUP(O27,Assumptions!$A$7:$E$10,4,FALSE)/2-IF(R27="",0,R27)) | U27: =M27*S27/(1+Assumptions!$B$3)^T27 | V27: =IF(M27=0,"",ROUND(U27/M27*100,1)) | W27: =U27*Assumptions!$B$4 | X27: =IF(M27=0,"",ROUND(W27/M27*100,1)) | Y27: ARRUDA & MELO COMERCIO E DISTRIBUICAO DE ALIMENTOS E BEBIDAS LTDA | Z27: 0008526-45.2025.8.17.2001 | AB27: diligence.adm.br | AC27: MAURO CESAR DE MELO ARRUDA | AD27: Sócio-Administrador | AE27: (81) 3314-2120 | AH27: PE | AI27: RECIFE | AJ27: Comércio atacadista de produtos alimentícios em geral | AK27: DEMAIS | AL27: ATIVA | AM27: https://diligence.adm.br/wp-content/uploads/2025/06/Edital-1a-Lista-de-Credores.pdf | AN27: p5 r48 | AO27: p5: R$ 1.068.252,89 | AP27: DEBTOR_LIST | AQ27: 2025-06-10 | AR27: OK | AS27: ROWS:p5r48 | AT27: 1658892fa167
A28: 27 | B28: NEW | D28: 0 | I28: MINERAX - MINERACAO XAMBIOA LTDA | J28: MINERACAO XAMBIOA LTDA | K28: 08886407 | L28: 08886407000170 | M28: 962991.9 | N28: 1 | O28: UNKNOWN | R28: =IF(Q28="","",ROUND((TODAY()-Q28)/365.25,1)) | S28: =VLOOKUP(O28,Assumptions!$A$7:$E$10,2,FALSE) | T28: =MAX(0.5,VLOOKUP(O28,Assumptions!$A$7:$E$10,3,FALSE)+VLOOKUP(O28,Assumptions!$A$7:$E$10,4,FALSE)/2-IF(R28="",0,R28)) | U28: =M28*S28/(1+Assumptions!$B$3)^T28 | V28: =IF(M28=0,"",ROUND(U28/M28*100,1)) | W28: =U28*Assumptions!$B$4 | X28: =IF(M28=0,"",ROUND(W28/M28*100,1)) | Y28: SOJAL COMERCIAL AGRICOLA | Z28: 0804401-51.2025.8.14.0039 | AB28: lrflideres.com.br | AC28: FRANCISCO MIGUEL HENDGES | AD28: Administrador | AE28: (63) 3415-8500 | AH28: TO | AI28: XAMBIOA | AJ28: Extração de calcário e dolomita e beneficiamento associado | AK28: DEMAIS | AL28: ATIVA | AM28: https://lrflideres.com.br/wp-content/plugins/download-attachments/includes/download.php?id=6879 | AN28: p2 r4 | AO28: p2: R$ 962.991,90 | AP28: AJ_LIST | AQ28: 2026-01-15 | AR28: OK | AS28: ROWS:p2r4 | AT28: c56751547323
A29: 28 | B29: NEW | D29: 0 | J29: DANIELE MÚLTIPLO FUNDO DE INVESTIMENTO EM DIREITOS CREDITÓRIOS – NÃO PADRONIZADOS | K29: 09414255 | L29: 09414255000175 | M29: 926408.5 | N29: 1 | O29: UNKNOWN | R29: =IF(Q29="","",ROUND((TODAY()-Q29)/365.25,1)) | S29: =VLOOKUP(O29,Assumptions!$A$7:$E$10,2,FALSE) | T29: =MAX(0.5,VLOOKUP(O29,Assumptions!$A$7:$E$10,3,FALSE)+VLOOKUP(O29,Assumptions!$A$7:$E$10,4,FALSE)/2-IF(R29="",0,R29)) | U29: =M29*S29/(1+Assumptions!$B$3)^T29 | V29: =IF(M29=0,"",ROUND(U29/M29*100,1)) | W29: =U29*Assumptions!$B$4 | X29: =IF(M29=0,"",ROUND(W29/M29*100,1)) | Y29: Conduscabos Brasil Indústria Comércio de | Z29: 8005129-09.2023.8.05.0039 | AB29: assistjud.com.br | AM29: https://assistjud.com.br/wp-content/uploads/elementor/forms/65098c80a5824.pdf | AN29: p7 r1 | AO29: p7: R$ 926.408,50 | AP29: AJ_LIST | AQ29: 2023-09-18 | AR29: OK_NO_TOTALS | AS29: ROWS:p7r1 UNRECONCILED_SOURCE | AT29: a0ae32a59c29
A30: 29 | B30: NEW | D30: 0 | I30: RG COPPER INDUSTRIA E COMERCIO DE CONDUTORES ELETRICOS LTDA | J30: RG COPPER INDUSTRIA E COMERCIO DE CONDUT | K30: 21044682 | L30: 21044682000104 | M30: 864147.01 | N30: 1 | O30: UNKNOWN | R30: =IF(Q30="","",ROUND((TODAY()-Q30)/365.25,1)) | S30: =VLOOKUP(O30,Assumptions!$A$7:$E$10,2,FALSE) | T30: =MAX(0.5,VLOOKUP(O30,Assumptions!$A$7:$E$10,3,FALSE)+VLOOKUP(O30,Assumptions!$A$7:$E$10,4,FALSE)/2-IF(R30="",0,R30)) | U30: =M30*S30/(1+Assumptions!$B$3)^T30 | V30: =IF(M30=0,"",ROUND(U30/M30*100,1)) | W30: =U30*Assumptions!$B$4 | X30: =IF(M30=0,"",ROUND(W30/M30*100,1)) | Y30: Conduscabos Brasil Indústria Comércio de | Z30: 8005129-09.2023.8.05.0039 | AB30: assistjud.com.br | AC30: GERSON GOMES DA SILVA | AD30: Sócio-Administrador | AE30: (11) 2507-5535 | AH30: SP | AI30: JARDINOPOLIS | AJ30: Fabricação de fios, cabos e condutores elétricos isolados | AK30: DEMAIS | AL30: ATIVA | AM30: https://assistjud.com.br/wp-content/uploads/elementor/forms/65098c80a5824.pdf | AN30: p9 r14 | AO30: p9: R$ 864.147,01 | AP30: AJ_LIST | AQ30: 2023-09-18 | AR30: OK_NO_TOTALS | AS30: ROWS:p9r14 UNRECONCILED_SOURCE | AT30: a0ae32a59c29
A31: 30 | B31: NEW | D31: 0 | J31: ASIA FIDC | K31: 09172117 | L31: 09172117000127 | M31: 758759.36 | N31: 1 | O31: UNKNOWN | R31: =IF(Q31="","",ROUND((TODAY()-Q31)/365.25,1)) | S31: =VLOOKUP(O31,Assumptions!$A$7:$E$10,2,FALSE) | T31: =MAX(0.5,VLOOKUP(O31,Assumptions!$A$7:$E$10,3,FALSE)+VLOOKUP(O31,Assumptions!$A$7:$E$10,4,FALSE)/2-IF(R31="",0,R31)) | U31: =M31*S31/(1+Assumptions!$B$3)^T31 | V31: =IF(M31=0,"",ROUND(U31/M31*100,1)) | W31: =U31*Assumptions!$B$4 | X31: =IF(M31=0,"",ROUND(W31/M31*100,1)) | Y31: Conduscabos Brasil Indústria Comércio de | Z31: 8005129-09.2023.8.05.0039 | AB31: assistjud.com.br | AM31: https://assistjud.com.br/wp-content/uploads/elementor/forms/65098c80a5824.pdf | AN31: p5 r5 | AO31: p5: R$ 758.759,36 | AP31: AJ_LIST | AQ31: 2023-09-18 | AR31: OK_NO_TOTALS | AS31: ROWS:p5r5 UNRECONCILED_SOURCE VALUE_COL:Valor_Do_Crédito_2º_Edital_De_Credores | AT31: a0ae32a59c29
A32: 31 | B32: NEW | D32: 0 | I32: MAGNUM DISTRIBUIDORA DE PNEUS S/A | J32: MAGNUM DISTRIBUIDORA DE PNEUS S/A | K32: 19403406 | L32: 19403406001549 | M32: 644893.08 | N32: 1 | O32: UNKNOWN | R32: =IF(Q32="","",ROUND((TODAY()-Q32)/365.25,1)) | S32: =VLOOKUP(O32,Assumptions!$A$7:$E$10,2,FALSE) | T32: =MAX(0.5,VLOOKUP(O32,Assumptions!$A$7:$E$10,3,FALSE)+VLOOKUP(O32,Assumptions!$A$7:$E$10,4,FALSE)/2-IF(R32="",0,R32)) | U32: =M32*S32/(1+Assumptions!$B$3)^T32 | V32: =IF(M32=0,"",ROUND(U32/M32*100,1)) | W32: =U32*Assumptions!$B$4 | X32: =IF(M32=0,"",ROUND(W32/M32*100,1)) | Y32: DR. ALYSSON CORREIA MACIEL – OAB/PB 11.841, DRA. CAROL DE ALMEIDA LIMA | Z32: 0804204-35.2022.8.15.0731 | AB32: lrflideres.com.br | AC32: ANTONIO CARLOS CAVALCANTI DE ARAUJO FILHO | AD32: Presidente | AE32: (81) 3797-6245 | AF32: (81) 3797-6246 | AH32: PE | AI32: JABOATAO DOS GUARARAPES | AJ32: Comércio por atacado de pneumáticos e câmaras-de-ar | AK32: DEMAIS | AL32: ATIVA | AM32: https://lrflideres.com.br/wp-content/uploads/2022/08/4.-EDITAL-2a-LISTA-DE-CREDORES.pdf | AN32: p1 r21 | AO32: p1: R$ 644.893,08 | AP32: AJ_LIST | AQ32: 2023-12-04 | AR32: OK | AS32: ROWS:p1r21 | AT32: 1355f93a13cd
A33: 32 | B33: NEW | D33: 0 | I33: SOTIN SOLUCOES TECNICAS, INDUSTRIA E COMERCIO LTDA | J33: SOTIN SOLUÇÕES TECNICAS IND E COMERCIO LTDA | K33: 38733545 | L33: 38733545000180 | M33: 611207.1 | N33: 1 | O33: UNKNOWN | R33: =IF(Q33="","",ROUND((TODAY()-Q33)/365.25,1)) | S33: =VLOOKUP(O33,Assumptions!$A$7:$E$10,2,FALSE) | T33: =MAX(0.5,VLOOKUP(O33,Assumptions!$A$7:$E$10,3,FALSE)+VLOOKUP(O33,Assumptions!$A$7:$E$10,4,FALSE)/2-IF(R33="",0,R33)) | U33: =M33*S33/(1+Assumptions!$B$3)^T33 | V33: =IF(M33=0,"",ROUND(U33/M33*100,1)) | W33: =U33*Assumptions!$B$4 | X33: =IF(M33=0,"",ROUND(W33/M33*100,1)) | Y33: DR. ALYSSON CORREIA MACIEL – OAB/PB 11.841, DRA. CAROL DE ALMEIDA LIMA | Z33: 0804204-35.2022.8.15.0731 | AB33: lrflideres.com.br | AC33: SPENCER WILLIAM STELLA JUNIOR | AD33: Sócio-Administrador | AE33: (11) 4496-8888 | AH33: SP | AI33: JUNDIAI | AJ33: Fabricação de outros produtos de metal não especificados anteriormente | AK33: DEMAIS | AL33: ATIVA | AM33: https://lrflideres.com.br/wp-content/uploads/2022/08/4.-EDITAL-2a-LISTA-DE-CREDORES.pdf | AN33: p2 r9 | AO33: p2: R$ 611.207,10 | AP33: AJ_LIST | AQ33: 2023-12-04 | AR33: OK | AS33: ROWS:p2r9 | AT33: 1355f93a13cd
A34: 33 | B34: NEW | D34: 0 | I34: COBREMACK INDUSTRIA DE CONDUTORES ELETRICOS LIMITADA EM RECUPERACAO JUDICIAL EM RECUPERACAO JUDICIAL | J34: COBREMACK INDUSTRIA DE CONDUTORES ELETRI | K34: 11065453 | L34: 11065453000201 | M34: 611009.25 | N34: 2 | O34: UNKNOWN | R34: =IF(Q34="","",ROUND((TODAY()-Q34)/365.25,1)) | S34: =VLOOKUP(O34,Assumptions!$A$7:$E$10,2,FALSE) | T34: =MAX(0.5,VLOOKUP(O34,Assumptions!$A$7:$E$10,3,FALSE)+VLOOKUP(O34,Assumptions!$A$7:$E$10,4,FALSE)/2-IF(R34="",0,R34)) | U34: =M34*S34/(1+Assumptions!$B$3)^T34 | V34: =IF(M34=0,"",ROUND(U34/M34*100,1)) | W34: =U34*Assumptions!$B$4 | X34: =IF(M34=0,"",ROUND(W34/M34*100,1)) | Y34: Conduscabos Brasil Indústria Comércio de | Z34: 8005129-09.2023.8.05.0039 | AB34: assistjud.com.br | AC34: JOSE CARLOS MENDES MATUIAMA | AD34: Sócio-Administrador | AE34: (11) 4156-5531 | AH34: BA | AI34: LAURO DE FREITAS | AJ34: Fabricação de fios, cabos e condutores elétricos isolados | AK34: DEMAIS | AL34: ATIVA | AM34: https://assistjud.com.br/wp-content/uploads/elementor/forms/65098c80a5824.pdf | AN34: p6 r8; p17 r10 | AO34: p6: R$ 420.273,65; p17: R$ 190.735,60 | AP34: AJ_LIST | AQ34: 2023-09-18 | AR34: OK_NO_TOTALS | AS34: ROWS:p6r8,p17r10 UNRECONCILED_SOURCE VALUE_COL:Valor_Do_Crédito_2º_Edital_De_Credores | AT34: a0ae32a59c29
A35: 34 | B35: NEW | D35: 0 | I35: BIOBASE INDUSTRIA E COMERCIO LTDA | J35: BIOBASE INDUSTRIA E COMERCIO LTDA | K35: 05216859 | L35: 05216859000156 | M35: 569654.02 | N35: 1 | O35: UNKNOWN | R35: =IF(Q35="","",ROUND((TODAY()-Q35)/365.25,1)) | S35: =VLOOKUP(O35,Assumptions!$A$7:$E$10,2,FALSE) | T35: =MAX(0.5,VLOOKUP(O35,Assumptions!$A$7:$E$10,3,FALSE)+VLOOKUP(O35,Assumptions!$A$7:$E$10,4,FALSE)/2-IF(R35="",0,R35)) | U35: =M35*S35/(1+Assumptions!$B$3)^T35 | V35: =IF(M35=0,"",ROUND(U35/M35*100,1)) | W35: =U35*Assumptions!$B$4 | X35: =IF(M35=0,"",ROUND(W35/M35*100,1)) | Z35: (not found in document) | AB35: bernardobicalho.com.br | AC35: RICHARD REIS FARIAS | AD35: Sócio-Administrador | AE35: (35) 3427-7000 | AF35: (35) 3427-7012 | AH35: MG | AI35: POUSO ALEGRE | AJ35: Fabricação de materiais para medicina e odontologia | AK35: DEMAIS | AL35: ATIVA | AM35: http://bernardobicalho.com.br/login/app/documents/Rela%C3%A7%C3%A3o%20de%20Credores/6.%20RVC-%20Nutricium%20-%20simplificada.pdf | AN35: p3 r7 | AO35: p3: R$ 569.654,02 | AP35: AJ_LIST | AR35: OK | AS35: CASE_NUMBER_MISSING ROWS:p3r7 | AT35: 6a92d74da333
A36: 35 | B36: NEW | D36: 0 | J36: CREDIT PARTNERS FUNDO DE INVESTIMENTO EM DIREITOS CREDITÓRIOS NÃO PADRONIZADOS | K36: 32274874 | L36: 32274874000123 | M36: 547127.35 | N36: 2 | O36: UNKNOWN | R36: =IF(Q36="","",ROUND((TODAY()-Q36)/365.25,1)) | S36: =VLOOKUP(O36,Assumptions!$A$7:$E$10,2,FALSE) | T36: =MAX(0.5,VLOOKUP(O36,Assumptions!$A$7:$E$10,3,FALSE)+VLOOKUP(O36,Assumptions!$A$7:$E$10,4,FALSE)/2-IF(R36="",0,R36)) | U36: =M36*S36/(1+Assumptions!$B$3)^T36 | V36: =IF(M36=0,"",ROUND(U36/M36*100,1)) | W36: =U36*Assumptions!$B$4 | X36: =IF(M36=0,"",ROUND(W36/M36*100,1)) | Y36: Conduscabos Brasil Indústria Comércio de | Z36: 8005129-09.2023.8.05.0039 | AB36: assistjud.com.br | AM36: https://assistjud.com.br/wp-content/uploads/elementor/forms/65098c80a5824.pdf | AN36: p6 r11; p17 r11 | AO36: p6: R$ 333.437,35; p17: R$ 213.690,00 | AP36: AJ_LIST | AQ36: 2023-09-18 | AR36: OK_NO_TOTALS | AS36: ROWS:p6r11,p17r11 UNRECONCILED_SOURCE VALUE_COL:Valor_Do_Crédito_2º_Edital_De_Credores | AT36: a0ae32a59c29
A37: 36 | B37: NEW | D37: 0 | I37: CALMAP INDUSTRIA DE CALCARIO LTDA | J37: CALMAP INDUSTRIA DE CALCARIO LTDA | K37: 10962529 | L37: 10962529000140 | M37: 526042.93 | N37: 1 | O37: UNKNOWN | R37: =IF(Q37="","",ROUND((TODAY()-Q37)/365.25,1)) | S37: =VLOOKUP(O37,Assumptions!$A$7:$E$10,2,FALSE) | T37: =MAX(0.5,VLOOKUP(O37,Assumptions!$A$7:$E$10,3,FALSE)+VLOOKUP(O37,Assumptions!$A$7:$E$10,4,FALSE)/2-IF(R37="",0,R37)) | U37: =M37*S37/(1+Assumptions!$B$3)^T37 | V37: =IF(M37=0,"",ROUND(U37/M37*100,1)) | W37: =U37*Assumptions!$B$4 | X37: =IF(M37=0,"",ROUND(W37/M37*100,1)) | Y37: SOJAL COMERCIAL AGRICOLA | Z37: 0804401-51.2025.8.14.0039 | AB37: lrflideres.com.br | AC37: ANTONIO HOLANDA DE OLIVEIRA NETO | AD37: Sócio-Administrador | AE37: (85) 3082-0505 | AH37: PA | AI37: SAO GERALDO DO ARAGUAIA | AJ37: Extração de minerais para fabricação de adubos, fertilizantes e outros produtos químicos | AK37: DEMAIS | AL37: ATIVA | AM37: https://lrflideres.com.br/wp-content/plugins/download-attachments/includes/download.php?id=6879 | AN37: p1 r8 | AO37: p1: R$ 526.042,93 | AP37: AJ_LIST | AQ37: 2026-01-15 | AR37: OK | AS37: ROWS:p1r8 | AT37: c56751547323
A38: 37 | B38: NEW | D38: 0 | I38: COBB-VANTRESS BRASIL LTDA | J38: COBB - VANTRESS BRASIL LTDA | K38: 00466591 | L38: 00466591000197 | M38: 497078.85 | N38: 1 | O38: UNKNOWN | R38: =IF(Q38="","",ROUND((TODAY()-Q38)/365.25,1)) | S38: =VLOOKUP(O38,Assumptions!$A$7:$E$10,2,FALSE) | T38: =MAX(0.5,VLOOKUP(O38,Assumptions!$A$7:$E$10,3,FALSE)+VLOOKUP(O38,Assumptions!$A$7:$E$10,4,FALSE)/2-IF(R38="",0,R38)) | U38: =M38*S38/(1+Assumptions!$B$3)^T38 | V38: =IF(M38=0,"",ROUND(U38/M38*100,1)) | W38: =U38*Assumptions!$B$4 | X38: =IF(M38=0,"",ROUND(W38/M38*100,1)) | Y38: AGROPECUÁRIA SERROTE REDONDO | Z38: 0000206-69.2013.8.17.1340 | AB38: lrflideres.com.br | AC38: RODRIGO FERREIRA SIQUEIRA DE MELLO | AD38: Administrador | AH38: SP | AI38: GUAPIACU | AJ38: Produção de pintos de um dia | AK38: DEMAIS | AL38: ATIVA | AM38: https://lrflideres.com.br/wp-content/plugins/download-attachments/includes/download.php?id=5001 | AN38: p1 r23 | AO38: p1: R$ 497.078,85 | AP38: UNKNOWN | AR38: OK | AS38: ALT_VALUE:497.078,85 ROWS:p1r23 VALUE_COL:Valor_Atualizado | AT38: 7c0ce2830d0d
A39: 38 | B39: NEW | D39: 0 | I39: CROPFERT INDUSTRIA DE FERTILIZANTES E AGROQUIMICOS LTDA | J39: CROPFERT INDUSTRIA DE FERTILIZANTES E AG | K39: 18373437 | L39: 18373437000136 | M39: 467392 | N39: 1 | O39: UNKNOWN | R39: =IF(Q39="","",ROUND((TODAY()-Q39)/365.25,1)) | S39: =VLOOKUP(O39,Assumptions!$A$7:$E$10,2,FALSE) | T39: =MAX(0.5,VLOOKUP(O39,Assumptions!$A$7:$E$10,3,FALSE)+VLOOKUP(O39,Assumptions!$A$7:$E$10,4,FALSE)/2-IF(R39="",0,R39)) | U39: =M39*S39/(1+Assumptions!$B$3)^T39 | V39: =IF(M39=0,"",ROUND(U39/M39*100,1)) | W39: =U39*Assumptions!$B$4 | X39: =IF(M39=0,"",ROUND(W39/M39*100,1)) | Y39: SOJAL COMERCIAL AGRICOLA | Z39: 0804401-51.2025.8.14.0039 | AB39: lrflideres.com.br | AC39: ANDERSON JOSE FAUSTINO | AD39: Administrador | AE39: (43) 3162-2700 | AH39: PR | AI39: JANDAIA DO SUL | AJ39: Fabricação de defensivos agrícolas | AK39: DEMAIS | AL39: ATIVA | AM39: https://lrflideres.com.br/wp-content/plugins/download-attachments/includes/download.php?id=6879 | AN39: p1 r12 | AO39: p1: R$ 467.392,00 | AP39: AJ_LIST | AQ39: 2026-01-15 | AR39: OK | AS39: ROWS:p1r12 | AT39: c56751547323
A40: 39 | B40: NEW | D40: 0 | I40: COMARY INDUSTRIA DE BEBIDAS LTDA | J40: COMARY INDUSTRIA DE BEBIDAS LTDA | K40: 29588019 | L40: 29588019001316 | M40: 407241.98 | N40: 1 | O40: UNKNOWN | R40: =IF(Q40="","",ROUND((TODAY()-Q40)/365.25,1)) | S40: =VLOOKUP(O40,Assumptions!$A$7:$E$10,2,FALSE) | T40: =MAX(0.5,VLOOKUP(O40,Assumptions!$A$7:$E$10,3,FALSE)+VLOOKUP(O40,Assumptions!$A$7:$E$10,4,FALSE)/2-IF(R40="",0,R40)) | U40: =M40*S40/(1+Assumptions!$B$3)^T40 | V40: =IF(M40=0,"",ROUND(U40/M40*100,1)) | W40: =U40*Assumptions!$B$4 | X40: =IF(M40=0,"",ROUND(W40/M40*100,1)) | Y40: ARRUDA & MELO COMERCIO E DISTRIBUICAO DE ALIMENTOS E BEBIDAS LTDA | Z40: 0008526-45.2025.8.17.2001 | AB40: diligence.adm.br | AC40: MOZART RIBEIRO RODRIGUES | AD40: Sócio-Administrador | AE40: (21) 2152-4014 | AF40: (21) 2152-4000 | AH40: RJ | AI40: TERESOPOLIS | AJ40: Fabricação de vinho | AK40: DEMAIS | AL40: ATIVA | AM40: https://diligence.adm.br/wp-content/uploads/2025/06/Edital-1a-Lista-de-Credores.pdf | AN40: p5 r69 | AO40: p5: R$ 407.241,98 | AP40: DEBTOR_LIST | AQ40: 2025-06-10 | AR40: OK | AS40: ROWS:p5r69 | AT40: 1658892fa167
...

Sheet Pooling (100-200k)
A1: Rank | B1: Status | C1: Owner | D1: Attempts | E1: Last touch | F1: Next action | G1: Next date | H1: Notes | I1: Company (RFB) | J1: Name as printed | K1: CNPJ root | L1: Establishment CNPJs | M1: Class III face (R$) | N1: Claims | O1: Plan status | P1: Stage | Q1: Case filed | R1: Years since filing | S1: Est. recovery % | T1: Years to payment (est.) | U1: Fund price @ IRR (R$) | V1: Fund price (cents) | W1: OUR QUOTE (R$) | X1: Quote (cents) | Y1: Debtor | Z1: Case number | AA1: Court | AB1: Administrator (site) | AC1: Decision-maker | AD1: Role | AE1: Phone | AF1: Phone 2 | AG1: Email | AH1: UF | AI1: City | AJ1: CNAE | AK1: Porte | AL1: Situação | AM1: PROOF: source document | AN1: Page / row | AO1: Value as printed | AP1: Which list | AQ1: Published | AR1: Reconciled | AS1: Data flags | AT1: Doc id
A2: 1 | B2: NEW | D2: 0 | J2: ALVAREZ & MARSAL REESTRUTURACAO E ASSESS ORIA FINANCEIRA PARA SIT ESP LTDA | K2: 32282989 | L2: 32282989000160 | M2: 188233.36 | N2: 1 | O2: UNKNOWN | R2: =IF(Q2="","",ROUND((TODAY()-Q2)/365.25,1)) | S2: =VLOOKUP(O2,Assumptions!$A$7:$E$10,2,FALSE) | T2: =MAX(0.5,VLOOKUP(O2,Assumptions!$A$7:$E$10,3,FALSE)+VLOOKUP(O2,Assumptions!$A$7:$E$10,4,FALSE)/2-IF(R2="",0,R2)) | U2: =M2*S2/(1+Assumptions!$B$3)^T2 | V2: =IF(M2=0,"",ROUND(U2/M2*100,1)) | W2: =U2*Assumptions!$B$4 | X2: =IF(M2=0,"",ROUND(W2/M2*100,1)) | Z2: 0820780-23.2026.8.14.0301 | AB2: cdn.dol.com.br | AM2: https://cdn.dol.com.br/img/attachmentinline/940000/6publicacao-2-edital-art-7-parag-2-da-lei-11101-20009467060.pdf?xid=3272528 | AN2: p3 r13 | AO2: p3: R$ 188.233,36 | AP2: AJ_LIST | AQ2: 2026-07-07 | AR2: QUARANTINED | AS2: PARTIAL_DOC_CLASS_III_RECONCILED ROWS:p3r13 | AT2: 38d930ab1caa
A3: 2 | B3: NEW | D3: 0 | J3: MULTIPLO FUNDO DE INVESTIMENTO EM DIREITOS CREDITÓRIOS NÃO PADRONIZADOS MULTISSETORIA L | K3: 10842374 | L3: 10842374000108 | M3: 160996.26 | N3: 1 | O3: UNKNOWN | R3: =IF(Q3="","",ROUND((TODAY()-Q3)/365.25,1)) | S3: =VLOOKUP(O3,Assumptions!$A$7:$E$10,2,FALSE) | T3: =MAX(0.5,VLOOKUP(O3,Assumptions!$A$7:$E$10,3,FALSE)+VLOOKUP(O3,Assumptions!$A$7:$E$10,4,FALSE)/2-IF(R3="",0,R3)) | U3: =M3*S3/(1+Assumptions!$B$3)^T3 | V3: =IF(M3=0,"",ROUND(U3/M3*100,1)) | W3: =U3*Assumptions!$B$4 | X3: =IF(M3=0,"",ROUND(W3/M3*100,1)) | Y3: Conduscabos Brasil Indústria Comércio de | Z3: 8005129-09.2023.8.05.0039 | AB3: assistjud.com.br | AM3: https://assistjud.com.br/wp-content/uploads/elementor/forms/65098c80a5824.pdf | AN3: p19 r1 | AO3: p19: R$ 160.996,26 | AP3: AJ_LIST | AQ3: 2023-09-18 | AR3: OK_NO_TOTALS | AS3: ROWS:p19r1 UNRECONCILED_SOURCE | AT3: a0ae32a59c29
A4: 3 | B4: NEW | D4: 0 | I4: SIAGRI SISTEMAS DE GESTAO LTDA | J4: SIAGRI SISTEMAS DE GESTAO LTDA | K4: 02435301 | L4: 02435301000416 | M4: 155266.23 | N4: 1 | O4: UNKNOWN | R4: =IF(Q4="","",ROUND((TODAY()-Q4)/365.25,1)) | S4: =VLOOKUP(O4,Assumptions!$A$7:$E$10,2,FALSE) | T4: =MAX(0.5,VLOOKUP(O4,Assumptions!$A$7:$E$10,3,FALSE)+VLOOKUP(O4,Assumptions!$A$7:$E$10,4,FALSE)/2-IF(R4="",0,R4)) | U4: =M4*S4/(1+Assumptions!$B$3)^T4 | V4: =IF(M4=0,"",ROUND(U4/M4*100,1)) | W4: =U4*Assumptions!$B$4 | X4: =IF(M4=0,"",ROUND(W4/M4*100,1)) | Y4: SOJAL COMERCIAL AGRICOLA | Z4: 0804401-51.2025.8.14.0039 | AB4: lrflideres.com.br | AC4: CARLOS ANTONIO BARBOSA | AD4: Administrador | AE4: (64) 3620-1550 | AF4: (64) 3620-1500 | AH4: GO | AI4: RIO VERDE | AJ4: Desenvolvimento e licenciamento de programas de computador customizáveis | AK4: DEMAIS | AL4: ATIVA | AM4: https://lrflideres.com.br/wp-content/plugins/download-attachments/includes/download.php?id=6879 | AN4: p2 r8 | AO4: p2: R$ 155.266,23 | AP4: AJ_LIST | AQ4: 2026-01-15 | AR4: OK | AS4: ROWS:p2r8 | AT4: c56751547323
A5: 4 | B5: NEW | D5: 0 | I5: JUAREZ DE OLIVEIRA | J5: JUAREZ DE OLIVEIRA M E | K5: 69915536 | L5: 69915536000133 | M5: 151663.31 | N5: 1 | O5: UNKNOWN | R5: =IF(Q5="","",ROUND((TODAY()-Q5)/365.25,1)) | S5: =VLOOKUP(O5,Assumptions!$A$7:$E$10,2,FALSE) | T5: =MAX(0.5,VLOOKUP(O5,Assumptions!$A$7:$E$10,3,FALSE)+VLOOKUP(O5,Assumptions!$A$7:$E$10,4,FALSE)/2-IF(R5="",0,R5)) | U5: =M5*S5/(1+Assumptions!$B$3)^T5 | V5: =IF(M5=0,"",ROUND(U5/M5*100,1)) | W5: =U5*Assumptions!$B$4 | X5: =IF(M5=0,"",ROUND(W5/M5*100,1)) | Y5: AGROPECUÁRIA SERROTE REDONDO | Z5: 0000206-69.2013.8.17.1340 | AB5: lrflideres.com.br | AH5: PE | AI5: ARCOVERDE | AJ5: Comércio varejista de outros produtos não especificados anteriormente | AK5: MICRO EMPRESA | AL5: ATIVA | AM5: https://lrflideres.com.br/wp-content/plugins/download-attachments/includes/download.php?id=5001 | AN5: p2 r32 | AO5: p2: R$ 151.663,31 | AP5: UNKNOWN | AR5: OK | AS5: ALT_VALUE:67.051,58 ROWS:p2r32 | AT5: 7c0ce2830d0d
A6: 5 | B6: NEW | D6: 0 | I6: JC SOCCER TALENTS MARKETING ESPORTIVO LTDA | J6: JC SOCCER TALENTS | K6: 12073848 | L6: 12073848000120 | M6: 151585.39 | N6: 1 | O6: UNKNOWN | R6: =IF(Q6="","",ROUND((TODAY()-Q6)/365.25,1)) | S6: =VLOOKUP(O6,Assumptions!$A$7:$E$10,2,FALSE) | T6: =MAX(0.5,VLOOKUP(O6,Assumptions!$A$7:$E$10,3,FALSE)+VLOOKUP(O6,Assumptions!$A$7:$E$10,4,FALSE)/2-IF(R6="",0,R6)) | U6: =M6*S6/(1+Assumptions!$B$3)^T6 | V6: =IF(M6=0,"",ROUND(U6/M6*100,1)) | W6: =U6*Assumptions!$B$4 | X6: =IF(M6=0,"",ROUND(W6/M6*100,1)) | Z6: 0820780-23.2026.8.14.0301 | AB6: cdn.dol.com.br | AC6: ALEXANDRE BASTOS LOPES | AD6: Sócio-Administrador | AE6: (21) 3970-8940 | AH6: RJ | AI6: RIO DE JANEIRO | AJ6: Agenciamento de profissionais para atividades esportivas, culturais e artísticas | AK6: DEMAIS | AL6: ATIVA | AM6: https://cdn.dol.com.br/img/attachmentinline/940000/6publicacao-2-edital-art-7-parag-2-da-lei-11101-20009467060.pdf?xid=3272528 | AN6: p3 r22 | AO6: p3: R$ 151.585,39 | AP6: AJ_LIST | AQ6: 2026-07-07 | AR6: QUARANTINED | AS6: PARTIAL_DOC_CLASS_III_RECONCILED ROWS:p3r22 | AT6: 38d930ab1caa
A7: 6 | B7: NEW | D7: 0 | I7: SULPECAS COMERCIO E REPRESENTACOES LTDA | J7: SULPEÇAS COM E REPRES LTDA | K7: 52068491 | L7: 52068491000106 | M7: 135239.5 | N7: 1 | O7: UNKNOWN | R7: =IF(Q7="","",ROUND((TODAY()-Q7)/365.25,1)) | S7: =VLOOKUP(O7,Assumptions!$A$7:$E$10,2,FALSE) | T7: =MAX(0.5,VLOOKUP(O7,Assumptions!$A$7:$E$10,3,FALSE)+VLOOKUP(O7,Assumptions!$A$7:$E$10,4,FALSE)/2-IF(R7="",0,R7)) | U7: =M7*S7/(1+Assumptions!$B$3)^T7 | V7: =IF(M7=0,"",ROUND(U7/M7*100,1)) | W7: =U7*Assumptions!$B$4 | X7: =IF(M7=0,"",ROUND(W7/M7*100,1)) | Y7: DR. ALYSSON CORREIA MACIEL – OAB/PB 11.841, DRA. CAROL DE ALMEIDA LIMA | Z7: 0804204-35.2022.8.15.0731 | AB7: lrflideres.com.br | AC7: MARCELO DE SOUZA GUERINI | AD7: Sócio-Administrador | AE7: (11) 3829-9900 | AH7: SP | AI7: SAO PAULO | AJ7: Comércio atacadista de máquinas, equipamentos para terraplenagem, mineração e construção; partes e peças | AK7: DEMAIS | AL7: ATIVA | AM7: https://lrflideres.com.br/wp-content/uploads/2022/08/4.-EDITAL-2a-LISTA-DE-CREDORES.pdf | AN7: p2 r10 | AO7: p2: R$ 135.239,50 | AP7: AJ_LIST | AQ7: 2023-12-04 | AR7: OK | AS7: ROWS:p2r10 | AT7: 1355f93a13cd
A8: 7 | B8: NEW | D8: 0 | I8: M CASSAB COMERCIO E INDUSTRIA LTDA | J8: M CASSAB COMERCIO E INDUSTRIA LTDA | K8: 49698723 | L8: 49698723000103 | M8: 131926.28 | N8: 1 | O8: UNKNOWN | R8: =IF(Q8="","",ROUND((TODAY()-Q8)/365.25,1)) | S8: =VLOOKUP(O8,Assumptions!$A$7:$E$10,2,FALSE) | T8: =MAX(0.5,VLOOKUP(O8,Assumptions!$A$7:$E$10,3,FALSE)+VLOOKUP(O8,Assumptions!$A$7:$E$10,4,FALSE)/2-IF(R8="",0,R8)) | U8: =M8*S8/(1+Assumptions!$B$3)^T8 | V8: =IF(M8=0,"",ROUND(U8/M8*100,1)) | W8: =U8*Assumptions!$B$4 | X8: =IF(M8=0,"",ROUND(W8/M8*100,1)) | Z8: (not found in document) | AB8: bernardobicalho.com.br | AC8: MARIO SERGIO CUTAIT | AD8: Administrador | AE8: (11) 2162-7700 | AF8: (11) 2162-7751 | AH8: SP | AI8: SAO PAULO | AJ8: Comércio atacadista especializado em outros produtos intermediários não especificados anteriormente | AK8: DEMAIS | AL8: ATIVA | AM8: http://bernardobicalho.com.br/login/app/documents/Rela%C3%A7%C3%A3o%20de%20Credores/6.%20RVC-%20Nutricium%20-%20simplificada.pdf | AN8: p3 r23 | AO8: p3: R$ 131.926,28 | AP8: AJ_LIST | AR8: OK | AS8: CASE_NUMBER_MISSING ROWS:p3r23 | AT8: 6a92d74da333
A9: 8 | B9: NEW | D9: 0 | I9: COMPANHIA DE ALIMENTOS DO NORDESTE CIALNE | J9: COMPANHIA DE ALIMENTOSDO NORDESTE CIALNE | K9: 07220874 | L9: 07220874000101 | M9: 131836.89 | N9: 1 | O9: UNKNOWN | R9: =IF(Q9="","",ROUND((TODAY()-Q9)/365.25,1)) | S9: =VLOOKUP(O9,Assumptions!$A$7:$E$10,2,FALSE) | T9: =MAX(0.5,VLOOKUP(O9,Assumptions!$A$7:$E$10,3,FALSE)+VLOOKUP(O9,Assumptions!$A$7:$E$10,4,FALSE)/2-IF(R9="",0,R9)) | U9: =M9*S9/(1+Assumptions!$B$3)^T9 | V9: =IF(M9=0,"",ROUND(U9/M9*100,1)) | W9: =U9*Assumptions!$B$4 | X9: =IF(M9=0,"",ROUND(W9/M9*100,1)) | Y9: AGROPECUÁRIA SERROTE REDONDO | Z9: 0000206-69.2013.8.17.1340 | AB9: lrflideres.com.br | AC9: IVAN ANTONIO PERUZZO | AD9: Presidente | AE9: (85) 3477-2700 | AH9: CE | AI9: FORTALEZA | AJ9: Produção de pintos de um dia | AK9: DEMAIS | AL9: ATIVA | AM9: https://lrflideres.com.br/wp-content/plugins/download-attachments/includes/download.php?id=5001 | AN9: p1 r27 | AO9: p1: R$ 131.836,89 | AP9: UNKNOWN | AR9: OK | AS9: ALT_VALUE:131.836,89 ROWS:p1r27 VALUE_COL:Valor_Atualizado | AT9: 7c0ce2830d0d
A10: 9 | B10: NEW | D10: 0 | I10: MARTINS CONFECCAO E COMERCIO DE ARTIGOS DO VESTUARIO E ACESSORIOS LTDA | J10: MARTINS INDUSTRIA TEXTIL, CNPJ | K10: 82165010 | L10: 82165010000141 | M10: 127861.62 | N10: 1 | O10: UNKNOWN | R10: =IF(Q10="","",ROUND((TODAY()-Q10)/365.25,1)) | S10: =VLOOKUP(O10,Assumptions!$A$7:$E$10,2,FALSE) | T10: =MAX(0.5,VLOOKUP(O10,Assumptions!$A$7:$E$10,3,FALSE)+VLOOKUP(O10,Assumptions!$A$7:$E$10,4,FALSE)/2-IF(R10="",0,R10)) | U10: =M10*S10/(1+Assumptions!$B$3)^T10 | V10: =IF(M10=0,"",ROUND(U10/M10*100,1)) | W10: =U10*Assumptions!$B$4 | X10: =IF(M10=0,"",ROUND(W10/M10*100,1)) | Y10: DICARLO MOVEIS E ACESSORIOS PARA CASA E LOJAS LTDA | Z10: 0301015-33.2016.8.24.0031 | AB10: administradorajudicialgs.com.br | AC10: ILMA FEUSER MARTINS | AD10: Sócio-Administrador | AE10: (47) 2123-2500 | AH10: SC | AI10: INDAIAL | AJ10: Tecelagem de fios de algodão | AK10: DEMAIS | AL10: ATIVA | AM10: https://administradorajudicialgs.com.br/wp-content/uploads/2023/08/edital-quadro-geral-de-credores.pdf | AN10: p3 r12 | AO10: p3: R$ 127.861,62 | AP10: QGC | AQ10: 2024-07-05 | AR10: OK_NO_TOTALS | AS10: ROWS:p3r12 UNRECONCILED_SOURCE | AT10: 98f99945499b
A11: 10 | B11: NEW | D11: 0 | J11: SOFISA RECEBÍVEIS FUNDO DE INVESTIMENTO EM DIREITOS CREDITÓRIOS PADRONIZADOS | K11: 28075236 | L11: 28075236000106 | M11: 126832.55 | N11: 1 | O11: UNKNOWN | R11: =IF(Q11="","",ROUND((TODAY()-Q11)/365.25,1)) | S11: =VLOOKUP(O11,Assumptions!$A$7:$E$10,2,FALSE) | T11: =MAX(0.5,VLOOKUP(O11,Assumptions!$A$7:$E$10,3,FALSE)+VLOOKUP(O11,Assumptions!$A$7:$E$10,4,FALSE)/2-IF(R11="",0,R11)) | U11: =M11*S11/(1+Assumptions!$B$3)^T11 | V11: =IF(M11=0,"",ROUND(U11/M11*100,1)) | W11: =U11*Assumptions!$B$4 | X11: =IF(M11=0,"",ROUND(W11/M11*100,1)) | Y11: Conduscabos Brasil Indústria Comércio de | Z11: 8005129-09.2023.8.05.0039 | AB11: assistjud.com.br | AM11: https://assistjud.com.br/wp-content/uploads/elementor/forms/65098c80a5824.pdf | AN11: p10 r3 | AO11: p10: R$ 126.832,55 | AP11: AJ_LIST | AQ11: 2023-09-18 | AR11: OK_NO_TOTALS | AS11: ROWS:p10r3 UNRECONCILED_SOURCE | AT11: a0ae32a59c29
A12: 11 | B12: NEW | D12: 0 | I12: PETROSTAR COMBUSTIVEIS LTDA | J12: PETROSTAR COMBUSTIVEIS LTDA | K12: 29736901 | L12: 29736901000128 | M12: 120950 | N12: 1 | O12: UNKNOWN | R12: =IF(Q12="","",ROUND((TODAY()-Q12)/365.25,1)) | S12: =VLOOKUP(O12,Assumptions!$A$7:$E$10,2,FALSE) | T12: =MAX(0.5,VLOOKUP(O12,Assumptions!$A$7:$E$10,3,FALSE)+VLOOKUP(O12,Assumptions!$A$7:$E$10,4,FALSE)/2-IF(R12="",0,R12)) | U12: =M12*S12/(1+Assumptions!$B$3)^T12 | V12: =IF(M12=0,"",ROUND(U12/M12*100,1)) | W12: =U12*Assumptions!$B$4 | X12: =IF(M12=0,"",ROUND(W12/M12*100,1)) | Y12: DR. ALYSSON CORREIA MACIEL – OAB/PB 11.841, DRA. CAROL DE ALMEIDA LIMA | Z12: 0804204-35.2022.8.15.0731 | AB12: lrflideres.com.br | AC12: CRISTIANO LINS NOGUEIRA DE ARAUJO | AD12: Sócio-Administrador | AE12: (81) 9197-4902 | AH12: PE | AI12: CABO DE SANTO AGOSTINHO | AJ12: Comércio atacadista de combustíveis realizado por transportador retalhista (T.R.R.) | AK12: DEMAIS | AL12: ATIVA | AM12: https://lrflideres.com.br/wp-content/uploads/2022/08/4.-EDITAL-2a-LISTA-DE-CREDORES.pdf | AN12: p1 r24 | AO12: p1: R$ 120.950,00 | AP12: AJ_LIST | AQ12: 2023-12-04 | AR12: OK | AS12: ROWS:p1r24 | AT12: 1355f93a13cd
A13: 12 | B13: NEW | D13: 0 | I13: MASTERSENSE INGREDIENTES ALIMENTICIOS LTDA | J13: MASTERSENSE INGREDIENTES ALIMENTICIOS LTDA | K13: 03161388 | L13: 03161388000109 | M13: 119306.11 | N13: 1 | O13: UNKNOWN | R13: =IF(Q13="","",ROUND((TODAY()-Q13)/365.25,1)) | S13: =VLOOKUP(O13,Assumptions!$A$7:$E$10,2,FALSE) | T13: =MAX(0.5,VLOOKUP(O13,Assumptions!$A$7:$E$10,3,FALSE)+VLOOKUP(O13,Assumptions!$A$7:$E$10,4,FALSE)/2-IF(R13="",0,R13)) | U13: =M13*S13/(1+Assumptions!$B$3)^T13 | V13: =IF(M13=0,"",ROUND(U13/M13*100,1)) | W13: =U13*Assumptions!$B$4 | X13: =IF(M13=0,"",ROUND(W13/M13*100,1)) | Z13: (not found in document) | AB13: bernardobicalho.com.br | AC13: GUSTAVO ASSIS RODRIGUES | AD13: Sócio-Administrador | AE13: (11) 3109-3108 | AH13: SP | AI13: JUNDIAI | AJ13: Comércio atacadista de produtos alimentícios em geral | AK13: DEMAIS | AL13: ATIVA | AM13: http://bernardobicalho.com.br/login/app/documents/Rela%C3%A7%C3%A3o%20de%20Credores/6.%20RVC-%20Nutricium%20-%20simplificada.pdf | AN13: p3 r25 | AO13: p3: R$ 119.306,11 | AP13: AJ_LIST | AR13: OK | AS13: CASE_NUMBER_MISSING ROWS:p3r25 | AT13: 6a92d74da333
