Workbook

Sheet README
A1: ANTEPARO — CALL SHEET
A2: Run 20260903T230425Z-e7c9a7 · generated 2026-09-05 · 559 leads ≥ R$200k · 236 pooling leads (R$100–200k) · 1199 source documents · 527 cases
A4: WHAT EACH ROW IS
A5: One company × one recovery case. The company holds class III (trade) credit against the debtor, admitted in the court's own creditor list. All establishments of the company (same 8-digit CNPJ root) are summed.
A7: THE NUMBER
A8: 'Class III face' is the admitted value AS PRINTED in the court document — what the company is OWED, updated only to the filing date (art. 9 II). It is NOT what will be paid.
A9: 'OUR QUOTE' is a model: face → assumed plan terms → discounted at the investor IRR → fund price → our share. Edit the Assumptions tab. It is not court data.
A11: PROOF OF CLAIM (green columns)
A12: Click 'PROOF: source document', go to the page/row listed, and read the value as printed. If a seller asks 'how did you get this?', that link is the answer.
A13: 'Reconciled' = OK means the document's extracted class totals matched its own printed totals within 0.5%. OK_NO_TOTALS means the document prints no totals — the number was read from its own row but could not be cross-checked; quote with that caveat.
A15: DECISION-MAKER
A16: From the Receita Federal partner register (sócio-administrador / administrador / diretor / presidente). Phone and email are the company's registry contact. Confidence LOW = registry only; nothing here was guessed or looked up from memory.
... A22: Individuals (CPF), banks (CNAE 64–66), public entities, inactive companies, foreign-currency claims, extraconcursal sections, quarantined documents. They remain in the CSV tables with flags.

Sheet Assumptions
A1: PRICING ASSUMPTIONS — edit the yellow cells; every quote on the call sheet recalculates
A3: Target investor IRR (annual) | B3: 0.25 | F3: Fund price = face × recovery% ÷ (1+IRR)^(years to payment). A fund needing 25% IRR on a plan paying 30% over years 3–10 pays ~8 cents, not 25 — check the 7 buyers' real numbers against this.
A4: Buy price as share of fund price (we pay 60% → 0.60) | B4: 0.6 | F4: Our quote = fund price × this share. The doc rule is 60% of mandate price; expected 55–70% once Gate 6 data exists.
A6: Debtor band | B6: Class III recovery % of face | C6: Grace (years) | D6: Term (years) | E6: Plan lag (years) | F6: Note
A7: A | B7: 0.4 | C7: 2 | D7: 8 | E7: 1.5 | F7: Recovery GRANTED (art. 58): plan approved by the creditors and granted by the court; payments run from the grant
A8: B | B8: 0.3 | C8: 2 | D8: 8 | E8: 1.5 | F8: Live case filed within the last 2 years, plan filed (art. 53) or pending — not yet granted; the payment clock has not started
A9: C | B9: 0.15 | C9: 3 | D9: 10 | E9: 2.5 | F9: Older case (filed >2 y ago) or dormant/closed with no grant seen: a plan very probably exists but is not in our documents — check the docket before quoting
A10: D | B10: 0.03 | C10: 0 | D10: 0 | E10: 6 | F10: Not in the book: falência decreed, RJ extinguished, or the company is closed (baixada) at RFB — rows go to EXCLUDED (review)
A11: U | B11: 0.25 | C11: 3 | D11: 8 | E11: 2.5 | F11: Unresolved: debtor or case not identified — kept on PRICING HOLD (zero quote) until the case is found
A13: Everything in this tab is an ASSUMPTION, not court data. The face value on the call sheet IS court data — it links to the page.

Sheet Call List
A1: Rank | B1: Status | C1: Owner | D1: Attempts | E1: Last touch | F1: Next action | G1: Next date | H1: Notes | I1: Company (RFB) | J1: Name as printed | K1: CNPJ root | L1: Establishment CNPJs | M1: Class III face (R$) | N1: Claims | O1: Debtor band | P1: Stage | Q1: Case filed | R1: Years since filing | S1: Est. recovery % | T1: Years to payment (est.) | U1: Fund price @ IRR (R$) | V1: Fund price (cents) | W1: OUR QUOTE (R$) | X1: Quote (cents) | Y1: Debtor | Z1: Case number | AA1: Court | AB1: Administrator (site) | AC1: Decision-maker | AD1: Role | AE1: Phone | AF1: Phone 2 | AG1: Email | AH1: UF | AI1: City | AJ1: CNAE | AK1: Porte | AL1: Situação | AM1: PROOF: source document | AN1: Page / row | AO1: Value as printed | AP1: Which list | AQ1: Published | AR1: Reconciled | AS1: Data flags | AT1: Doc id
A2: 1 | B2: NEW | D2: 0 | I2: PETROLEO BRASILEIRO S A PETROBRAS | J2: Petróleo Brasileiro S.A. (Petrobras) | K2: 33000167 | L2: 33000167000101 | M2: 3.3005476e+08 | N2: 1 | O2: B | Q2: 45756 | R2: =IF(Q2="","",ROUND((TODAY()-Q2)/365.25,1)) | S2: =IFERROR(VLOOKUP(O2,Assumptions!$A$7:$F$11,2,FALSE),0.25) | T2: =IF(O2="A",MAX(1,IFERROR(VLOOKUP(O2,Assumptions!$A$7:$F$11,3,FALSE),3)+IFERROR(VLOOKUP(O2,Assumptions!$A$7:$F$11,4,FALSE),8)/2-MAX(0,IF(R2="",0,R2)-IFERROR(VLOOKUP(O2,Assumptions!$A$7:$F$11,5,FALSE),1.5))),IFERROR(VLOOKUP(O2,Assumptions!$A$7:$F$11,5,FALSE),2.5)+IFERROR(VLOOKUP(O2,Assumptions!$A$7:$F$11,3,FALSE),3)+IFERROR(VLOOKUP(O2,Assumptions!$A$7:$F$11,4,FALSE),8)/2) | U2: =M2*S2/(1+Assumptions!$B$3)^T2 | V2: =IF(M2=0,"",ROUND(U2/M2*100,1)) | W2: =U2*Assumptions!$B$4 | X2: =IF(M2=0,"",ROUND(W2/M2*100,1)) | Y2: GRUPO EGESA (EGESA ENG S.A, EGESUR PART E EMP S.A, MATRIX INFRA LTDA, BEMVIVER ENG AMBIENTAL E SERV LTDA, DKF CONST E EMP LTDA, EGEPEL LTDA, ETR ASSESSORIA EMP E PART LTDA, MVT ENG E SERV LTDA, PARQUES DO VALE LTDA, ELMO RIBEIRO E ANA RIBEIRO) | Z2: 5088952-81.2025.8.13.0024 | AA2: TJMG | AB2: scalzilliaj.com.br | AC2: MAGDA MARIA DE REGINA CHAMBRIARD | AD2: Presidente | AE2: (21) 2166-0000 | AH2: RJ | AI2: RIO DE JANEIRO | AJ2: Extração de petróleo e gás natural | AK2: DEMAIS | AL2: ATIVA | AM2: https://scalzilliaj.com.br/sgc/download.php?file=files/processo_documento/processo_documento09514021082025_1_.pdf&nome=04 - Relação de credores das Recuperandas | AN2: p71 r9 | AO2: p71: R$ 330.054.762,86 | AP2: DEBTOR_LIST | AR2: OK | AS2: ROWS:p71r9 VALUE_COL:Valor_Atualizado CASE_NUMBER_CORRECTED CASE_FROM_PORTAL | AT2: 24ed98480a57
A3: 2 | B3: NEW | D3: 0 | I3: DM CONSTRUTORA DE OBRAS LTDA | J3: DM Construtora de Obras LTDA | K3: 76483726 | L3: 76483726000194 | M3: 1.7805218e+08 | N3: 1 | O3: B | P3: ACTIVE | Q3: 45833 | R3: =IF(Q3="","",ROUND((TODAY()-Q3)/365.25,1)) | S3: =IFERROR(VLOOKUP(O3,Assumptions!$A$7:$F$11,2,FALSE),0.25) | T3: =IF(O3="A",MAX(1,IFERROR(VLOOKUP(O3,Assumptions!$A$7:$F$11,3,FALSE),3)+IFERROR(VLOOKUP(O3,Assumptions!$A$7:$F$11,4,FALSE),8)/2-MAX(0,IF(R3="",0,R3)-IFERROR(VLOOKUP(O3,Assumptions!$A$7:$F$11,5,FALSE),1.5))),IFERROR(VLOOKUP(O3,Assumptions!$A$7:$F$11,5,FALSE),2.5)+IFERROR(VLOOKUP(O3,Assumptions!$A$7:$F$11,3,FALSE),3)+IFERROR(VLOOKUP(O3,Assumptions!$A$7:$F$11,4,FALSE),8)/2) | U3: =M3*S3/(1+Assumptions!$B$3)^T3 | V3: =IF(M3=0,"",ROUND(U3/M3*100,1)) | W3: =U3*Assumptions!$B$4 | X3: =IF(M3=0,"",ROUND(W3/M3*100,1)) | Y3: GRUPO MARINGÁ PARK | Z3: 0016033-22.2025.8.16.0017 | AA3: TJPR | AB3: marquesadmjudicial.com.br | AC3: DENIZ ALBINO FANTIN | AD3: Sócio-Administrador | AE3: (41) 3313-8000 | AF3: (41) 3313-8090 | AH3: PR | AI3: CURITIBA | AJ3: Construção de rodovias e ferrovias | AK3: DEMAIS | AL3: ATIVA | AM3: https://marquesadmjudicial.com.br/sgc/download.php?file=files/processo_documento/processo_documento19270817122025_1_.pdf&nome=Relação Nominal de Credores AJ | AN3: p4 r8 | AO3: p4: R$ 178.052.183,86 | AP3: AJ_LIST | AQ3: 2025-12-17 | AR3: OK | AS3: ROWS:p4r8 | AT3: fcb10a251582
A4: 3 | B4: NEW | D4: 0 | I4: TAG INDUSTRIA E LAMINACAO LTDA | J4: TAG INDUSTRIA E LAMINACAO LTDA | K4: 33233778 | L4: 33233778000108 | M4: 64713515 | N4: 2 | O4: C | P4: ACTIVE | Q4: 45068 | R4: =IF(Q4="","",ROUND((TODAY()-Q4)/365.25,1)) | S4: =IFERROR(VLOOKUP(O4,Assumptions!$A$7:$F$11,2,FALSE),0.25) | T4: =IF(O4="A",MAX(1,IFERROR(VLOOKUP(O4,Assumptions!$A$7:$F$11,3,FALSE),3)+IFERROR(VLOOKUP(O4,Assumptions!$A$7:$F$11,4,FALSE),8)/2-MAX(0,IF(R4="",0,R4)-IFERROR(VLOOKUP(O4,Assumptions!$A$7:$F$11,5,FALSE),1.5))),IFERROR(VLOOKUP(O4,Assumptions!$A$7:$F$11,5,FALSE),2.5)+IFERROR(VLOOKUP(O4,Assumptions!$A$7:$F$11,3,FALSE),3)+IFERROR(VLOOKUP(O4,Assumptions!$A$7:$F$11,4,FALSE),8)/2) | U4: =M4*S4/(1+Assumptions!$B$3)^T4 | V4: =IF(M4=0,"",ROUND(U4/M4*100,1)) | W4: =U4*Assumptions!$B$4 | X4: =IF(M4=0,"",ROUND(W4/M4*100,1)) | Y4: Grupo Conduscabos | Z4: 8005129-09.2023.8.05.0039 | AA4: TJBA | AB4: assistjud.com.br | AC4: TIAGO RODRIGO DETTILIO | AD4: Administrador | AE4: (11) 4463-4833 | AH4: SP | AI4: SAO PAULO | AJ4: Outras atividades profissionais, científicas e técnicas não especificadas anteriormente | AK4: DEMAIS | AL4: ATIVA | AM4: https://assistjud.com.br/wp-content/uploads/elementor/forms/65098c80a5824.pdf | AN4: p10 r4; p19 r8 | AO4: p10: R$ 32.731.819,08; p19: R$ 31.981.695,98 | AP4: AJ_LIST | AQ4: 2023-09-18 | AR4: OK_NO_TOTALS | AS4: ROWS:p10r4,p19r8 UNRECONCILED_SOURCE | AT4: a0ae32a59c29
A5: 4 | B5: NEW | D5: 0 | I5: IBIPORA NEGOCIOS IMOBILIARIOS S.A. | J5: IBIPORA NEGOCIOS IMOBILIARIOS S.A. | K5: 19256534 | L5: 19256534000101 | M5: 45075483 | N5: 1 | O5: B | Q5: 45756 | R5: =IF(Q5="","",ROUND((TODAY()-Q5)/365.25,1)) | S5: =IFERROR(VLOOKUP(O5,Assumptions!$A$7:$F$11,2,FALSE),0.25) | T5: =IF(O5="A",MAX(1,IFERROR(VLOOKUP(O5,Assumptions!$A$7:$F$11,3,FALSE),3)+IFERROR(VLOOKUP(O5,Assumptions!$A$7:$F$11,4,FALSE),8)/2-MAX(0,IF(R5="",0,R5)-IFERROR(VLOOKUP(O5,Assumptions!$A$7:$F$11,5,FALSE),1.5))),IFERROR(VLOOKUP(O5,Assumptions!$A$7:$F$11,5,FALSE),2.5)+IFERROR(VLOOKUP(O5,Assumptions!$A$7:$F$11,3,FALSE),3)+IFERROR(VLOOKUP(O5,Assumptions!$A$7:$F$11,4,FALSE),8)/2) | U5: =M5*S5/(1+Assumptions!$B$3)^T5 | V5: =IF(M5=0,"",ROUND(U5/M5*100,1)) | W5: =U5*Assumptions!$B$4 | X5: =IF(M5=0,"",ROUND(W5/M5*100,1)) | Y5: GRUPO EGESA (EGESA ENG S.A, EGESUR PART E EMP S.A, MATRIX INFRA LTDA, BEMVIVER ENG AMBIENTAL E SERV LTDA, DKF CONST E EMP LTDA, EGEPEL LTDA, ETR ASSESSORIA EMP E PART LTDA, MVT ENG E SERV LTDA, PARQUES DO VALE LTDA, ELMO RIBEIRO E ANA RIBEIRO) | Z5: 5088952-81.2025.8.13.0024 | AA5: TJMG | AB5: scalzilliaj.com.br | AC5: JOSE JULIO COSTA NETO | AD5: Presidente | AE5: (31) 3586-9418 | AH5: MG | AI5: NOVA LIMA | AJ5: Compra e venda de imóveis próprios | AK5: DEMAIS | AL5: ATIVA | AM5: https://scalzilliaj.com.br/sgc/download.php?file=files/processo_documento/processo_documento09514021082025_1_.pdf&nome=04 - Relação de credores das Recuperandas | AN5: p68 r4 | AO5: p68: R$ 45.075.482,57 | AP5: DEBTOR_LIST | AR5: OK | AS5: ROWS:p68r4 VALUE_COL:Valor_Atualizado CASE_NUMBER_CORRECTED CASE_FROM_PORTAL | AT5: 24ed98480a57
A6: 5 | B6: NEW | D6: 0 | I6: COMPANHIA ESTADUAL DE DISTRIBUICAO DE ENERGIA ELETRICA - CEEE-D | J6: CIA.EST.DE ENERG.ELETRICA-CEE ( | K6: 08467115 | L6: 08467115000100 | M6: 31446844 | N6: 1 | O6: C | P6: ACTIVE | Q6: 44735 | R6: =IF(Q6="","",ROUND((TODAY()-Q6)/365.25,1)) | S6: =IFERROR(VLOOKUP(O6,Assumptions!$A$7:$F$11,2,FALSE),0.25) | T6: =IF(O6="A",MAX(1,IFERROR(VLOOKUP(O6,Assumptions!$A$7:$F$11,3,FALSE),3)+IFERROR(VLOOKUP(O6,Assumptions!$A$7:$F$11,4,FALSE),8)/2-MAX(0,IF(R6="",0,R6)-IFERROR(VLOOKUP(O6,Assumptions!$A$7:$F$11,5,FALSE),1.5))),IFERROR(VLOOKUP(O6,Assumptions!$A$7:$F$11,5,FALSE),2.5)+IFERROR(VLOOKUP(O6,Assumptions!$A$7:$F$11,3,FALSE),3)+IFERROR(VLOOKUP(O6,Assumptions!$A$7:$F$11,4,FALSE),8)/2) | U6: =M6*S6/(1+Assumptions!$B$3)^T6 | V6: =IF(M6=0,"",ROUND(U6/M6*100,1)) | W6: =U6*Assumptions!$B$4 | X6: =IF(M6=0,"",ROUND(W6/M6*100,1)) | Y6: ASSOCIAÇÃO DE CARIDADE SANTA CASA DO RIO GRANDE | Z6: 5012306-16.2022.8.21.0023 | AA6: TJRS | AB6: scalzilliaj.com.br | AC6: RIBERTO JOSE BARBANERA | AD6: Presidente | AE6: (98) 3217-8000 | AH6: RS | AI6: PORTO ALEGRE | AJ6: Distribuição de energia elétrica | AK6: DEMAIS | AL6: ATIVA | AM6: https://scalzilliaj.com.br/sgc/download.php?file=files/processo_documento/processo_documento09120721032023_1_.pdf&nome=15 - Edital do art. 7º, §2º e 53 da Lei 11.101/2005 (segunda lista de credores e recebimento do plano)) | AN6: p26 r26 | AO6: p26: R$ 31.446.843,91 | AP6: AJ_LIST | AQ6: 2023-03-21 | AR6: OK_NO_TOTALS | AS6: ROWS:p26r26 UNRECONCILED_SOURCE | AT6: ebfb999b457c
A7: 6 | B7: NEW | D7: 0 | I7: HYPERA S.A. | J7: Hypera S/A | K7: 02932074 | L7: 02932074004260 | M7: 25912508 | N7: 1 | O7: C | P7: ACTIVE | Q7: 44987 | R7: =IF(Q7="","",ROUND((TODAY()-Q7)/365.25,1)) | S7: =IFERROR(VLOOKUP(O7,Assumptions!$A$7:$F$11,2,FALSE),0.25) | T7: =IF(O7="A",MAX(1,IFERROR(VLOOKUP(O7,Assumptions!$A$7:$F$11,3,FALSE),3)+IFERROR(VLOOKUP(O7,Assumptions!$A$7:$F$11,4,FALSE),8)/2-MAX(0,IF(R7="",0,R7)-IFERROR(VLOOKUP(O7,Assumptions!$A$7:$F$11,5,FALSE),1.5))),IFERROR(VLOOKUP(O7,Assumptions!$A$7:$F$11,5,FALSE),2.5)+IFERROR(VLOOKUP(O7,Assumptions!$A$7:$F$11,3,FALSE),3)+IFERROR(VLOOKUP(O7,Assumptions!$A$7:$F$11,4,FALSE),8)/2) | U7: =M7*S7/(1+Assumptions!$B$3)^T7 | V7: =IF(M7=0,"",ROUND(U7/M7*100,1)) | W7: =U7*Assumptions!$B$4 | X7: =IF(M7=0,"",ROUND(W7/M7*100,1)) | Y7: GRUPO DP4 | Z7: 0005010-98.2023.8.16.0001 | AA7: TJPR | AB7: marquesadmjudicial.com.br | AC7: BRENO TOLEDO PIRES DE OLIVEIRA | AD7: Presidente | AE7: (62) 3878-8150 | AH7: SP | AI7: SAO PAULO | AJ7: Comércio atacadista de medicamentos e drogas de uso humano | AK7: DEMAIS | AL7: ATIVA | AM7: https://marquesadmjudicial.com.br/sgc/download.php?file=files/processo_documento/processo_documento15293208032024_1_.pdf&nome=Relação Nominal de Credores da AJ-Sintética | AN7: p26 r9 | AO7: p26: R$ 25.912.507,68 | AP7: AJ_LIST | AQ7: 2023-03-02 | AR7: QUARANTINED | AS7: PARTIAL_DOC_CLASS_III_RECONCILED ROWS:p26r9 | AT7: b465a5d11eec
A8: 7 | B8: NEW | D8: 0 | I8: ADLIM-TERCEIRIZACAO EM SERVICOS LTDA - EM RECUPERACAO JUDICIAL | J8: ADLIM TERCEIRIZACAO EM SERVICOS LTDA, CPF/CNPJ/OAB nº | K8: 11436813 | L8: 11436813000145 | M8: 20647588 | N8: 2 | O8: B | P8: ACTIVE | Q8: 45349 | R8: =IF(Q8="","",ROUND((TODAY()-Q8)/365.25,1)) | S8: =IFERROR(VLOOKUP(O8,Assumptions!$A$7:$F$11,2,FALSE),0.25) | T8: =IF(O8="A",MAX(1,IFERROR(VLOOKUP(O8,Assumptions!$A$7:$F$11,3,FALSE),3)+IFERROR(VLOOKUP(O8,Assumptions!$A$7:$F$11,4,FALSE),8)/2-MAX(0,IF(R8="",0,R8)-IFERROR(VLOOKUP(O8,Assumptions!$A$7:$F$11,5,FALSE),1.5))),IFERROR(VLOOKUP(O8,Assumptions!$A$7:$F$11,5,FALSE),2.5)+IFERROR(VLOOKUP(O8,Assumptions!$A$7:$F$11,3,FALSE),3)+IFERROR(VLOOKUP(O8,Assumptions!$A$7:$F$11,4,FALSE),8)/2) | U8: =M8*S8/(1+Assumptions!$B$3)^T8 | V8: =IF(M8=0,"",ROUND(U8/M8*100,1)) | W8: =U8*Assumptions!$B$4 | X8: =IF(M8=0,"",ROUND(W8/M8*100,1)) | Y8: GRUPO ADLIM | Z8: 0019761-43.2024.8.17.2001 | AA8: TJPE | AB8: lrflideres.com.br | AC8: JONAS ALVARENGA DA SILVA | AD8: Sócio-Administrador | AH8: PE | AI8: BEZERROS | AJ8: Fornecimento e gestão de recursos humanos para terceiros | AK8: DEMAIS | AL8: ATIVA | AM8: https://lrflideres.com.br/wp-content/plugins/download-attachments/includes/download.php?id=6051 | AN8: p85 r37; p97 r26 | AO8: p85: R$ 13674501,07; p97: R$ 6973087,07 | AP8: AJ_LIST | AQ8: 2024-08-12 | AR8: QUARANTINED | AS8: PARTIAL_DOC_CLASS_III_RECONCILED ROWS:p85r37,p97r26 | AT8: a32497797bac
A9: 8 | B9: NEW | D9: 0 | I9: SPC BRASIL S.A. | J9: BRASIL S.A | K9: 29341643 | L9: 29341643000342 | M9: 18875474 | N9: 1 | O9: B | P9: ACTIVE | Q9: 46048 | R9: =IF(Q9="","",ROUND((TODAY()-Q9)/365.25,1)) | S9: =IFERROR(VLOOKUP(O9,Assumptions!$A$7:$F$11,2,FALSE),0.25) | T9: =IF(O9="A",MAX(1,IFERROR(VLOOKUP(O9,Assumptions!$A$7:$F$11,3,FALSE),3)+IFERROR(VLOOKUP(O9,Assumptions!$A$7:$F$11,4,FALSE),8)/2-MAX(0,IF(R9="",0,R9)-IFERROR(VLOOKUP(O9,Assumptions!$A$7:$F$11,5,FALSE),1.5))),IFERROR(VLOOKUP(O9,Assumptions!$A$7:$F$11,5,FALSE),2.5)+IFERROR(VLOOKUP(O9,Assumptions!$A$7:$F$11,3,FALSE),3)+IFERROR(VLOOKUP(O9,Assumptions!$A$7:$F$11,4,FALSE),8)/2) | U9: =M9*S9/(1+Assumptions!$B$3)^T9 | V9: =IF(M9=0,"",ROUND(U9/M9*100,1)) | W9: =U9*Assumptions!$B$4 | X9: =IF(M9=0,"",ROUND(W9/M9*100,1)) | Y9: GRUPO GLP | Z9: 0001639-09.2026.8.17.2810 | AA9: TJPE | AB9: recuperasolucoes.com | AC9: ROQUE PELLIZZARO JUNIOR | AD9: Presidente | AE9: (11) 3549-6800 | AH9: SP | AI9: BARUERI | AJ9: Portais, provedores de conteúdo e outros serviços de informação na internet | AK9: DEMAIS | AL9: ATIVA | AM9: https://recuperasolucoes.com/wp-content/plugins/download-attachments/includes/download.php?id=1597 | AN9: p13 r8 | AO9: p13: R$ 18.875.473,82 | AP9: DEBTOR_LIST | AQ9: 2026-05-21 | AR9: OK | AS9: ROWS:p13r8 | AT9: 5da7b77bb569
A10: 9 | B10: NEW | D10: 0 | I10: COMPANHIA RIOGRANDENSE DE SANEAMENTO - CORSAN | J10: CIA.RIOGRANDENSE SANEAMENTO CORSAN ( | K10: 92802784 | L10: 92802784000190 | M10: 18555955 | N10: 1 | O10: C | P10: ACTIVE | Q10: 44735 | R10: =IF(Q10="","",ROUND((TODAY()-Q10)/365.25,1)) | S10: =IFERROR(VLOOKUP(O10,Assumptions!$A$7:$F$11,2,FALSE),0.25) | T10: =IF(O10="A",MAX(1,IFERROR(VLOOKUP(O10,Assumptions!$A$7:$F$11,3,FALSE),3)+IFERROR(VLOOKUP(O10,Assumptions!$A$7:$F$11,4,FALSE),8)/2-MAX(0,IF(R10="",0,R10)-IFERROR(VLOOKUP(O10,Assumptions!$A$7:$F$11,5,FALSE),1.5))),IFERROR(VLOOKUP(O10,Assumptions!$A$7:$F$11,5,FALSE),2.5)+IFERROR(VLOOKUP(O10,Assumptions!$A$7:$F$11,3,FALSE),3)+IFERROR(VLOOKUP(O10,Assumptions!$A$7:$F$11,4,FALSE),8)/2) | U10: =M10*S10/(1+Assumptions!$B$3)^T10 | V10: =IF(M10=0,"",ROUND(U10/M10*100,1)) | W10: =U10*Assumptions!$B$4 | X10: =IF(M10=0,"",ROUND(W10/M10*100,1)) | Y10: ASSOCIAÇÃO DE CARIDADE SANTA CASA DO RIO GRANDE | Z10: 5012306-16.2022.8.21.0023 | AA10: TJRS | AB10: scalzilliaj.com.br | AC10: ANGELO AUGUSTO MENDES | AD10: Diretor | AE10: (05) 1215-5789 | AH10: RS | AI10: PORTO ALEGRE | AJ10: Captação, tratamento e distribuição de água | AK10: DEMAIS | AL10: ATIVA | AM10: https://scalzilliaj.com.br/sgc/download.php?file=files/processo_documento/processo_documento09120721032023_1_.pdf&nome=15 - Edital do art. 7º, §2º e 53 da Lei 11.101/2005 (segunda lista de credores e recebimento do plano)) | AN10: p26 r27 | AO10: p26: R$ 18.555.954,55 | AP10: AJ_LIST | AQ10: 2023-03-21 | AR10: OK_NO_TOTALS | AS10: ROWS:p26r27 UNRECONCILED_SOURCE | AT10: ebfb999b457c
A11: 10 | B11: NEW | D11: 0 | I11: DREYMOOR BRASIL COMERCIO DE FERTILIZANTES LTDA | J11: DREYMOOR BRASIL COMÉRCIO DE FERTILIZANTES LTDA | K11: 26419229 | L11: 26419229000159 | M11: 15134865 | N11: 1 | O11: D | Q11: 45862 | R11: =IF(Q11="","",ROUND((TODAY()-Q11)/365.25,1)) | S11: =IFERROR(VLOOKUP(O11,Assumptions!$A$7:$F$11,2,FALSE),0.25) | T11: =IF(O11="A",MAX(1,IFERROR(VLOOKUP(O11,Assumptions!$A$7:$F$11,3,FALSE),3)+IFERROR(VLOOKUP(O11,Assumptions!$A$7:$F$11,4,FALSE),8)/2-MAX(0,IF(R11="",0,R11)-IFERROR(VLOOKUP(O11,Assumptions!$A$7:$F$11,5,FALSE),1.5))),IFERROR(VLOOKUP(O11,Assumptions!$A$7:$F$11,5,FALSE),2.5)+IFERROR(VLOOKUP(O11,Assumptions!$A$7:$F$11,3,FALSE),3)+IFERROR(VLOOKUP(O11,Assumptions!$A$7:$F$11,4,FALSE),8)/2) | U11: =M11*S11/(1+Assumptions!$B$3)^T11 | V11: =IF(M11=0,"",ROUND(U11/M11*100,1)) | W11: =U11*Assumptions!$B$4 | X11: =IF(M11=0,"",ROUND(W11/M11*100,1)) | Y11: JOB FERTILIZANTES LTDA | Z11: 5000561-63.2025.8.24.0536 | AA11: TJSC | AB11: scalzilliaj.com.br | AC11: MAURICIO GIORDANI BODANESE | AD11: Administrador | AE11: (41) 3209-6613 | AH11: PR | AI11: CURITIBA | AJ11: Comércio atacadista de defensivos agrícolas, adubos, fertilizantes e corretivos do solo | AK11: DEMAIS | AL11: ATIVA | AM11: https://scalzilliaj.com.br/sgc/download.php?file=files/processo_documento/processo_documento13183320052026_1_.pdf&nome=10 - QGC Provisório - atualizado até Maio de 2026 | AN11: p1 r9 | AO11: p1: R$ 15.134.865,10 | AP11: QGC | AR11: OK_NO_TOTALS | AS11: CASE_NUMBER_MISSING ROWS:p1r9 UNRECONCILED_SOURCE VALUE_COL:Valor_Do_Crédito CASE_FROM_PORTAL | AT11: 8b4c169de629
A12: 11 | B12: NEW | D12: 0 | I12: FRESENIUS MEDICAL CARE LTDA | J12: FRESENIUS MEDICAL CARE LTDA | K12: 01440590 | L12: 01440590000136 | M12: 14567734 | N12: 1 | O12: U | R12: =IF(Q12="","",ROUND((TODAY()-Q12)/365.25,1)) | S12: =IFERROR(VLOOKUP(O12,Assumptions!$A$7:$F$11,2,FALSE),0.25) | T12: =IF(O12="A",MAX(1,IFERROR(VLOOKUP(O12,Assumptions!$A$7:$F$11,3,FALSE),3)+IFERROR(VLOOKUP(O12,Assumptions!$A$7:$F$11,4,FALSE),8)/2-MAX(0,IF(R12="",0,R12)-IFERROR(VLOOKUP(O12,Assumptions!$A$7:$F$11,5,FALSE),1.5))),IFERROR(VLOOKUP(O12,Assumptions!$A$7:$F$11,5,FALSE),2.5)+IFERROR(VLOOKUP(O12,Assumptions!$A$7:$F$11,3,FALSE),3)+IFERROR(VLOOKUP(O12,Assumptions!$A$7:$F$11,4,FALSE),8)/2) | U12: =M12*S12/(1+Assumptions!$B$3)^T12 | V12: =IF(M12=0,"",ROUND(U12/M12*100,1)) | W12: =U12*Assumptions!$B$4 | X12: =IF(M12=0,"",ROUND(W12/M12*100,1)) | Z12: (not found in document) | AB12: bernardobicalho.com.br | AC12: ANA LUCIA ZENKNER PERCIA | AD12: Administrador | AE12: (19) 3847-9700 | AF12: (19) 3847-9700 | AH12: SP | AI12: JAGUARIUNA | AJ12: Fabricação de medicamentos alopáticos para uso humano | AK12: DEMAIS | AL12: ATIVA | AM12: http://bernardobicalho.com.br/login/app/documents/Rela%C3%A7%C3%A3o%20de%20Credores/6.%20RVC-%20Nutricium%20-%20simplificada.pdf | AN12: p3 r16 | AO12: p3: R$ 14.567.733,99 | AP12: AJ_LIST | AR12: OK | AS12: CASE_NUMBER_MISSING ROWS:p3r16 | AT12: 6a92d74da333
A13: 12 | B13: NEW | D13: 0 | I13: VINICOLA CAMPESTRE LTDA | J13: VINICOLA CAMPESTRE LTDA | K13: 98521909 | L13: 98521909000190, 98521909000270 | M13: 13980346 | N13: 2 | O13: B | P13: ACTIVE | Q13: 45685 | R13: =IF(Q13="","",ROUND((TODAY()-Q13)/365.25,1)) | S13: =IFERROR(VLOOKUP(O13,Assumptions!$A$7:$F$11,2,FALSE),0.25) | T13: =IF(O13="A",MAX(1,IFERROR(VLOOKUP(O13,Assumptions!$A$7:$F$11,3,FALSE),3)+IFERROR(VLOOKUP(O13,Assumptions!$A$7:$F$11,4,FALSE),8)/2-MAX(0,IF(R13="",0,R13)-IFERROR(VLOOKUP(O13,Assumptions!$A$7:$F$11,5,FALSE),1.5))),IFERROR(VLOOKUP(O13,Assumptions!$A$7:$F$11,5,FALSE),2.5)+IFERROR(VLOOKUP(O13,Assumptions!$A$7:$F$11,3,FALSE),3)+IFERROR(VLOOKUP(O13,Assumptions!$A$7:$F$11,4,FALSE),8)/2) | U13: =M13*S13/(1+Assumptions!$B$3)^T13 | V13: =IF(M13=0,"",ROUND(U13/M13*100,1)) | W13: =U13*Assumptions!$B$4 | X13: =IF(M13=0,"",ROUND(W13/M13*100,1)) | Y13: Grupo Arruda (ARRUDA & MELO REPRESENTACAO DE ALIMENTOS E BEBIDAS LTDA, ARRUDA & MELO COMERCIO E DISTRIBUICAO DE ALIMENTOS E BEBIDAS LTDA, ARRUDA & MELO COMERCIO E DISTRIBUICAO DE ALIMENTOS E BEBIDAS DA BAHIA LTDA) | Z13: 0008526-45.2025.8.17.2001 | AA13: TJPE | AB13: diligence.adm.br | AC13: CESAR AUGUSTO ZANOTTO | AD13: Sócio-Administrador | AE13: (54) 3511-6050 | AF13: (54) 3511-6052 | AH13: RS | AI13: CAMPESTRE DA SERRA | AJ13: Fabricação de vinho | AK13: DEMAIS | AL13: ATIVA | AM13: https://diligence.adm.br/wp-content/uploads/2025/06/Edital-1a-Lista-de-Credores.pdf | AN13: p5 r60; p5 r61 | AO13: p5: R$ 4.421.862,65; p5: R$ 9.558.482,85 | AP13: DEBTOR_LIST | AQ13: 2025-06-10 | AR13: OK | AS13: ROWS:p5r60,p5r61 | AT13: 1658892fa167
A14: 13 | B14: NEW | D14: 0 | I14: AGUIA SERVICOS DE VIGILANCIA LTDA - EM RECUPERACAO JUDICIAL | J14: AGUIA SERVICOS DE VIGILANCIA LTDA, CPF/CNPJ/OAB nº | K14: 11516861 | L14: 11516861000143 | M14: 13645092 | N14: 1 | O14: B | P14: ACTIVE | Q14: 45349 | R14: =IF(Q14="","",ROUND((TODAY()-Q14)/365.25,1)) | S14: =IFERROR(VLOOKUP(O14,Assumptions!$A$7:$F$11,2,FALSE),0.25) | T14: =IF(O14="A",MAX(1,IFERROR(VLOOKUP(O14,Assumptions!$A$7:$F$11,3,FALSE),3)+IFERROR(VLOOKUP(O14,Assumptions!$A$7:$F$11,4,FALSE),8)/2-MAX(0,IF(R14="",0,R14)-IFERROR(VLOOKUP(O14,Assumptions!$A$7:$F$11,5,FALSE),1.5))),IFERROR(VLOOKUP(O14,Assumptions!$A$7:$F$11,5,FALSE),2.5)+IFERROR(VLOOKUP(O14,Assumptions!$A$7:$F$11,3,FALSE),3)+IFERROR(VLOOKUP(O14,Assumptions!$A$7:$F$11,4,FALSE),8)/2) | U14: =M14*S14/(1+Assumptions!$B$3)^T14 | V14: =IF(M14=0,"",ROUND(U14/M14*100,1)) | W14: =U14*Assumptions!$B$4 | X14: =IF(M14=0,"",ROUND(W14/M14*100,1)) | Y14: GRUPO ADLIM | Z14: 0019761-43.2024.8.17.2001 | AA14: TJPE | AB14: lrflideres.com.br | AC14: JONAS ALVARENGA DA SILVA | AD14: Sócio-Administrador | AE14: (81) 3252-6115 | AF14: (81) 3252-6117 | AH14: PE | AI14: RECIFE | AJ14: Atividades de vigilância e segurança privada | AK14: DEMAIS | AL14: ATIVA | AM14: https://lrflideres.com.br/wp-content/plugins/download-attachments/includes/download.php?id=6051 | AN14: p97 r27 | AO14: p97: R$ 13645091,92 | AP14: AJ_LIST | AQ14: 2024-08-12 | AR14: QUARANTINED | AS14: PARTIAL_DOC_CLASS_III_RECONCILED ROWS:p97r27 | AT14: a32497797bac
A15: 14 | B15: NEW | D15: 0 | I15: GREE ELECTRIC APPLIANCES DO BRASIL LTDA. | J15: Avenida dos Oitis, Distrito Industrial, Distr Industrial 2, Manaus/AM - CEP 69007002 | K15: 03519135 | L15: 03519135000156 | M15: 13499976 | N15: 1 | O15: C | R15: =IF(Q15="","",ROUND((TODAY()-Q15)/365.25,1)) | S15: =IFERROR(VLOOKUP(O15,Assumptions!$A$7:$F$11,2,FALSE),0.25) | T15: =IF(O15="A",MAX(1,IFERROR(VLOOKUP(O15,Assumptions!$A$7:$F$11,3,FALSE),3)+IFERROR(VLOOKUP(O15,Assumptions!$A$7:$F$11,4,FALSE),8)/2-MAX(0,IF(R15="",0,R15)-IFERROR(VLOOKUP(O15,Assumptions!$A$7:$F$11,5,FALSE),1.5))),IFERROR(VLOOKUP(O15,Assumptions!$A$7:$F$11,5,FALSE),2.5)+IFERROR(VLOOKUP(O15,Assumptions!$A$7:$F$11,3,FALSE),3)+IFERROR(VLOOKUP(O15,Assumptions!$A$7:$F$11,4,FALSE),8)/2) | U15: =M15*S15/(1+Assumptions!$B$3)^T15 | V15: =IF(M15=0,"",ROUND(U15/M15*100,1)) | W15: =U15*Assumptions!$B$4 | X15: =IF(M15=0,"",ROUND(W15/M15*100,1)) | Y15: REAL DISTRIBUIDORA ÚNICA RIO COMÉRCIO DE REFRIGERAÇÃO LTDA. | Z15: 0873061-47.2023.8.19.0001 | AB15: inova-aj.com.br | AC15: QUNBING ZHAO | AD15: Administrador | AE15: (92) 2123-6900 | AH15: AM | AI15: MANAUS | AJ15: Fabricação de aparelhos e equipamentos de ar condicionado para uso não-industrial | AK15: DEMAIS | AL15: ATIVA | AM15: https://inova-aj.com.br/wp-content/uploads/2026/08/1a-Relacao-de-Credores-Real.pdf | AN15: p1 r32 | AO15: p1: R$ 13.499.976,37 | AP15: AJ_LIST | AQ15: 2023-06-05 | AR15: OK | AS15: ALT_VALUE:R$9.815.941,50 ROWS:p1r32 | AT15: 8eb5d0d64353
A16: 15 | B16: NEW | D16: 0 | I16: LOUIS DREYFUS COMPANY SUCOS S.A | J16: AV. BRIGADEIRO FARIA LIMA, 1355 CJ. 1401 | K16: 00831373 | L16: 00831373000104 | M16: 13129218 | N16: 1 | O16: C | Q16: 44720 | R16: =IF(Q16="","",ROUND((TODAY()-Q16)/365.25,1)) | S16: =IFERROR(VLOOKUP(O16,Assumptions!$A$7:$F$11,2,FALSE),0.25) | T16: =IF(O16="A",MAX(1,IFERROR(VLOOKUP(O16,Assumptions!$A$7:$F$11,3,FALSE),3)+IFERROR(VLOOKUP(O16,Assumptions!$A$7:$F$11,4,FALSE),8)/2-MAX(0,IF(R16="",0,R16)-IFERROR(VLOOKUP(O16,Assumptions!$A$7:$F$11,5,FALSE),1.5))),IFERROR(VLOOKUP(O16,Assumptions!$A$7:$F$11,5,FALSE),2.5)+IFERROR(VLOOKUP(O16,Assumptions!$A$7:$F$11,3,FALSE),3)+IFERROR(VLOOKUP(O16,Assumptions!$A$7:$F$11,4,FALSE),8)/2) | U16: =M16*S16/(1+Assumptions!$B$3)^T16 | V16: =IF(M16=0,"",ROUND(U16/M16*100,1)) | W16: =U16*Assumptions!$B$4 | X16: =IF(M16=0,"",ROUND(W16/M16*100,1)) | Y16: PAULO CÉSAR SOMILIO (produtor rural, pessoa física) | Z16: 1001087-02.2022.8.26.0390 | AA16: TJSP | AB16: brasiltrustee.com.br | AC16: LEONARDO OLIVEIRA D ELIA | AD16: Diretor | AE16: (11) 3039-7160 | AF16: (13) 2127-9893 | AH16: SP | AI16: SAO PAULO | AJ16: Fabricação de sucos concentrados de frutas, hortaliças e legumes | AK16: DEMAIS | AL16: ATIVA | AM16: https://violet-wolf-754008.hostingersite.com/wp-content/uploads/2022/10/Primeiro-Edital-de-Credores-Integral-com-creditos.pdf | AN16: p4 r1 | AO16: p4: R$ 13.129.217,80 | AP16: UNKNOWN | AR16: OK | AS16: ROWS:p4r1 VALUE_COL:Valor CASE_NUMBER_CORRECTED | AT16: cefc6f1f4e0b
A17: 16 | B17: NEW | D17: 0 | I17: TABLEROS IND. E COM. DE PAINEIS LTDA | J17: Tableros Indústria e e Comércio de Painéis Ltda | K17: 09402999 | L17: 09402999000170 | M17: 12966350 | N17: 1 | O17: C | P17: ACTIVE | Q17: 44218 | R17: =IF(Q17="","",ROUND((TODAY()-Q17)/365.25,1)) | S17: =IFERROR(VLOOKUP(O17,Assumptions!$A$7:$F$11,2,FALSE),0.25) | T17: =IF(O17="A",MAX(1,IFERROR(VLOOKUP(O17,Assumptions!$A$7:$F$11,3,FALSE),3)+IFERROR(VLOOKUP(O17,Assumptions!$A$7:$F$11,4,FALSE),8)/2-MAX(0,IF(R17="",0,R17)-IFERROR(VLOOKUP(O17,Assumptions!$A$7:$F$11,5,FALSE),1.5))),IFERROR(VLOOKUP(O17,Assumptions!$A$7:$F$11,5,FALSE),2.5)+IFERROR(VLOOKUP(O17,Assumptions!$A$7:$F$11,3,FALSE),3)+IFERROR(VLOOKUP(O17,Assumptions!$A$7:$F$11,4,FALSE),8)/2) | U17: =M17*S17/(1+Assumptions!$B$3)^T17 | V17: =IF(M17=0,"",ROUND(U17/M17*100,1)) | W17: =U17*Assumptions!$B$4 | X17: =IF(M17=0,"",ROUND(W17/M17*100,1)) | Y17: FORMAPLAN FORMAS PLANEJADAS INDÚSTRIA E COMÉRCIO LTDA | Z17: 0000410-68.2021.8.16.0174 | AA17: TJPR | AB17: marquesadmjudicial.com.br | AC17: MARCIO GERALDO ROSA | AD17: Sócio-Administrador | AE17: (46) 3263-8500 | AH17: PR | AI17: PALMAS | AJ17: Fabricação de madeira laminada e de chapas de madeira compensada, prensada e aglomerada | AK17: DEMAIS | AL17: ATIVA | AM17: https://marquesadmjudicial.com.br/sgc/download.php?file=files/processo_documento/processo_documento15232121112024_1_.pdf&nome=Relação de Credores | AN17: p16 r3 | AO17: p16: R$ 12.966.349,62 | AP17: AJ_LIST | AQ17: 2021-01-22 | AR17: QUARANTINED | AS17: PARTIAL_DOC_CLASS_III_RECONCILED ROWS:p16r3 | AT17: b1a9f73b4c11
A18: 17 | B18: NEW | D18: 0 | I18: GRANELES BRASIL COMERCIAL IMPORTADORA EXPORTADORA AGRICOLA S.A EM RECUPERACAO JUDICIAL | J18: GRANELES BRASIL COMERC IMPORT EXPORTADORA AGRICO | K18: 24785274 | L18: 24785274000444 | M18: 11676960 | N18: 1 | O18: D | Q18: 45862 | R18: =IF(Q18="","",ROUND((TODAY()-Q18)/365.25,1)) | S18: =IFERROR(VLOOKUP(O18,Assumptions!$A$7:$F$11,2,FALSE),0.25) | T18: =IF(O18="A",MAX(1,IFERROR(VLOOKUP(O18,Assumptions!$A$7:$F$11,3,FALSE),3)+IFERROR(VLOOKUP(O18,Assumptions!$A$7:$F$11,4,FALSE),8)/2-MAX(0,IF(R18="",0,R18)-IFERROR(VLOOKUP(O18,Assumptions!$A$7:$F$11,5,FALSE),1.5))),IFERROR(VLOOKUP(O18,Assumptions!$A$7:$F$11,5,FALSE),2.5)+IFERROR(VLOOKUP(O18,Assumptions!$A$7:$F$11,3,FALSE),3)+IFERROR(VLOOKUP(O18,Assumptions!$A$7:$F$11,4,FALSE),8)/2) | U18: =M18*S18/(1+Assumptions!$B$3)^T18 | V18: =IF(M18=0,"",ROUND(U18/M18*100,1)) | W18: =U18*Assumptions!$B$4 | X18: =IF(M18=0,"",ROUND(W18/M18*100,1)) | Y18: JOB FERTILIZANTES LTDA | Z18: 5000561-63.2025.8.24.0536 | AA18: TJSC | AB18: scalzilliaj.com.br | AC18: GABRIEL DE FREITAS MACHADO | AD18: Presidente | AE18: (41) 9539-0828 | AH18: SP | AI18: SAO PAULO | AJ18: Comércio atacadista de produtos alimentícios em geral | AK18: DEMAIS | AL18: ATIVA | AM18: https://scalzilliaj.com.br/sgc/download.php?file=files/processo_documento/processo_documento13183320052026_1_.pdf&nome=10 - QGC Provisório - atualizado até Maio de 2026 | AN18: p1 r10 | AO18: p1: R$ 11.676.960,19 | AP18: QGC | AR18: OK_NO_TOTALS | AS18: CASE_NUMBER_MISSING ROWS:p1r10 UNRECONCILED_SOURCE VALUE_COL:Valor_Do_Crédito CASE_FROM_PORTAL | AT18: 8b4c169de629
A19: 18 | B19: NEW | D19: 0 | I19: ALBAUGH AGRO BRASIL LTDA. | J19: ALBAUGH AGRO BRASIL LTDA | K19: 01789121 | L19: 01789121000470, 01789121000984, 01789121001107 | M19: 11525550 | N19: 1 | O19: B | P19: ACTIVE | Q19: 45845 | R19: =IF(Q19="","",ROUND((TODAY()-Q19)/365.25,1)) | S19: =IFERROR(VLOOKUP(O19,Assumptions!$A$7:$F$11,2,FALSE),0.25) | T19: =IF(O19="A",MAX(1,IFERROR(VLOOKUP(O19,Assumptions!$A$7:$F$11,3,FALSE),3)+IFERROR(VLOOKUP(O19,Assumptions!$A$7:$F$11,4,FALSE),8)/2-MAX(0,IF(R19="",0,R19)-IFERROR(VLOOKUP(O19,Assumptions!$A$7:$F$11,5,FALSE),1.5))),IFERROR(VLOOKUP(O19,Assumptions!$A$7:$F$11,5,FALSE),2.5)+IFERROR(VLOOKUP(O19,Assumptions!$A$7:$F$11,3,FALSE),3)+IFERROR(VLOOKUP(O19,Assumptions!$A$7:$F$11,4,FALSE),8)/2) | U19: =M19*S19/(1+Assumptions!$B$3)^T19 | V19: =IF(M19=0,"",ROUND(U19/M19*100,1)) | W19: =U19*Assumptions!$B$4 | X19: =IF(M19=0,"",ROUND(W19/M19*100,1)) | Y19: SOJAL COMERCIAL AGRICOLA LTDA e OUTROS | Z19: 0804401-51.2025.8.14.0039 | AA19: TJPA | AB19: lrflideres.com.br | AC19: CESAR EMILIANO ROJAS RUIZ | AD19: Administrador | AE19: (11) 3076-4243 | AH19: SP | AI19: SAO PAULO | AJ19: Fabricação de defensivos agrícolas | AK19: DEMAIS | AL19: ATIVA | AM19: https://lrflideres.com.br/wp-content/plugins/download-attachments/includes/download.php?id=6879 | AN19: p1 r4 | AO19: p1: R$ 11.525.550,26 | AP19: AJ_LIST | AQ19: 2026-01-15 | AR19: OK | AS19: ROWS:p1r4 | AT19: c56751547323
A20: 19 | B20: NEW | D20: 0 | I20: DC COMERCIO, REPRESENTACOES, INVESTIMENTOS E PARTICIPACOES LTDA. | J20: DC COMERCIO, REPRESENTACOES, INVESTIMENTOS E PARTICIPACOES LTDA | K20: 09036221 | L20: 09036221000194 | M20: 11125000 | N20: 3 | O20: C | P20: ACTIVE | Q20: 44571 | R20: =IF(Q20="","",ROUND((TODAY()-Q20)/365.25,1)) | S20: =IFERROR(VLOOKUP(O20,Assumptions!$A$7:$F$11,2,FALSE),0.25) | T20: =IF(O20="A",MAX(1,IFERROR(VLOOKUP(O20,Assumptions!$A$7:$F$11,3,FALSE),3)+IFERROR(VLOOKUP(O20,Assumptions!$A$7:$F$11,4,FALSE),8)/2-MAX(0,IF(R20="",0,R20)-IFERROR(VLOOKUP(O20,Assumptions!$A$7:$F$11,5,FALSE),1.5))),IFERROR(VLOOKUP(O20,Assumptions!$A$7:$F$11,5,FALSE),2.5)+IFERROR(VLOOKUP(O20,Assumptions!$A$7:$F$11,3,FALSE),3)+IFERROR(VLOOKUP(O20,Assumptions!$A$7:$F$11,4,FALSE),8)/2) | U20: =M20*S20/(1+Assumptions!$B$3)^T20 | V20: =IF(M20=0,"",ROUND(U20/M20*100,1)) | W20: =U20*Assumptions!$B$4 | X20: =IF(M20=0,"",ROUND(W20/M20*100,1)) | Y20: GRUPO CATTAN | Z20: 0002484-82.2022.8.17.2001 | AA20: TJPE | AB20: lrflideres.com.br | AC20: FERNANDO MELO CATAO | AD20: Sócio-Administrador | AE20: (81) 3032-8400 | AF20: (81) 3419-8550 | AH20: PE | AI20: RECIFE | AJ20: Aluguel de imóveis próprios | AK20: DEMAIS | AL20: ATIVA | AM20: https://lrflideres.com.br/wp-content/plugins/download-attachments/includes/download.php?id=4023 | AN20: p4 r68; p7 r92; p9 r68 | AO20: p4: R$ 1.150.000,00; p7: R$ 9.715.000,00; p9: R$ 260.000,00 | AP20: DEBTOR_LIST | AR20: QUARANTINED | AS20: PARTIAL_DOC_CLASS_III_RECONCILED ROWS:p4r68,p7r92,p9r68 | AT20: f3b6182e3aa2
A21: 20 | B21: NEW | D21: 0 | I21: SANDOZ DO BRASIL INDUSTRIA FARMACEUTICA LTDA. | J21: Sandoz do Brasil Industria Farmaceutica Ltda | K21: 61286647 | L21: 61286647001007 | M21: 10696834 | N21: 1 | O21: C | P21: ACTIVE | Q21: 44987 | R21: =IF(Q21="","",ROUND((TODAY()-Q21)/365.25,1)) | S21: =IFERROR(VLOOKUP(O21,Assumptions!$A$7:$F$11,2,FALSE),0.25) | T21: =IF(O21="A",MAX(1,IFERROR(VLOOKUP(O21,Assumptions!$A$7:$F$11,3,FALSE),3)+IFERROR(VLOOKUP(O21,Assumptions!$A$7:$F$11,4,FALSE),8)/2-MAX(0,IF(R21="",0,R21)-IFERROR(VLOOKUP(O21,Assumptions!$A$7:$F$11,5,FALSE),1.5))),IFERROR(VLOOKUP(O21,Assumptions!$A$7:$F$11,5,FALSE),2.5)+IFERROR(VLOOKUP(O21,Assumptions!$A$7:$F$11,3,FALSE),3)+IFERROR(VLOOKUP(O21,Assumptions!$A$7:$F$11,4,FALSE),8)/2) | U21: =M21*S21/(1+Assumptions!$B$3)^T21 | V21: =IF(M21=0,"",ROUND(U21/M21*100,1)) | W21: =U21*Assumptions!$B$4 | X21: =IF(M21=0,"",ROUND(W21/M21*100,1)) | Y21: GRUPO DP4 | Z21: 0005010-98.2023.8.16.0001 | AA21: TJPR | AB21: marquesadmjudicial.com.br | AC21: BRUNO PETENUCI | AD21: Administrador | AE21: (43) 3174-8000 | AH21: PR | AI21: CAMBE | AJ21: Fabricação de medicamentos alopáticos para uso humano | AK21: DEMAIS | AL21: ATIVA | AM21: https://marquesadmjudicial.com.br/sgc/download.php?file=files/processo_documento/processo_documento15293208032024_1_.pdf&nome=Relação Nominal de Credores da AJ-Sintética | AN21: p31 r4 | AO21: p31: R$ 10.696.833,99 | AP21: AJ_LIST | AQ21: 2023-03-02 | AR21: QUARANTINED | AS21: PARTIAL_DOC_CLASS_III_RECONCILED ROWS:p31r4 | AT21: b465a5d11eec
A22: 21 | B22: NEW | D22: 0 | I22: BASTON INDUSTRIA DE AEROSSOIS LTDA | J22: Baston Industria de Aerossois Ltda | K22: 05855974 | L22: 05855974000170 | M22: 10636330 | N22: 1 | O22: C | P22: ACTIVE | Q22: 44987 | R22: =IF(Q22="","",ROUND((TODAY()-Q22)/365.25,1)) | S22: =IFERROR(VLOOKUP(O22,Assumptions!$A$7:$F$11,2,FALSE),0.25) | T22: =IF(O22="A",MAX(1,IFERROR(VLOOKUP(O22,Assumptions!$A$7:$F$11,3,FALSE),3)+IFERROR(VLOOKUP(O22,Assumptions!$A$7:$F$11,4,FALSE),8)/2-MAX(0,IF(R22="",0,R22)-IFERROR(VLOOKUP(O22,Assumptions!$A$7:$F$11,5,FALSE),1.5))),IFERROR(VLOOKUP(O22,Assumptions!$A$7:$F$11,5,FALSE),2.5)+IFERROR(VLOOKUP(O22,Assumptions!$A$7:$F$11,3,FALSE),3)+IFERROR(VLOOKUP(O22,Assumptions!$A$7:$F$11,4,FALSE),8)/2) | U22: =M22*S22/(1+Assumptions!$B$3)^T22 | V22: =IF(M22=0,"",ROUND(U22/M22*100,1)) | W22: =U22*Assumptions!$B$4 | X22: =IF(M22=0,"",ROUND(W22/M22*100,1)) | Y22: GRUPO DP4 | Z22: 0005010-98.2023.8.16.0001 | AA22: TJPR | AB22: marquesadmjudicial.com.br | AC22: LUIS GUSTAVO MALUCELLI BACILA | AD22: Administrador | AE22: (42) 3252-8120 | AF22: (42) 3252-1705 | AH22: PR | AI22: PALMEIRA | AJ22: Fabricação de outros produtos químicos não especificados anteriormente | AK22: DEMAIS | AL22: ATIVA | AM22: https://marquesadmjudicial.com.br/sgc/download.php?file=files/processo_documento/processo_documento15293208032024_1_.pdf&nome=Relação Nominal de Credores da AJ-Sintética | AN22: p21 r8 | AO22: p21: R$ 10.636.330,31 | AP22: AJ_LIST | AQ22: 2023-03-02 | AR22: QUARANTINED | AS22: PARTIAL_DOC_CLASS_III_RECONCILED ROWS:p21r8 | AT22: b465a5d11eec
A23: 22 | B23: NEW | D23: 0 | I23: ENVTECH DO BRASIL DESCONTAMINACOES INDUSTRIAIS LTDA | J23: Envtech do Brasil Descontaminações Industriais Ltda | K23: 11486977 | L23: 11486977000187 | M23: 10310429 | N23: 1 | O23: B | Q23: 45756 | R23: =IF(Q23="","",ROUND((TODAY()-Q23)/365.25,1)) | S23: =IFERROR(VLOOKUP(O23,Assumptions!$A$7:$F$11,2,FALSE),0.25) | T23: =IF(O23="A",MAX(1,IFERROR(VLOOKUP(O23,Assumptions!$A$7:$F$11,3,FALSE),3)+IFERROR(VLOOKUP(O23,Assumptions!$A$7:$F$11,4,FALSE),8)/2-MAX(0,IF(R23="",0,R23)-IFERROR(VLOOKUP(O23,Assumptions!$A$7:$F$11,5,FALSE),1.5))),IFERROR(VLOOKUP(O23,Assumptions!$A$7:$F$11,5,FALSE),2.5)+IFERROR(VLOOKUP(O23,Assumptions!$A$7:$F$11,3,FALSE),3)+IFERROR(VLOOKUP(O23,Assumptions!$A$7:$F$11,4,FALSE),8)/2) | U23: =M23*S23/(1+Assumptions!$B$3)^T23 | V23: =IF(M23=0,"",ROUND(U23/M23*100,1)) | W23: =U23*Assumptions!$B$4 | X23: =IF(M23=0,"",ROUND(W23/M23*100,1)) | Y23: GRUPO EGESA (EGESA ENG S.A, EGESUR PART E EMP S.A, MATRIX INFRA LTDA, BEMVIVER ENG AMBIENTAL E SERV LTDA, DKF CONST E EMP LTDA, EGEPEL LTDA, ETR ASSESSORIA EMP E PART LTDA, MVT ENG E SERV LTDA, PARQUES DO VALE LTDA, ELMO RIBEIRO E ANA RIBEIRO) | Z23: 5088952-81.2025.8.13.0024 | AA23: TJMG | AB23: scalzilliaj.com.br | AC23: FREDDY VLADIMIR RADA COVALOVA | AD23: Sócio-Administrador | AE23: (31) 8447-7021 | AH23: RJ | AI23: PETROPOLIS | AJ23: Manutenção e reparação de outras máquinas e equipamentos para usos industriais não especificados anteriormente | AK23: DEMAIS | AL23: ATIVA | AM23: https://scalzilliaj.com.br/sgc/download.php?file=files/processo_documento/processo_documento09514021082025_1_.pdf&nome=04 - Relação de credores das Recuperandas | AN23: p66 r6 | AO23: p66: R$ 10.310.428,56 | AP23: DEBTOR_LIST | AR23: OK | AS23: ROWS:p66r6 VALUE_COL:Valor_Atualizado CASE_NUMBER_CORRECTED CASE_FROM_PORTAL | AT23: 24ed98480a57
A24: 23 | B24: NEW | D24: 0 | I24: DANONE LTDA | J24: Danone Ltda | K24: 23643315 | L24: 23643315014455 | M24: 9093937.7 | N24: 1 | O24: C | P24: ACTIVE | Q24: 44987 | R24: =IF(Q24="","",ROUND((TODAY()-Q24)/365.25,1)) | S24: =IFERROR(VLOOKUP(O24,Assumptions!$A$7:$F$11,2,FALSE),0.25) | T24: =IF(O24="A",MAX(1,IFERROR(VLOOKUP(O24,Assumptions!$A$7:$F$11,3,FALSE),3)+IFERROR(VLOOKUP(O24,Assumptions!$A$7:$F$11,4,FALSE),8)/2-MAX(0,IF(R24="",0,R24)-IFERROR(VLOOKUP(O24,Assumptions!$A$7:$F$11,5,FALSE),1.5))),IFERROR(VLOOKUP(O24,Assumptions!$A$7:$F$11,5,FALSE),2.5)+IFERROR(VLOOKUP(O24,Assumptions!$A$7:$F$11,3,FALSE),3)+IFERROR(VLOOKUP(O24,Assumptions!$A$7:$F$11,4,FALSE),8)/2) | U24: =M24*S24/(1+Assumptions!$B$3)^T24 | V24: =IF(M24=0,"",ROUND(U24/M24*100,1)) | W24: =U24*Assumptions!$B$4 | X24: =IF(M24=0,"",ROUND(W24/M24*100,1)) | Y24: GRUPO DP4 | Z24: 0005010-98.2023.8.16.0001 | AA24: TJPR | AB24: marquesadmjudicial.com.br | AC24: GEOVANI VIEIRA MANZANO | AD24: Administrador | AE24: (35) 3729-7901 | AH24: SP | AI24: SAO PAULO | AJ24: Fabricação de laticínios | AK24: DEMAIS | AL24: ATIVA | AM24: https://marquesadmjudicial.com.br/sgc/download.php?file=files/processo_documento/processo_documento15293208032024_1_.pdf&nome=Relação Nominal de Credores da AJ-Sintética | AN24: p24 r6 | AO24: p24: R$ 9.093.937,71 | AP24: AJ_LIST | AQ24: 2023-03-02 | AR24: QUARANTINED | AS24: PARTIAL_DOC_CLASS_III_RECONCILED ROWS:p24r6 | AT24: b465a5d11eec
A25: 24 | B25: NEW | D25: 0 | I25: COPA ENERGIA S.A. | J25: COPA ENERGIA DISTRIBUIDORA DE GÁS S.A | K25: 03237583 | L25: 03237583000167 | M25: 9000000 | N25: 1 | O25: B | P25: ACTIVE | Q25: 46048 | R25: =IF(Q25="","",ROUND((TODAY()-Q25)/365.25,1)) | S25: =IFERROR(VLOOKUP(O25,Assumptions!$A$7:$F$11,2,FALSE),0.25) | T25: =IF(O25="A",MAX(1,IFERROR(VLOOKUP(O25,Assumptions!$A$7:$F$11,3,FALSE),3)+IFERROR(VLOOKUP(O25,Assumptions!$A$7:$F$11,4,FALSE),8)/2-MAX(0,IF(R25="",0,R25)-IFERROR(VLOOKUP(O25,Assumptions!$A$7:$F$11,5,FALSE),1.5))),IFERROR(VLOOKUP(O25,Assumptions!$A$7:$F$11,5,FALSE),2.5)+IFERROR(VLOOKUP(O25,Assumptions!$A$7:$F$11,3,FALSE),3)+IFERROR(VLOOKUP(O25,Assumptions!$A$7:$F$11,4,FALSE),8)/2) | U25: =M25*S25/(1+Assumptions!$B$3)^T25 | V25: =IF(M25=0,"",ROUND(U25/M25*100,1)) | W25: =U25*Assumptions!$B$4 | X25: =IF(M25=0,"",ROUND(W25/M25*100,1)) | Y25: GRUPO GLP | Z25: 0001639-09.2026.8.17.2810 | AA25: TJPE | AB25: recuperasolucoes.com | AC25: PEDRO JOAO ZAHRAN TURQUETO | AD25: Presidente | AE25: (11) 5505-4077 | AH25: SP | AI25: SAO PAULO | AJ25: Comércio atacadista de gás liqüefeito de petróleo (GLP) | AK25: DEMAIS | AL25: ATIVA | AM25: https://recuperasolucoes.com/wp-content/plugins/download-attachments/includes/download.php?id=1597 | AN25: p13 r12 | AO25: p13: R$ 9.000.000,00 | AP25: DEBTOR_LIST | AQ25: 2026-05-21 | AR25: OK | AS25: ROWS:p13r12 | AT25: 5da7b77bb569
A26: 25 | B26: NEW | D26: 0 | I26: MINERACAO AURORA LTDA | J26: MINERACAO AURORA LTDA | K26: 10509915 | L26: 10509915000180 | M26: 8433590 | N26: 1 | O26: C | P26: ACTIVE | Q26: 43838 | R26: =IF(Q26="","",ROUND((TODAY()-Q26)/365.25,1)) | S26: =IFERROR(VLOOKUP(O26,Assumptions!$A$7:$F$11,2,FALSE),0.25) | T26: =IF(O26="A",MAX(1,IFERROR(VLOOKUP(O26,Assumptions!$A$7:$F$11,3,FALSE),3)+IFERROR(VLOOKUP(O26,Assumptions!$A$7:$F$11,4,FALSE),8)/2-MAX(0,IF(R26="",0,R26)-IFERROR(VLOOKUP(O26,Assumptions!$A$7:$F$11,5,FALSE),1.5))),IFERROR(VLOOKUP(O26,Assumptions!$A$7:$F$11,5,FALSE),2.5)+IFERROR(VLOOKUP(O26,Assumptions!$A$7:$F$11,3,FALSE),3)+IFERROR(VLOOKUP(O26,Assumptions!$A$7:$F$11,4,FALSE),8)/2) | U26: =M26*S26/(1+Assumptions!$B$3)^T26 | V26: =IF(M26=0,"",ROUND(U26/M26*100,1)) | W26: =U26*Assumptions!$B$4 | X26: =IF(M26=0,"",ROUND(W26/M26*100,1)) | Y26: CONSTRUTORA ANDRADE GUEDES LTDA | Z26: 0000880-57.2020.8.17.2001 | AA26: TJPE | AB26: diligence.adm.br | AC26: SHIRLEY MONTEIRO REBOCHO SILVA | AD26: Sócio-Administrador | AE26: (81) 3972-4964 | AH26: PE | AI26: JABOATAO DOS GUARARAPES | AJ26: Extração e britamento de pedras e outros materiais para construção e beneficiamento associado | AK26: DEMAIS | AL26: ATIVA | AM26: https://diligence.adm.br/wp-content/plugins/download-attachments/includes/download.php?id=4599 | AN26: p10 r60 | AO26: p10: R$ 8.433.590,01 | AP26: AJ_LIST | AQ26: 2024-06-25 | AR26: OK_NO_TOTALS | AS26: ALT_VALUE:R$2.710.146,67 ALT_VALUE:R$5.723.443,34 ROWS:p10r60 UNRECONCILED_SOURCE VALUE_COL:2ª_Lista | AT26: 44ecd0afa707
A27: 26 | B27: NEW | D27: 0 | I27: FIRST S/A | J27: PENDENTE DE REGULARIZAÇÃO | K27: 00802235 | L27: 00802235000105 | M27: 8354815.1 | N27: 1 | O27: B | R27: =IF(Q27="","",ROUND((TODAY()-Q27)/365.25,1)) | S27: =IFERROR(VLOOKUP(O27,Assumptions!$A$7:$F$11,2,FALSE),0.25) | T27: =IF(O27="A",MAX(1,IFERROR(VLOOKUP(O27,Assumptions!$A$7:$F$11,3,FALSE),3)+IFERROR(VLOOKUP(O27,Assumptions!$A$7:$F$11,4,FALSE),8)/2-MAX(0,IF(R27="",0,R27)-IFERROR(VLOOKUP(O27,Assumptions!$A$7:$F$11,5,FALSE),1.5))),IFERROR(VLOOKUP(O27,Assumptions!$A$7:$F$11,5,FALSE),2.5)+IFERROR(VLOOKUP(O27,Assumptions!$A$7:$F$11,3,FALSE),3)+IFERROR(VLOOKUP(O27,Assumptions!$A$7:$F$11,4,FALSE),8)/2) | U27: =M27*S27/(1+Assumptions!$B$3)^T27 | V27: =IF(M27=0,"",ROUND(U27/M27*100,1)) | W27: =U27*Assumptions!$B$4 | X27: =IF(M27=0,"",ROUND(W27/M27*100,1)) | Y27: Grupo Rech | Z27: 5057720-48.2025.8.24.0023 | AB27: credibilita.com.br | AC27: NATANAEL SANTOS DE SOUZA | AD27: Presidente | AE27: (11) 5054-8110 | AH27: SP | AI27: SAO PAULO | AJ27: Comércio atacadista especializado em outros produtos intermediários não especificados anteriormente | AK27: DEMAIS | AL27: ATIVA | AM27: https://credibilita.com.br/wp-content/uploads/2025/09/Relacao-Credores-29.04.2026.pdf | AN27: p1 r23 | AO27: p1: R$ 8.354.815,13 | AP27: QUORUM_LIST | AR27: OK_NO_TOTALS | AS27: ROWS:p1r23 UNRECONCILED_SOURCE VALUE_COL:Valor_Após_Analise CASE_NUMBER_CORRECTED | AT27: cf92cff797d2
A28: 27 | B28: NEW | D28: 0 | I28: IPESA DO BRASIL COMERCIO DE PRODUTOS PLASTICOS LTDA | J28: NÃO | K28: 05607230 | L28: 05607230000480 | M28: 8353250 | N28: 1 | O28: B | R28: =IF(Q28="","",ROUND((TODAY()-Q28)/365.25,1)) | S28: =IFERROR(VLOOKUP(O28,Assumptions!$A$7:$F$11,2,FALSE),0.25) | T28: =IF(O28="A",MAX(1,IFERROR(VLOOKUP(O28,Assumptions!$A$7:$F$11,3,FALSE),3)+IFERROR(VLOOKUP(O28,Assumptions!$A$7:$F$11,4,FALSE),8)/2-MAX(0,IF(R28="",0,R28)-IFERROR(VLOOKUP(O28,Assumptions!$A$7:$F$11,5,FALSE),1.5))),IFERROR(VLOOKUP(O28,Assumptions!$A$7:$F$11,5,FALSE),2.5)+IFERROR(VLOOKUP(O28,Assumptions!$A$7:$F$11,3,FALSE),3)+IFERROR(VLOOKUP(O28,Assumptions!$A$7:$F$11,4,FALSE),8)/2) | U28: =M28*S28/(1+Assumptions!$B$3)^T28 | V28: =IF(M28=0,"",ROUND(U28/M28*100,1)) | W28: =U28*Assumptions!$B$4 | X28: =IF(M28=0,"",ROUND(W28/M28*100,1)) | Y28: Grupo Rech | Z28: 5057720-48.2025.8.24.0023 | AB28: credibilita.com.br | AC28: VIRGINIA KUMVICH | AD28: Administrador | AE28: (11) 5524-2877 | AH28: SP | AI28: SAO PAULO | AJ28: Comércio atacadista especializado em outros produtos intermediários não especificados anteriormente | AK28: DEMAIS | AL28: ATIVA | AM28: https://credibilita.com.br/wp-content/uploads/2025/09/Relacao-Credores-29.04.2026.pdf | AN28: p1 r27 | AO28: p1: R$ 8.353.250,00 | AP28: QUORUM_LIST | AR28: OK_NO_TOTALS | AS28: ROWS:p1r27 UNRECONCILED_SOURCE VALUE_COL:Valor_Após_Analise CASE_NUMBER_CORRECTED | AT28: cf92cff797d2
A29: 28 | B29: NEW | D29: 0 | I29: CLIMAZON INDUSTRIAL LTDA | J29: Avenida Torquato Tapajos, 7937, Lote 14, 14B, Taruma, Manaus/ AM - CEP 69041025 | K29: 04222931 | L29: 04222931000195 | M29: 8012248.6 | N29: 1 | O29: C | R29: =IF(Q29="","",ROUND((TODAY()-Q29)/365.25,1)) | S29: =IFERROR(VLOOKUP(O29,Assumptions!$A$7:$F$11,2,FALSE),0.25) | T29: =IF(O29="A",MAX(1,IFERROR(VLOOKUP(O29,Assumptions!$A$7:$F$11,3,FALSE),3)+IFERROR(VLOOKUP(O29,Assumptions!$A$7:$F$11,4,FALSE),8)/2-MAX(0,IF(R29="",0,R29)-IFERROR(VLOOKUP(O29,Assumptions!$A$7:$F$11,5,FALSE),1.5))),IFERROR(VLOOKUP(O29,Assumptions!$A$7:$F$11,5,FALSE),2.5)+IFERROR(VLOOKUP(O29,Assumptions!$A$7:$F$11,3,FALSE),3)+IFERROR(VLOOKUP(O29,Assumptions!$A$7:$F$11,4,FALSE),8)/2) | U29: =M29*S29/(1+Assumptions!$B$3)^T29 | V29: =IF(M29=0,"",ROUND(U29/M29*100,1)) | W29: =U29*Assumptions!$B$4 | X29: =IF(M29=0,"",ROUND(W29/M29*100,1)) | Y29: REAL DISTRIBUIDORA ÚNICA RIO COMÉRCIO DE REFRIGERAÇÃO LTDA. | Z29: 0873061-47.2023.8.19.0001 | AB29: inova-aj.com.br | AC29: ADRIANO ZACCARI FORTUNA | AD29: Administrador | AE29: (51) 3477-9873 | AF29: (51) 3477-9684 | AH29: AM | AI29: MANAUS | AJ29: Fabricação de aparelhos e equipamentos de ar condicionado para uso não-industrial | AK29: DEMAIS | AL29: ATIVA | AM29: https://inova-aj.com.br/wp-content/uploads/2026/08/1a-Relacao-de-Credores-Real.pdf | AN29: p1 r25 | AO29: p1: R$ 8.012.248,57 | AP29: AJ_LIST | AQ29: 2023-06-05 | AR29: OK | AS29: ALT_VALUE:R$5.825.770,44 ROWS:p1r25 | AT29: 8eb5d0d64353
A30: 29 | B30: NEW | D30: 0 | I30: COOPERATIVA DOS PLANTADORES DE CANA DO ESTADO SAO PAULO | J30: TITULARES DE CRÉDITOS QUIROGRAFÁRIOS SEQUENCIA EMPRESA CREDOR CNPJ / CPF ENDEREÇO BAIRRO CEP CIDADE UF ENDEREÇO ELETRONICO NATUREZA DOCUMENTO VALOR EM R$ 1 PRODUTOR RURAL (TAIKI MORIOKA) COOPERATIVA DOS PLANTADORES DE CANA DO ESTADO SÃO PAULO | K30: 54366547 | L30: 00000000000191, 02398976000190, 28138113004164, 54366547000134, 54366547003400, 60701190481609 | M30: 8000000 | N30: 1 | O30: B | P30: ACTIVE | Q30: 46184 | R30: =IF(Q30="","",ROUND((TODAY()-Q30)/365.25,1)) | S30: =IFERROR(VLOOKUP(O30,Assumptions!$A$7:$F$11,2,FALSE),0.25) | T30: =IF(O30="A",MAX(1,IFERROR(VLOOKUP(O30,Assumptions!$A$7:$F$11,3,FALSE),3)+IFERROR(VLOOKUP(O30,Assumptions!$A$7:$F$11,4,FALSE),8)/2-MAX(0,IF(R30="",0,R30)-IFERROR(VLOOKUP(O30,Assumptions!$A$7:$F$11,5,FALSE),1.5))),IFERROR(VLOOKUP(O30,Assumptions!$A$7:$F$11,5,FALSE),2.5)+IFERROR(VLOOKUP(O30,Assumptions!$A$7:$F$11,3,FALSE),3)+IFERROR(VLOOKUP(O30,Assumptions!$A$7:$F$11,4,FALSE),8)/2) | U30: =M30*S30/(1+Assumptions!$B$3)^T30 | V30: =IF(M30=0,"",ROUND(U30/M30*100,1)) | W30: =U30*Assumptions!$B$4 | X30: =IF(M30=0,"",ROUND(W30/M30*100,1)) | Y30: NAIR AKICO NAWAKAMI MORIOKA, TAIKI FELIPE MORIOKA e TIEZO FERNANDO MORIOKA (produtores rurais) | Z30: 4000807-49.2026.8.26.0354 | AA30: TJSP | AB30: vtladm.com.br | AC30: MARCOS FARHAT | AD30: Presidente | AE30: (19) 3401-2200 | AH30: SP | AI30: PIRACICABA | AJ30: Comércio atacadista de defensivos agrícolas, adubos, fertilizantes e corretivos do solo | AK30: DEMAIS | AL30: ATIVA | AM30: https://vtladm.com.br/wp-content/uploads/2026/06/02-–-Relacao-de-Credores-–-NAIR-AKICO-KAWAKAMI-MORIOKA-E-OUTROS.pdf | AN30: p4 r1 | AO30: p4: R$ 8.000.000,00 | AP30: UNKNOWN | AR30: OK_NO_TOTALS | AS30: LONG_CHUNK MULTI_ROOT ROWS:p4r1 UNRECONCILED_SOURCE | AT30: abf6f46571cf
A31: 30 | B31: NEW | D31: 0 | I31: LEGRAND PHARMA INDUSTRIA FARMACEUTICA LTDA | J31: Legrand Pharma Industria Farmaceutica Ltda | K31: 05044984 | L31: 05044984000126 | M31: 7715049.7 | N31: 1 | O31: C | P31: ACTIVE | Q31: 44987 | R31: =IF(Q31="","",ROUND((TODAY()-Q31)/365.25,1)) | S31: =IFERROR(VLOOKUP(O31,Assumptions!$A$7:$F$11,2,FALSE),0.25) | T31: =IF(O31="A",MAX(1,IFERROR(VLOOKUP(O31,Assumptions!$A$7:$F$11,3,FALSE),3)+IFERROR(VLOOKUP(O31,Assumptions!$A$7:$F$11,4,FALSE),8)/2-MAX(0,IF(R31="",0,R31)-IFERROR(VLOOKUP(O31,Assumptions!$A$7:$F$11,5,FALSE),1.5))),IFERROR(VLOOKUP(O31,Assumptions!$A$7:$F$11,5,FALSE),2.5)+IFERROR(VLOOKUP(O31,Assumptions!$A$7:$F$11,3,FALSE),3)+IFERROR(VLOOKUP(O31,Assumptions!$A$7:$F$11,4,FALSE),8)/2) | U31: =M31*S31/(1+Assumptions!$B$3)^T31 | V31: =IF(M31=0,"",ROUND(U31/M31*100,1)) | W31: =U31*Assumptions!$B$4 | X31: =IF(M31=0,"",ROUND(W31/M31*100,1)) | Y31: GRUPO DP4 | Z31: 0005010-98.2023.8.16.0001 | AA31: TJPR | AB31: marquesadmjudicial.com.br | AC31: GUSTAVO ANDRE REGIS DUTRA SVENSSON | AD31: Administrador | AE31: (19) 3887-9800 | AH31: SP | AI31: HORTOLANDIA | AJ31: Fabricação de medicamentos alopáticos para uso humano | AK31: DEMAIS | AL31: ATIVA | AM31: https://marquesadmjudicial.com.br/sgc/download.php?file=files/processo_documento/processo_documento15293208032024_1_.pdf&nome=Relação Nominal de Credores da AJ-Sintética | AN31: p28 r5 | AO31: p28: R$ 7.715.049,72 | AP31: AJ_LIST | AQ31: 2023-03-02 | AR31: QUARANTINED | AS31: PARTIAL_DOC_CLASS_III_RECONCILED ROWS:p28r5 | AT31: b465a5d11eec
A32: 31 | B32: NEW | D32: 0 | I32: BRASIL ASFALTOS LTDA | J32: BRASIL ASFALTOS LTDA | K32: 12447077 | L32: 12447077000193 | M32: 7707516.4 | N32: 1 | O32: C | P32: ACTIVE | Q32: 43838 | R32: =IF(Q32="","",ROUND((TODAY()-Q32)/365.25,1)) | S32: =IFERROR(VLOOKUP(O32,Assumptions!$A$7:$F$11,2,FALSE),0.25) | T32: =IF(O32="A",MAX(1,IFERROR(VLOOKUP(O32,Assumptions!$A$7:$F$11,3,FALSE),3)+IFERROR(VLOOKUP(O32,Assumptions!$A$7:$F$11,4,FALSE),8)/2-MAX(0,IF(R32="",0,R32)-IFERROR(VLOOKUP(O32,Assumptions!$A$7:$F$11,5,FALSE),1.5))),IFERROR(VLOOKUP(O32,Assumptions!$A$7:$F$11,5,FALSE),2.5)+IFERROR(VLOOKUP(O32,Assumptions!$A$7:$F$11,3,FALSE),3)+IFERROR(VLOOKUP(O32,Assumptions!$A$7:$F$11,4,FALSE),8)/2) | U32: =M32*S32/(1+Assumptions!$B$3)^T32 | V32: =IF(M32=0,"",ROUND(U32/M32*100,1)) | W32: =U32*Assumptions!$B$4 | X32: =IF(M32=0,"",ROUND(W32/M32*100,1)) | Y32: CONSTRUTORA ANDRADE GUEDES LTDA | Z32: 0000880-57.2020.8.17.2001 | AA32: TJPE | AB32: diligence.adm.br | AC32: ALBERTO GARRIDO PINON | AD32: Administrador | AE32: (71) 3118-2100 | AF32: (71) 3176-2828 | AH32: BA | AI32: CANDEIAS | AJ32: Fabricação de outros produtos de minerais não-metálicos não especificados anteriormente | AK32: DEMAIS | AL32: ATIVA | AM32: https://diligence.adm.br/wp-content/plugins/download-attachments/includes/download.php?id=4599 | AN32: p10 r9 | AO32: p10: R$ 7.707.516,40 | AP32: AJ_LIST | AQ32: 2024-06-25 | AR32: OK_NO_TOTALS | AS32: ALT_VALUE:R$613.244,70 ALT_VALUE:R$7.094.271,70 ROWS:p10r9 UNRECONCILED_SOURCE VALUE_COL:2ª_Lista | AT32: 44ecd0afa707
A33: 32 | B33: NEW | D33: 0 | I33: TITAN PNEUS DO BRASIL LTDA | J33: SIM | K33: 11385941 | L33: 11385941000107 | M33: 7525940 | N33: 1 | O33: B | R33: =IF(Q33="","",ROUND((TODAY()-Q33)/365.25,1)) | S33: =IFERROR(VLOOKUP(O33,Assumptions!$A$7:$F$11,2,FALSE),0.25) | T33: =IF(O33="A",MAX(1,IFERROR(VLOOKUP(O33,Assumptions!$A$7:$F$11,3,FALSE),3)+IFERROR(VLOOKUP(O33,Assumptions!$A$7:$F$11,4,FALSE),8)/2-MAX(0,IF(R33="",0,R33)-IFERROR(VLOOKUP(O33,Assumptions!$A$7:$F$11,5,FALSE),1.5))),IFERROR(VLOOKUP(O33,Assumptions!$A$7:$F$11,5,FALSE),2.5)+IFERROR(VLOOKUP(O33,Assumptions!$A$7:$F$11,3,FALSE),3)+IFERROR(VLOOKUP(O33,Assumptions!$A$7:$F$11,4,FALSE),8)/2) | U33: =M33*S33/(1+Assumptions!$B$3)^T33 | V33: =IF(M33=0,"",ROUND(U33/M33*100,1)) | W33: =U33*Assumptions!$B$4 | X33: =IF(M33=0,"",ROUND(W33/M33*100,1)) | Y33: Grupo Rech | Z33: 5057720-48.2025.8.24.0023 | AB33: credibilita.com.br | AC33: WALTER JOSE CHIOSINI | AD33: Administrador | AE33: (11) 2177-7360 | AF33: (11) 2177-7201 | AH33: SP | AI33: SAO PAULO | AJ33: Fabricação de pneumáticos e de câmaras-de-ar | AK33: DEMAIS | AL33: ATIVA | AM33: https://credibilita.com.br/wp-content/uploads/2025/09/Relacao-Credores-29.04.2026.pdf | AN33: p2 r23 | AO33: p2: R$ 7.525.940,00 | AP33: QUORUM_LIST | AR33: OK_NO_TOTALS | AS33: ROWS:p2r23 UNRECONCILED_SOURCE VALUE_COL:Valor_Após_Analise CASE_NUMBER_CORRECTED | AT33: cf92cff797d2
A34: 33 | B34: NEW | D34: 0 | I34: FEDERACAO PERNAMBUCANA DE FUTEBOL | J34: FEDERACAO PERNAMBUCANA DE FUTEBOL, CPF/CNPJ Nº | K34: 10956258 | L34: 10956258000110 | M34: 7251967.1 | N34: 1 | O34: C | P34: ACTIVE | Q34: 44966 | R34: =IF(Q34="","",ROUND((TODAY()-Q34)/365.25,1)) | S34: =IFERROR(VLOOKUP(O34,Assumptions!$A$7:$F$11,2,FALSE),0.25) | T34: =IF(O34="A",MAX(1,IFERROR(VLOOKUP(O34,Assumptions!$A$7:$F$11,3,FALSE),3)+IFERROR(VLOOKUP(O34,Assumptions!$A$7:$F$11,4,FALSE),8)/2-MAX(0,IF(R34="",0,R34)-IFERROR(VLOOKUP(O34,Assumptions!$A$7:$F$11,5,FALSE),1.5))),IFERROR(VLOOKUP(O34,Assumptions!$A$7:$F$11,5,FALSE),2.5)+IFERROR(VLOOKUP(O34,Assumptions!$A$7:$F$11,3,FALSE),3)+IFERROR(VLOOKUP(O34,Assumptions!$A$7:$F$11,4,FALSE),8)/2) | U34: =M34*S34/(1+Assumptions!$B$3)^T34 | V34: =IF(M34=0,"",ROUND(U34/M34*100,1)) | W34: =U34*Assumptions!$B$4 | X34: =IF(M34=0,"",ROUND(W34/M34*100,1)) | Y34: CLUBE NÁUTICO CAPIBARIBE | Z34: 0011283-80.2023.8.17.2001 | AA34: TJPE | AB34: lrflideres.com.br | AC34: EVANDRO BARROS DE CARVALHO | AD34: Presidente | AH34: PE | AI34: RECIFE | AJ34: Produção e promoção de eventos esportivos | AK34: DEMAIS | AL34: ATIVA | AM34: https://lrflideres.com.br/wp-content/plugins/download-attachments/includes/download.php?id=5589 | AN34: p12 r9 | AO34: p12: R$ 7.251.967,09 | AP34: AJ_LIST | AQ34: 2023-11-27 | AR34: QUARANTINED | AS34: PARTIAL_DOC_CLASS_III_RECONCILED ROWS:p12r9 | AT34: 677be5783c06
A35: 34 | B35: NEW | D35: 0 | I35: ADDIANTE S.A | J35: ADDIANTE S.A | K35: 48430290 | L35: 48430290000130 | M35: 7135517 | N35: 1 | O35: B | P35: ACTIVE | Q35: 45845 | R35: =IF(Q35="","",ROUND((TODAY()-Q35)/365.25,1)) | S35: =IFERROR(VLOOKUP(O35,Assumptions!$A$7:$F$11,2,FALSE),0.25) | T35: =IF(O35="A",MAX(1,IFERROR(VLOOKUP(O35,Assumptions!$A$7:$F$11,3,FALSE),3)+IFERROR(VLOOKUP(O35,Assumptions!$A$7:$F$11,4,FALSE),8)/2-MAX(0,IF(R35="",0,R35)-IFERROR(VLOOKUP(O35,Assumptions!$A$7:$F$11,5,FALSE),1.5))),IFERROR(VLOOKUP(O35,Assumptions!$A$7:$F$11,5,FALSE),2.5)+IFERROR(VLOOKUP(O35,Assumptions!$A$7:$F$11,3,FALSE),3)+IFERROR(VLOOKUP(O35,Assumptions!$A$7:$F$11,4,FALSE),8)/2) | U35: =M35*S35/(1+Assumptions!$B$3)^T35 | V35: =IF(M35=0,"",ROUND(U35/M35*100,1)) | W35: =U35*Assumptions!$B$4 | X35: =IF(M35=0,"",ROUND(W35/M35*100,1)) | Y35: SOJAL COMERCIAL AGRICOLA LTDA e OUTROS | Z35: 0804401-51.2025.8.14.0039 | AA35: TJPA | AB35: lrflideres.com.br | AC35: FABIO ROBERTO LEITE | AD35: Presidente | AE35: (41) 9571-0152 | AH35: PR | AI35: CURITIBA | AJ35: Locação de outros meios de transporte não especificados anteriormente, sem condutor | AK35: DEMAIS | AL35: ATIVA | AM35: https://lrflideres.com.br/wp-content/plugins/download-attachments/includes/download.php?id=6879 | AN35: p1 r2 | AO35: p1: R$ 7.135.516,97 | AP35: AJ_LIST | AQ35: 2026-01-15 | AR35: OK | AS35: ROWS:p1r2 | AT35: c56751547323
A36: 35 | B36: NEW | D36: 0 | I36: SOLUS DO BRASIL LTDA | J36: SOLUS INDUSTRIA QUIMICA LTDA | K36: 21203489 | L36: 21203489000764, 21203489000926 | M36: 7058181.5 | N36: 1 | O36: B | P36: ACTIVE | Q36: 45845 | R36: =IF(Q36="","",ROUND((TODAY()-Q36)/365.25,1)) | S36: =IFERROR(VLOOKUP(O36,Assumptions!$A$7:$F$11,2,FALSE),0.25) | T36: =IF(O36="A",MAX(1,IFERROR(VLOOKUP(O36,Assumptions!$A$7:$F$11,3,FALSE),3)+IFERROR(VLOOKUP(O36,Assumptions!$A$7:$F$11,4,FALSE),8)/2-MAX(0,IF(R36="",0,R36)-IFERROR(VLOOKUP(O36,Assumptions!$A$7:$F$11,5,FALSE),1.5))),IFERROR(VLOOKUP(O36,Assumptions!$A$7:$F$11,5,FALSE),2.5)+IFERROR(VLOOKUP(O36,Assumptions!$A$7:$F$11,3,FALSE),3)+IFERROR(VLOOKUP(O36,Assumptions!$A$7:$F$11,4,FALSE),8)/2) | U36: =M36*S36/(1+Assumptions!$B$3)^T36 | V36: =IF(M36=0,"",ROUND(U36/M36*100,1)) | W36: =U36*Assumptions!$B$4 | X36: =IF(M36=0,"",ROUND(W36/M36*100,1)) | Y36: SOJAL COMERCIAL AGRICOLA LTDA e OUTROS | Z36: 0804401-51.2025.8.14.0039 | AA36: TJPA | AB36: lrflideres.com.br | AC36: ANDERSON JOSE FAUSTINO | AD36: Administrador | AE36: (43) 3162-2715 | AH36: PR | AI36: APUCARANA | AJ36: Fabricação de defensivos agrícolas | AK36: DEMAIS | AL36: ATIVA | AM36: https://lrflideres.com.br/wp-content/plugins/download-attachments/includes/download.php?id=6879 | AN36: p2 r10 | AO36: p2: R$ 7.058.181,50 | AP36: AJ_LIST | AQ36: 2026-01-15 | AR36: OK | AS36: ROWS:p2r10 | AT36: c56751547323
A37: 36 | B37: NEW | D37: 0 | I37: COMERCIO RACOES BEM BOM LTDA | J37: Fabrica De Ração | K37: 41324359 | L37: 41324359000100 | M37: 6642119 | N37: 1 | O37: B | P37: ACTIVE | Q37: 46130 | R37: =IF(Q37="","",ROUND((TODAY()-Q37)/365.25,1)) | S37: =IFERROR(VLOOKUP(O37,Assumptions!$A$7:$F$11,2,FALSE),0.25) | T37: =IF(O37="A",MAX(1,IFERROR(VLOOKUP(O37,Assumptions!$A$7:$F$11,3,FALSE),3)+IFERROR(VLOOKUP(O37,Assumptions!$A$7:$F$11,4,FALSE),8)/2-MAX(0,IF(R37="",0,R37)-IFERROR(VLOOKUP(O37,Assumptions!$A$7:$F$11,5,FALSE),1.5))),IFERROR(VLOOKUP(O37,Assumptions!$A$7:$F$11,5,FALSE),2.5)+IFERROR(VLOOKUP(O37,Assumptions!$A$7:$F$11,3,FALSE),3)+IFERROR(VLOOKUP(O37,Assumptions!$A$7:$F$11,4,FALSE),8)/2) | U37: =M37*S37/(1+Assumptions!$B$3)^T37 | V37: =IF(M37=0,"",ROUND(U37/M37*100,1)) | W37: =U37*Assumptions!$B$4 | X37: =IF(M37=0,"",ROUND(W37/M37*100,1)) | Y37: GRUPO 3E | Z37: 5341375-33.2026.8.09.0049 | AA37: TJGO | AB37: stenius.com.br | AC37: EDSON VIANDELLI LOPES | AD37: Sócio-Administrador | AE37: (62) 3389-9200 | AF37: (62) 8115-0283 | AH37: GO | AI37: GOIANESIA | AJ37: Fabricação de alimentos para animais | AK37: DEMAIS | AL37: ATIVA | AM37: https://stenius.com.br/wp-content/uploads/2026/06/EDITAL-GRUPO-3E.pdf | AN37: p13 r19 | AO37: p13: R$ 6.642.118,99 | AP37: DEBTOR_LIST | AQ37: 2026-06-22 | AR37: OK_NO_TOTALS | AS37: ROWS:p13r19 UNRECONCILED_SOURCE | AT37: 8e8832093a15
