Workbook

Sheet DASHBOARD
A1: ANTEPARO — CALL DASHBOARD
A2: Live off the CALL SHEET tab · sorted by fund price (∝ our ágio) · 2026-09-04
A4: PIPELINE | E4: TOP 15 BY OUR ÁGIO | F4: Debtor | G4: Ágio (R$) | H4: Band | I4: Status | J4: Next date
A5: Leads on sheet | B5: =COUNTA('CALL SHEET'!$A$2:$A$560) | E5: =IFERROR(INDEX('CALL SHEET'!$A$2:$A$560,MATCH(G5,'CALL SHEET'!$AB$2:$AB$560,0)),"") | F5: =IFERROR(INDEX('CALL SHEET'!$C$2:$C$560,MATCH(G5,'CALL SHEET'!$AB$2:$AB$560,0)),"") | G5: =IFERROR(LARGE('CALL SHEET'!$AB$2:$AB$560,1),"") | H5: =IFERROR(INDEX('CALL SHEET'!$U$2:$U$560,MATCH(G5,'CALL SHEET'!$AB$2:$AB$560,0)),"") | I5: =IFERROR(INDEX('CALL SHEET'!$D$2:$D$560,MATCH(G5,'CALL SHEET'!$AB$2:$AB$560,0)),"") | J5: =IFERROR(INDEX('CALL SHEET'!$G$2:$G$560,MATCH(G5,'CALL SHEET'!$AB$2:$AB$560,0)),"")
A6: Total face (R$) | B6: =SUM('CALL SHEET'!$T$2:$T$560) | E6: =IFERROR(INDEX('CALL SHEET'!$A$2:$A$560,MATCH(G6,'CALL SHEET'!$AB$2:$AB$560,0)),"") | F6: =IFERROR(INDEX('CALL SHEET'!$C$2:$C$560,MATCH(G6,'CALL SHEET'!$AB$2:$AB$560,0)),"") | G6: =IFERROR(LARGE('CALL SHEET'!$AB$2:$AB$560,2),"") | H6: =IFERROR(INDEX('CALL SHEET'!$U$2:$U$560,MATCH(G6,'CALL SHEET'!$AB$2:$AB$560,0)),"") | I6: =IFERROR(INDEX('CALL SHEET'!$D$2:$D$560,MATCH(G6,'CALL SHEET'!$AB$2:$AB$560,0)),"") | J6: =IFERROR(INDEX('CALL SHEET'!$G$2:$G$560,MATCH(G6,'CALL SHEET'!$AB$2:$AB$560,0)),"")
A7: Fund price pipeline (R$) | B7: =SUM('CALL SHEET'!$X$2:$X$560) | E7: =IFERROR(INDEX('CALL SHEET'!$A$2:$A$560,MATCH(G7,'CALL SHEET'!$AB$2:$AB$560,0)),"") | F7: =IFERROR(INDEX('CALL SHEET'!$C$2:$C$560,MATCH(G7,'CALL SHEET'!$AB$2:$AB$560,0)),"") | G7: =IFERROR(LARGE('CALL SHEET'!$AB$2:$AB$560,3),"") | H7: =IFERROR(INDEX('CALL SHEET'!$U$2:$U$560,MATCH(G7,'CALL SHEET'!$AB$2:$AB$560,0)),"") | I7: =IFERROR(INDEX('CALL SHEET'!$D$2:$D$560,MATCH(G7,'CALL SHEET'!$AB$2:$AB$560,0)),"") | J7: =IFERROR(INDEX('CALL SHEET'!$G$2:$G$560,MATCH(G7,'CALL SHEET'!$AB$2:$AB$560,0)),"")
A8: OUR ÁGIO pipeline (R$) | B8: =SUM('CALL SHEET'!$AB$2:$AB$560) | E8: =IFERROR(INDEX('CALL SHEET'!$A$2:$A$560,MATCH(G8,'CALL SHEET'!$AB$2:$AB$560,0)),"") | F8: =IFERROR(INDEX('CALL SHEET'!$C$2:$C$560,MATCH(G8,'CALL SHEET'!$AB$2:$AB$560,0)),"") | G8: =IFERROR(LARGE('CALL SHEET'!$AB$2:$AB$560,4),"") | H8: =IFERROR(INDEX('CALL SHEET'!$U$2:$U$560,MATCH(G8,'CALL SHEET'!$AB$2:$AB$560,0)),"") | I8: =IFERROR(INDEX('CALL SHEET'!$D$2:$D$560,MATCH(G8,'CALL SHEET'!$AB$2:$AB$560,0)),"") | J8: =IFERROR(INDEX('CALL SHEET'!$G$2:$G$560,MATCH(G8,'CALL SHEET'!$AB$2:$AB$560,0)),"")
A9: Untouched (NEW) | B9: =COUNTIF('CALL SHEET'!$D$2:$D$560,"NEW") | E9: =IFERROR(INDEX('CALL SHEET'!$A$2:$A$560,MATCH(G9,'CALL SHEET'!$AB$2:$AB$560,0)),"") | F9: =IFERROR(INDEX('CALL SHEET'!$C$2:$C$560,MATCH(G9,'CALL SHEET'!$AB$2:$AB$560,0)),"") | G9: =IFERROR(LARGE('CALL SHEET'!$AB$2:$AB$560,5),"") | H9: =IFERROR(INDEX('CALL SHEET'!$U$2:$U$560,MATCH(G9,'CALL SHEET'!$AB$2:$AB$560,0)),"") | I9: =IFERROR(INDEX('CALL SHEET'!$D$2:$D$560,MATCH(G9,'CALL SHEET'!$AB$2:$AB$560,0)),"") | J9: =IFERROR(INDEX('CALL SHEET'!$G$2:$G$560,MATCH(G9,'CALL SHEET'!$AB$2:$AB$560,0)),"")
A10: Calls due today | B10: =COUNTIF('CALL SHEET'!$G$2:$G$560,TODAY()) | E10: =IFERROR(INDEX('CALL SHEET'!$A$2:$A$560,MATCH(G10,'CALL SHEET'!$AB$2:$AB$560,0)),"") | F10: =IFERROR(INDEX('CALL SHEET'!$C$2:$C$560,MATCH(G10,'CALL SHEET'!$AB$2:$AB$560,0)),"") | G10: =IFERROR(LARGE('CALL SHEET'!$AB$2:$AB$560,6),"") | H10: =IFERROR(INDEX('CALL SHEET'!$U$2:$U$560,MATCH(G10,'CALL SHEET'!$AB$2:$AB$560,0)),"") | I10: =IFERROR(INDEX('CALL SHEET'!$D$2:$D$560,MATCH(G10,'CALL SHEET'!$AB$2:$AB$560,0)),"") | J10: =IFERROR(INDEX('CALL SHEET'!$G$2:$G$560,MATCH(G10,'CALL SHEET'!$AB$2:$AB$560,0)),"")
A11: Overdue follow-ups | B11: =COUNTIFS('CALL SHEET'!$G$2:$G$560,"<"&TODAY(),'CALL SHEET'!$G$2:$G$560,"<>",'CALL SHEET'!$D$2:$D$560,"<>DEAD",'CALL SHEET'!$D$2:$D$560,"<>DEAL") | E11: =IFERROR(INDEX('CALL SHEET'!$A$2:$A$560,MATCH(G11,'CALL SHEET'!$AB$2:$AB$560,0)),"") | F11: =IFERROR(INDEX('CALL SHEET'!$C$2:$C$560,MATCH(G11,'CALL SHEET'!$AB$2:$AB$560,0)),"") | G11: =IFERROR(LARGE('CALL SHEET'!$AB$2:$AB$560,7),"") | H11: =IFERROR(INDEX('CALL SHEET'!$U$2:$U$560,MATCH(G11,'CALL SHEET'!$AB$2:$AB$560,0)),"") | I11: =IFERROR(INDEX('CALL SHEET'!$D$2:$D$560,MATCH(G11,'CALL SHEET'!$AB$2:$AB$560,0)),"") | J11: =IFERROR(INDEX('CALL SHEET'!$G$2:$G$560,MATCH(G11,'CALL SHEET'!$AB$2:$AB$560,0)),"")
A12: Interested + Deal — ágio (R$) | B12: =SUMIF('CALL SHEET'!$D$2:$D$560,"INTERESTED",'CALL SHEET'!$AB$2:$AB$560)+SUMIF('CALL SHEET'!$D$2:$D$560,"DEAL",'CALL SHEET'!$AB$2:$AB$560) | E12: =IFERROR(INDEX('CALL SHEET'!$A$2:$A$560,MATCH(G12,'CALL SHEET'!$AB$2:$AB$560,0)),"") | F12: =IFERROR(INDEX('CALL SHEET'!$C$2:$C$560,MATCH(G12,'CALL SHEET'!$AB$2:$AB$560,0)),"") | G12: =IFERROR(LARGE('CALL SHEET'!$AB$2:$AB$560,8),"") | H12: =IFERROR(INDEX('CALL SHEET'!$U$2:$U$560,MATCH(G12,'CALL SHEET'!$AB$2:$AB$560,0)),"") | I12: =IFERROR(INDEX('CALL SHEET'!$D$2:$D$560,MATCH(G12,'CALL SHEET'!$AB$2:$AB$560,0)),"") | J12: =IFERROR(INDEX('CALL SHEET'!$G$2:$G$560,MATCH(G12,'CALL SHEET'!$AB$2:$AB$560,0)),"")
E13: =IFERROR(INDEX('CALL SHEET'!$A$2:$A$560,MATCH(G13,'CALL SHEET'!$AB$2:$AB$560,0)),"") | F13: =IFERROR(INDEX('CALL SHEET'!$C$2:$C$560,MATCH(G13,'CALL SHEET'!$AB$2:$AB$560,0)),"") | G13: =IFERROR(LARGE('CALL SHEET'!$AB$2:$AB$560,9),"") | H13: =IFERROR(INDEX('CALL SHEET'!$U$2:$U$560,MATCH(G13,'CALL SHEET'!$AB$2:$AB$560,0)),"") | I13: =IFERROR(INDEX('CALL SHEET'!$D$2:$D$560,MATCH(G13,'CALL SHEET'!$AB$2:$AB$560,0)),"") | J13: =IFERROR(INDEX('CALL SHEET'!$G$2:$G$560,MATCH(G13,'CALL SHEET'!$AB$2:$AB$560,0)),"")
A14: FUNNEL | B14: leads | C14: ágio (R$) | E14: =IFERROR(INDEX('CALL SHEET'!$A$2:$A$560,MATCH(G14,'CALL SHEET'!$AB$2:$AB$560,0)),"") | F14: =IFERROR(INDEX('CALL SHEET'!$C$2:$C$560,MATCH(G14,'CALL SHEET'!$AB$2:$AB$560,0)),"") | G14: =IFERROR(LARGE('CALL SHEET'!$AB$2:$AB$560,10),"") | H14: =IFERROR(INDEX('CALL SHEET'!$U$2:$U$560,MATCH(G14,'CALL SHEET'!$AB$2:$AB$560,0)),"") | I14: =IFERROR(INDEX('CALL SHEET'!$D$2:$D$560,MATCH(G14,'CALL SHEET'!$AB$2:$AB$560,0)),"") | J14: =IFERROR(INDEX('CALL SHEET'!$G$2:$G$560,MATCH(G14,'CALL SHEET'!$AB$2:$AB$560,0)),"")
A15: NEW | B15: =COUNTIF('CALL SHEET'!$D$2:$D$560,"NEW") | C15: =SUMIF('CALL SHEET'!$D$2:$D$560,"NEW",'CALL SHEET'!$AB$2:$AB$560) | E15: =IFERROR(INDEX('CALL SHEET'!$A$2:$A$560,MATCH(G15,'CALL SHEET'!$AB$2:$AB$560,0)),"") | F15: =IFERROR(INDEX('CALL SHEET'!$C$2:$C$560,MATCH(G15,'CALL SHEET'!$AB$2:$AB$560,0)),"") | G15: =IFERROR(LARGE('CALL SHEET'!$AB$2:$AB$560,11),"") | H15: =IFERROR(INDEX('CALL SHEET'!$U$2:$U$560,MATCH(G15,'CALL SHEET'!$AB$2:$AB$560,0)),"") | I15: =IFERROR(INDEX('CALL SHEET'!$D$2:$D$560,MATCH(G15,'CALL SHEET'!$AB$2:$AB$560,0)),"") | J15: =IFERROR(INDEX('CALL SHEET'!$G$2:$G$560,MATCH(G15,'CALL SHEET'!$AB$2:$AB$560,0)),"")
A16: QUEUED | B16: =COUNTIF('CALL SHEET'!$D$2:$D$560,"QUEUED") | C16: =SUMIF('CALL SHEET'!$D$2:$D$560,"QUEUED",'CALL SHEET'!$AB$2:$AB$560) | E16: =IFERROR(INDEX('CALL SHEET'!$A$2:$A$560,MATCH(G16,'CALL SHEET'!$AB$2:$AB$560,0)),"") | F16: =IFERROR(INDEX('CALL SHEET'!$C$2:$C$560,MATCH(G16,'CALL SHEET'!$AB$2:$AB$560,0)),"") | G16: =IFERROR(LARGE('CALL SHEET'!$AB$2:$AB$560,12),"") | H16: =IFERROR(INDEX('CALL SHEET'!$U$2:$U$560,MATCH(G16,'CALL SHEET'!$AB$2:$AB$560,0)),"") | I16: =IFERROR(INDEX('CALL SHEET'!$D$2:$D$560,MATCH(G16,'CALL SHEET'!$AB$2:$AB$560,0)),"") | J16: =IFERROR(INDEX('CALL SHEET'!$G$2:$G$560,MATCH(G16,'CALL SHEET'!$AB$2:$AB$560,0)),"")
A17: EMAILED | B17: =COUNTIF('CALL SHEET'!$D$2:$D$560,"EMAILED") | C17: =SUMIF('CALL SHEET'!$D$2:$D$560,"EMAILED",'CALL SHEET'!$AB$2:$AB$560) | E17: =IFERROR(INDEX('CALL SHEET'!$A$2:$A$560,MATCH(G17,'CALL SHEET'!$AB$2:$AB$560,0)),"") | F17: =IFERROR(INDEX('CALL SHEET'!$C$2:$C$560,MATCH(G17,'CALL SHEET'!$AB$2:$AB$560,0)),"") | G17: =IFERROR(LARGE('CALL SHEET'!$AB$2:$AB$560,13),"") | H17: =IFERROR(INDEX('CALL SHEET'!$U$2:$U$560,MATCH(G17,'CALL SHEET'!$AB$2:$AB$560,0)),"") | I17: =IFERROR(INDEX('CALL SHEET'!$D$2:$D$560,MATCH(G17,'CALL SHEET'!$AB$2:$AB$560,0)),"") | J17: =IFERROR(INDEX('CALL SHEET'!$G$2:$G$560,MATCH(G17,'CALL SHEET'!$AB$2:$AB$560,0)),"")
A18: CALLED | B18: =COUNTIF('CALL SHEET'!$D$2:$D$560,"CALLED") | C18: =SUMIF('CALL SHEET'!$D$2:$D$560,"CALLED",'CALL SHEET'!$AB$2:$AB$560) | E18: =IFERROR(INDEX('CALL SHEET'!$A$2:$A$560,MATCH(G18,'CALL SHEET'!$AB$2:$AB$560,0)),"") | F18: =IFERROR(INDEX('CALL SHEET'!$C$2:$C$560,MATCH(G18,'CALL SHEET'!$AB$2:$AB$560,0)),"") | G18: =IFERROR(LARGE('CALL SHEET'!$AB$2:$AB$560,14),"") | H18: =IFERROR(INDEX('CALL SHEET'!$U$2:$U$560,MATCH(G18,'CALL SHEET'!$AB$2:$AB$560,0)),"") | I18: =IFERROR(INDEX('CALL SHEET'!$D$2:$D$560,MATCH(G18,'CALL SHEET'!$AB$2:$AB$560,0)),"") | J18: =IFERROR(INDEX('CALL SHEET'!$G$2:$G$560,MATCH(G18,'CALL SHEET'!$AB$2:$AB$560,0)),"")
A19: VOICEMAIL | B19: =COUNTIF('CALL SHEET'!$D$2:$D$560,"VOICEMAIL") | C19: =SUMIF('CALL SHEET'!$D$2:$D$560,"VOICEMAIL",'CALL SHEET'!$AB$2:$AB$560) | E19: =IFERROR(INDEX('CALL SHEET'!$A$2:$A$560,MATCH(G19,'CALL SHEET'!$AB$2:$AB$560,0)),"") | F19: =IFERROR(INDEX('CALL SHEET'!$C$2:$C$560,MATCH(G19,'CALL SHEET'!$AB$2:$AB$560,0)),"") | G19: =IFERROR(LARGE('CALL SHEET'!$AB$2:$AB$560,15),"") | H19: =IFERROR(INDEX('CALL SHEET'!$U$2:$U$560,MATCH(G19,'CALL SHEET'!$AB$2:$AB$560,0)),"") | I19: =IFERROR(INDEX('CALL SHEET'!$D$2:$D$560,MATCH(G19,'CALL SHEET'!$AB$2:$AB$560,0)),"") | J19: =IFERROR(INDEX('CALL SHEET'!$G$2:$G$560,MATCH(G19,'CALL SHEET'!$AB$2:$AB$560,0)),"")
A20: CONNECTED | B20: =COUNTIF('CALL SHEET'!$D$2:$D$560,"CONNECTED") | C20: =SUMIF('CALL SHEET'!$D$2:$D$560,"CONNECTED",'CALL SHEET'!$AB$2:$AB$560)
A21: INTERESTED | B21: =COUNTIF('CALL SHEET'!$D$2:$D$560,"INTERESTED") | C21: =SUMIF('CALL SHEET'!$D$2:$D$560,"INTERESTED",'CALL SHEET'!$AB$2:$AB$560) | E21: CASE OWNERSHIP — deepest debtors | F21: leads | G21: ágio (R$) | H21: called | I21: interested
A22: NOT INTERESTED | B22: =COUNTIF('CALL SHEET'!$D$2:$D$560,"NOT INTERESTED") | C22: =SUMIF('CALL SHEET'!$D$2:$D$560,"NOT INTERESTED",'CALL SHEET'!$AB$2:$AB$560) | E22: EGESA ENGENHARIA S/A (Consórcio ETDI) | F22: =COUNTIF('CALL SHEET'!$C$2:$C$560,"EGESA ENGENHARIA S/A (Consórcio ETDI)") | G22: =SUMIF('CALL SHEET'!$C$2:$C$560,"EGESA ENGENHARIA S/A (Consórcio ETDI)",'CALL SHEET'!$AB$2:$AB$560) | H22: =COUNTIFS('CALL SHEET'!$C$2:$C$560,"EGESA ENGENHARIA S/A (Consórcio ETDI)",'CALL SHEET'!$D$2:$D$560,"<>NEW") | I22: =COUNTIFS('CALL SHEET'!$C$2:$C$560,"EGESA ENGENHARIA S/A (Consórcio ETDI)",'CALL SHEET'!$D$2:$D$560,"INTERESTED")+COUNTIFS('CALL SHEET'!$C$2:$C$560,"EGESA ENGENHARIA S/A (Consórcio ETDI)",'CALL SHEET'!$D$2:$D$560,"DEAL")
A23: CALL BACK | B23: =COUNTIF('CALL SHEET'!$D$2:$D$560,"CALL BACK") | C23: =SUMIF('CALL SHEET'!$D$2:$D$560,"CALL BACK",'CALL SHEET'!$AB$2:$AB$560) | E23: COMERCIO RACOES BEM BOM LTDA | F23: =COUNTIF('CALL SHEET'!$C$2:$C$560,"COMERCIO RACOES BEM BOM LTDA") | G23: =SUMIF('CALL SHEET'!$C$2:$C$560,"COMERCIO RACOES BEM BOM LTDA",'CALL SHEET'!$AB$2:$AB$560) | H23: =COUNTIFS('CALL SHEET'!$C$2:$C$560,"COMERCIO RACOES BEM BOM LTDA",'CALL SHEET'!$D$2:$D$560,"<>NEW") | I23: =COUNTIFS('CALL SHEET'!$C$2:$C$560,"COMERCIO RACOES BEM BOM LTDA",'CALL SHEET'!$D$2:$D$560,"INTERESTED")+COUNTIFS('CALL SHEET'!$C$2:$C$560,"COMERCIO RACOES BEM BOM LTDA",'CALL SHEET'!$D$2:$D$560,"DEAL")
A24: DEAD | B24: =COUNTIF('CALL SHEET'!$D$2:$D$560,"DEAD") | C24: =SUMIF('CALL SHEET'!$D$2:$D$560,"DEAD",'CALL SHEET'!$AB$2:$AB$560) | E24: aludida empresa | F24: =COUNTIF('CALL SHEET'!$C$2:$C$560,"aludida empresa") | G24: =SUMIF('CALL SHEET'!$C$2:$C$560,"aludida empresa",'CALL SHEET'!$AB$2:$AB$560) | H24: =COUNTIFS('CALL SHEET'!$C$2:$C$560,"aludida empresa",'CALL SHEET'!$D$2:$D$560,"<>NEW") | I24: =COUNTIFS('CALL SHEET'!$C$2:$C$560,"aludida empresa",'CALL SHEET'!$D$2:$D$560,"INTERESTED")+COUNTIFS('CALL SHEET'!$C$2:$C$560,"aludida empresa",'CALL SHEET'!$D$2:$D$560,"DEAL")
A25: DEAL | B25: =COUNTIF('CALL SHEET'!$D$2:$D$560,"DEAL") | C25: =SUMIF('CALL SHEET'!$D$2:$D$560,"DEAL",'CALL SHEET'!$AB$2:$AB$560) | E25: R W CONSTRUCOES LTDA | F25: =COUNTIF('CALL SHEET'!$C$2:$C$560,"R W CONSTRUCOES LTDA") | G25: =SUMIF('CALL SHEET'!$C$2:$C$560,"R W CONSTRUCOES LTDA",'CALL SHEET'!$AB$2:$AB$560) | H25: =COUNTIFS('CALL SHEET'!$C$2:$C$560,"R W CONSTRUCOES LTDA",'CALL SHEET'!$D$2:$D$560,"<>NEW") | I25: =COUNTIFS('CALL SHEET'!$C$2:$C$560,"R W CONSTRUCOES LTDA",'CALL SHEET'!$D$2:$D$560,"INTERESTED")+COUNTIFS('CALL SHEET'!$C$2:$C$560,"R W CONSTRUCOES LTDA",'CALL SHEET'!$D$2:$D$560,"DEAL")
E26: VEV COMERCIO DE MEDICAMENTOS LTDA EM RECUPERACAO JUDICIAL | F26: =COUNTIF('CALL SHEET'!$C$2:$C$560,"VEV COMERCIO DE MEDICAMENTOS LTDA EM RECUPERACAO JUDICIAL") | G26: =SUMIF('CALL SHEET'!$C$2:$C$560,"VEV COMERCIO DE MEDICAMENTOS LTDA EM RECUPERACAO JUDICIAL",'CALL SHEET'!$AB$2:$AB$560) | H26: =COUNTIFS('CALL SHEET'!$C$2:$C$560,"VEV COMERCIO DE MEDICAMENTOS LTDA EM RECUPERACAO JUDICIAL",'CALL SHEET'!$D$2:$D$560,"<>NEW") | I26: =COUNTIFS('CALL SHEET'!$C$2:$C$560,"VEV COMERCIO DE MEDICAMENTOS LTDA EM RECUPERACAO JUDICIAL",'CALL SHEET'!$D$2:$D$560,"INTERESTED")+COUNTIFS('CALL SHEET'!$C$2:$C$560,"VEV COMERCIO DE MEDICAMENTOS LTDA EM RECUPERACAO JUDICIAL",'CALL SHEET'!$D$2:$D$560,"DEAL")
A27: DEBTOR BAND | B27: leads | C27: ágio (R$) | E27: ASSOCIACAO DE CARIDADE SANTA CASA DE RIO GRANDE | F27: =COUNTIF('CALL SHEET'!$C$2:$C$560,"ASSOCIACAO DE CARIDADE SANTA CASA DE RIO GRANDE") | G27: =SUMIF('CALL SHEET'!$C$2:$C$560,"ASSOCIACAO DE CARIDADE SANTA CASA DE RIO GRANDE",'CALL SHEET'!$AB$2:$AB$560) | H27: =COUNTIFS('CALL SHEET'!$C$2:$C$560,"ASSOCIACAO DE CARIDADE SANTA CASA DE RIO GRANDE",'CALL SHEET'!$D$2:$D$560,"<>NEW") | I27: =COUNTIFS('CALL SHEET'!$C$2:$C$560,"ASSOCIACAO DE CARIDADE SANTA CASA DE RIO GRANDE",'CALL SHEET'!$D$2:$D$560,"INTERESTED")+COUNTIFS('CALL SHEET'!$C$2:$C$560,"ASSOCIACAO DE CARIDADE SANTA CASA DE RIO GRANDE",'CALL SHEET'!$D$2:$D$560,"DEAL")
A28: A — Plan approved / homologation | B28: =COUNTIF('CALL SHEET'!$U$2:$U$560,"A") | C28: =SUMIF('CALL SHEET'!$U$2:$U$560,"A",'CALL SHEET'!$AB$2:$AB$560) | E28: ADVOCACIA WANDERLEI DE PAULA BARRETO | F28: =COUNTIF('CALL SHEET'!$C$2:$C$560,"ADVOCACIA WANDERLEI DE PAULA BARRETO") | G28: =SUMIF('CALL SHEET'!$C$2:$C$560,"ADVOCACIA WANDERLEI DE PAULA BARRETO",'CALL SHEET'!$AB$2:$AB$560) | H28: =COUNTIFS('CALL SHEET'!$C$2:$C$560,"ADVOCACIA WANDERLEI DE PAULA BARRETO",'CALL SHEET'!$D$2:$D$560,"<>NEW") | I28: =COUNTIFS('CALL SHEET'!$C$2:$C$560,"ADVOCACIA WANDERLEI DE PAULA BARRETO",'CALL SHEET'!$D$2:$D$560,"INTERESTED")+COUNTIFS('CALL SHEET'!$C$2:$C$560,"ADVOCACIA WANDERLEI DE PAULA BARRETO",'CALL SHEET'!$D$2:$D$560,"DEAL")
A29: B — Live case, no plan document | B29: =COUNTIF('CALL SHEET'!$U$2:$U$560,"B") | C29: =SUMIF('CALL SHEET'!$U$2:$U$560,"B",'CALL SHEET'!$AB$2:$AB$560) | E29: NORTESUL COMERCIAL AGRICOLA LTDA EM RECUPERACAO JUDICIAL | F29: =COUNTIF('CALL SHEET'!$C$2:$C$560,"NORTESUL COMERCIAL AGRICOLA LTDA EM RECUPERACAO JUDICIAL") | G29: =SUMIF('CALL SHEET'!$C$2:$C$560,"NORTESUL COMERCIAL AGRICOLA LTDA EM RECUPERACAO JUDICIAL",'CALL SHEET'!$AB$2:$AB$560) | H29: =COUNTIFS('CALL SHEET'!$C$2:$C$560,"NORTESUL COMERCIAL AGRICOLA LTDA EM RECUPERACAO JUDICIAL",'CALL SHEET'!$D$2:$D$560,"<>NEW") | I29: =COUNTIFS('CALL SHEET'!$C$2:$C$560,"NORTESUL COMERCIAL AGRICOLA LTDA EM RECUPERACAO JUDICIAL",'CALL SHEET'!$D$2:$D$560,"INTERESTED")+COUNTIFS('CALL SHEET'!$C$2:$C$560,"NORTESUL COMERCIAL AGRICOLA LTDA EM RECUPERACAO JUDICIAL",'CALL SHEET'!$D$2:$D$560,"DEAL")
A30: C — Stale: >4 years since filing | B30: =COUNTIF('CALL SHEET'!$U$2:$U$560,"C") | C30: =SUMIF('CALL SHEET'!$U$2:$U$560,"C",'CALL SHEET'!$AB$2:$AB$560) | E30: CLUBE NAUTICO CAPIBARIBE - EM RECUPERACAO JUDICIAL | F30: =COUNTIF('CALL SHEET'!$C$2:$C$560,"CLUBE NAUTICO CAPIBARIBE - EM RECUPERACAO JUDICIAL") | G30: =SUMIF('CALL SHEET'!$C$2:$C$560,"CLUBE NAUTICO CAPIBARIBE - EM RECUPERACAO JUDICIAL",'CALL SHEET'!$AB$2:$AB$560) | H30: =COUNTIFS('CALL SHEET'!$C$2:$C$560,"CLUBE NAUTICO CAPIBARIBE - EM RECUPERACAO JUDICIAL",'CALL SHEET'!$D$2:$D$560,"<>NEW") | I30: =COUNTIFS('CALL SHEET'!$C$2:$C$560,"CLUBE NAUTICO CAPIBARIBE - EM RECUPERACAO JUDICIAL",'CALL SHEET'!$D$2:$D$560,"INTERESTED")+COUNTIFS('CALL SHEET'!$C$2:$C$560,"CLUBE NAUTICO CAPIBARIBE - EM RECUPERACAO JUDICIAL",'CALL SHEET'!$D$2:$D$560,"DEAL")
A31: D — Avoid: falência decreed, or | B31: =COUNTIF('CALL SHEET'!$U$2:$U$560,"D") | C31: =SUMIF('CALL SHEET'!$U$2:$U$560,"D",'CALL SHEET'!$AB$2:$AB$560) | E31: Conduscabos Brasil Indústria Comércio de | F31: =COUNTIF('CALL SHEET'!$C$2:$C$560,"Conduscabos Brasil Indústria Comércio de") | G31: =SUMIF('CALL SHEET'!$C$2:$C$560,"Conduscabos Brasil Indústria Comércio de",'CALL SHEET'!$AB$2:$AB$560) | H31: =COUNTIFS('CALL SHEET'!$C$2:$C$560,"Conduscabos Brasil Indústria Comércio de",'CALL SHEET'!$D$2:$D$560,"<>NEW") | I31: =COUNTIFS('CALL SHEET'!$C$2:$C$560,"Conduscabos Brasil Indústria Comércio de",'CALL SHEET'!$D$2:$D$560,"INTERESTED")+COUNTIFS('CALL SHEET'!$C$2:$C$560,"Conduscabos Brasil Indústria Comércio de",'CALL SHEET'!$D$2:$D$560,"DEAL")
A32: ? — Debtor could not be resolved | B32: =COUNTIF('CALL SHEET'!$U$2:$U$560,"?") | C32: =SUMIF('CALL SHEET'!$U$2:$U$560,"?",'CALL SHEET'!$AB$2:$AB$560) | E32: Grupo Arnon de Mello — Lindoso e Araujo | F32: =COUNTIF('CALL SHEET'!$C$2:$C$560,"Grupo Arnon de Mello — Lindoso e Araujo") | G32: =SUMIF('CALL SHEET'!$C$2:$C$560,"Grupo Arnon de Mello — Lindoso e Araujo",'CALL SHEET'!$AB$2:$AB$560) | H32: =COUNTIFS('CALL SHEET'!$C$2:$C$560,"Grupo Arnon de Mello — Lindoso e Araujo",'CALL SHEET'!$D$2:$D$560,"<>NEW") | I32: =COUNTIFS('CALL SHEET'!$C$2:$C$560,"Grupo Arnon de Mello — Lindoso e Araujo",'CALL SHEET'!$D$2:$D$560,"INTERESTED")+COUNTIFS('CALL SHEET'!$C$2:$C$560,"Grupo Arnon de Mello — Lindoso e Araujo",'CALL SHEET'!$D$2:$D$560,"DEAL")
E33: REAL DISTRIBUIDORA ÚNICA RIO COMÉRCIO DE REFRIGERAÇÃO LTDA | F33: =COUNTIF('CALL SHEET'!$C$2:$C$560,"REAL DISTRIBUIDORA ÚNICA RIO COMÉRCIO DE REFRIGERAÇÃO LTDA") | G33: =SUMIF('CALL SHEET'!$C$2:$C$560,"REAL DISTRIBUIDORA ÚNICA RIO COMÉRCIO DE REFRIGERAÇÃO LTDA",'CALL SHEET'!$AB$2:$AB$560) | H33: =COUNTIFS('CALL SHEET'!$C$2:$C$560,"REAL DISTRIBUIDORA ÚNICA RIO COMÉRCIO DE REFRIGERAÇÃO LTDA",'CALL SHEET'!$D$2:$D$560,"<>NEW") | I33: =COUNTIFS('CALL SHEET'!$C$2:$C$560,"REAL DISTRIBUIDORA ÚNICA RIO COMÉRCIO DE REFRIGERAÇÃO LTDA",'CALL SHEET'!$D$2:$D$560,"INTERESTED")+COUNTIFS('CALL SHEET'!$C$2:$C$560,"REAL DISTRIBUIDORA ÚNICA RIO COMÉRCIO DE REFRIGERAÇÃO LTDA",'CALL SHEET'!$D$2:$D$560,"DEAL")
A34: How to use: work the CALL SHEET top-down (it is sorted by our ágio). Set STATUS and NEXT DATE on every touch; this tab updates itself.
A35: Bands: A plan approved · B live · C stale · D avoid. Quotes are a model off the Assumptions tab; the FACE VALUE and the PROOF link are court data. | E35: BY STATE | F35: leads | G35: ágio (R$)
E36: SP | F36: =COUNTIF('CALL SHEET'!$AQ$2:$AQ$560,"SP") | G36: =SUMIF('CALL SHEET'!$AQ$2:$AQ$560,"SP",'CALL SHEET'!$AB$2:$AB$560)
E37: PR | F37: =COUNTIF('CALL SHEET'!$AQ$2:$AQ$560,"PR") | G37: =SUMIF('CALL SHEET'!$AQ$2:$AQ$560,"PR",'CALL SHEET'!$AB$2:$AB$560)
E38: SC | F38: =COUNTIF('CALL SHEET'!$AQ$2:$AQ$560,"SC") | G38: =SUMIF('CALL SHEET'!$AQ$2:$AQ$560,"SC",'CALL SHEET'!$AB$2:$AB$560)
E39: RS | F39: =COUNTIF('CALL SHEET'!$AQ$2:$AQ$560,"RS") | G39: =SUMIF('CALL SHEET'!$AQ$2:$AQ$560,"RS",'CALL SHEET'!$AB$2:$AB$560)
E40: PE | F40: =COUNTIF('CALL SHEET'!$AQ$2:$AQ$560,"PE") | G40: =SUMIF('CALL SHEET'!$AQ$2:$AQ$560,"PE",'CALL SHEET'!$AB$2:$AB$560)
E41: GO | F41: =COUNTIF('CALL SHEET'!$AQ$2:$AQ$560,"GO") | G41: =SUMIF('CALL SHEET'!$AQ$2:$AQ$560,"GO",'CALL SHEET'!$AB$2:$AB$560)
...

Sheet CALL SHEET
A1: CREDITOR — company owed money | B1: AMOUNT OWED (R$) | C1: DEBTOR — company in RJ | D1: STATUS | E1: LAST TOUCH | F1: NEXT ACTION | G1: NEXT DATE | H1: NOTES | I1: DECISION MAKER | J1: Role | K1: Phone 1 | L1: Phone 2 | M1: Mobile (Apollo) | N1: Email | O1: Email 2 | P1: BACKUP CONTACT | Q1: Backup role | R1: Backup phone | S1: Backup email | T1: FACE VALUE (as printed) | U1: DEBTOR BAND | V1: Exp. recovery % | W1: Years to payment | X1: FUND PRICE @ IRR (R$) | Y1: cents | Z1: OUR QUOTE (R$) | AA1: cents | AB1: OUR ÁGIO (R$) | AC1: Ágio pts of face | AD1: Plan status | AE1: PROOF: source document | AF1: Page / row | AG1: Value as printed | AH1: Which list | AI1: Published | AJ1: Reconciled | AK1: Case number | AL1: Court | AM1: Stage | AN1: Filed | AO1: Band reason | AP1: City | AQ1: UF | AR1: Sector | AS1: Size | AT1: Seller fit | AU1: CNPJ root | AV1: Claims | AW1: Flags
A2: DM CONSTRUTORA DE OBRAS LTDA | B2: 1.7805218e+08 | C2: KADIMA EMPREENDIMENTOS E PARTICIPACOES EM RECUPERACAO JUDICIAL | D2: NEW | I2: Giovano Fantin | J2: VP | K2: (41) 3313-8000 | L2: (41) 3313-8090 | N2: giovano@dmconstrutora.com.br | T2: 1.7805218e+08 | U2: B | V2: =IFERROR(VLOOKUP(U2,Assumptions!$A$7:$D$11,2,FALSE),0) | W2: =MAX(0.5,IFERROR(VLOOKUP(U2,Assumptions!$A$7:$D$11,3,FALSE),3)+IFERROR(VLOOKUP(U2,Assumptions!$A$7:$D$11,4,FALSE),8)/2-IF(AN2="",0,YEAR(TODAY())-AN2)) | X2: =T2*V2/(1+Assumptions!$B$3)^W2 | Y2: =IF(T2=0,"",ROUND(X2/T2*100,1)) | Z2: =X2*Assumptions!$B$4 | AA2: =IF(T2=0,"",ROUND(Z2/T2*100,1)) | AB2: =X2-Z2 | AC2: =IF(T2=0,"",ROUND((X2-Z2)/T2*100,1)) | AD2: ESTIMATED | AE2: https://marquesadmjudicial.com.br/sgc/download.php?file=files/processo_documento/processo_documento19270817122025_1_.pdf&nome=Relação Nominal de Credores AJ | AF2: p4 r8 | AG2: p4: R$ 178.052.183,86 | AH2: AJ_LIST | AI2: 2025-12-17 | AJ2: OK | AK2: 0016033-22.2025.8.16.0017 | AL2: TJPR | AM2: ACTIVE | AN2: 2025 | AO2: live case, no plan document yet | AP2: CURITIBA | AQ2: PR | AR2: Construção de rodovias e ferrovias | AS2: DEMAIS | AT2: MID-MARKET | AU2: 76483726 | AV2: 1 | AW2: ROWS:p4r8
A3: PETROLEO BRASILEIRO S A PETROBRAS | B3: 3.3005476e+08 | C3: EGESA ENGENHARIA S/A (Consórcio ETDI) | D3: NEW | I3: MAGDA MARIA DE REGINA CHAMBRIARD | J3: Presidente | K3: (21) 2166-0000 | P3: ANGELICA GARCIA COBAS LAUREANO | Q3: Diretor | R3: (21) 2166-0000 | T3: 3.3005476e+08 | U3: ? | V3: =IFERROR(VLOOKUP(U3,Assumptions!$A$7:$D$11,2,FALSE),0) | W3: =MAX(0.5,IFERROR(VLOOKUP(U3,Assumptions!$A$7:$D$11,3,FALSE),3)+IFERROR(VLOOKUP(U3,Assumptions!$A$7:$D$11,4,FALSE),8)/2-IF(AN3="",0,YEAR(TODAY())-AN3)) | X3: =T3*V3/(1+Assumptions!$B$3)^W3 | Y3: =IF(T3=0,"",ROUND(X3/T3*100,1)) | Z3: =X3*Assumptions!$B$4 | AA3: =IF(T3=0,"",ROUND(Z3/T3*100,1)) | AB3: =X3-Z3 | AC3: =IF(T3=0,"",ROUND((X3-Z3)/T3*100,1)) | AD3: UNKNOWN | AE3: https://scalzilliaj.com.br/sgc/download.php?file=files/processo_documento/processo_documento09514021082025_1_.pdf&nome=04 - Relação de credores das Recuperandas | AF3: p71 r9 | AG3: p71: R$ 330.054.762,86 | AH3: DEBTOR_LIST | AJ3: OK | AK3: (not printed) | AO3: RJ case number not identified on the document | AP3: RIO DE JANEIRO | AQ3: RJ | AR3: Extração de petróleo e gás natural | AS3: DEMAIS | AT3: LARGE CORP | AU3: 33000167 | AV3: 1 | AW3: ROWS:p71r9 VALUE_COL:Valor_Atualizado CASE_NUMBER_CORRECTED
A4: TAG INDUSTRIA E LAMINACAO LTDA | B4: 64713515 | C4: Conduscabos Brasil Indústria Comércio de | D4: NEW | I4: TIAGO RODRIGO DETTILIO | J4: Administrador | K4: (11) 4463-4833 | P4: WEBER MICAEL DA SILVA | Q4: Administrador | R4: (11) 4463-4833 | T4: 64713515 | U4: B | V4: =IFERROR(VLOOKUP(U4,Assumptions!$A$7:$D$11,2,FALSE),0) | W4: =MAX(0.5,IFERROR(VLOOKUP(U4,Assumptions!$A$7:$D$11,3,FALSE),3)+IFERROR(VLOOKUP(U4,Assumptions!$A$7:$D$11,4,FALSE),8)/2-IF(AN4="",0,YEAR(TODAY())-AN4)) | X4: =T4*V4/(1+Assumptions!$B$3)^W4 | Y4: =IF(T4=0,"",ROUND(X4/T4*100,1)) | Z4: =X4*Assumptions!$B$4 | AA4: =IF(T4=0,"",ROUND(Z4/T4*100,1)) | AB4: =X4-Z4 | AC4: =IF(T4=0,"",ROUND((X4-Z4)/T4*100,1)) | AD4: ESTIMATED | AE4: https://assistjud.com.br/wp-content/uploads/elementor/forms/65098c80a5824.pdf | AF4: p10 r4; p19 r8 | AG4: p10: R$ 32.731.819,08; p19: R$ 31.981.695,98 | AH4: AJ_LIST | AI4: 2023-09-18 | AJ4: OK_NO_TOTALS | AK4: 8005129-09.2023.8.05.0039 | AL4: TJBA | AM4: ACTIVE | AN4: 2023 | AO4: live case, no plan document yet | AP4: SAO PAULO | AQ4: SP | AR4: Outras atividades profissionais, científicas e técnicas não especificadas anteriormente | AS4: DEMAIS | AT4: MID-MARKET | AU4: 33233778 | AV4: 2 | AW4: ROWS:p10r4,p19r8 UNRECONCILED_SOURCE
A5: COMPANHIA ESTADUAL DE DISTRIBUICAO DE ENERGIA ELETRICA - CEEE-D | B5: 31446844 | C5: ASSOCIACAO DE CARIDADE SANTA CASA DE RIO GRANDE | D5: NEW | I5: Willian Maeda | J5: Gerente de Planejamento e Controle Financeiro - CEEE Equatorial | K5: (98) 3217-8000 | N5: willian.maeda@equatorialenergia.com.br | P5: Nairton Iwen | Q5: Controller IOP | T5: 31446844 | U5: B | V5: =IFERROR(VLOOKUP(U5,Assumptions!$A$7:$D$11,2,FALSE),0) | W5: =MAX(0.5,IFERROR(VLOOKUP(U5,Assumptions!$A$7:$D$11,3,FALSE),3)+IFERROR(VLOOKUP(U5,Assumptions!$A$7:$D$11,4,FALSE),8)/2-IF(AN5="",0,YEAR(TODAY())-AN5)) | X5: =T5*V5/(1+Assumptions!$B$3)^W5 | Y5: =IF(T5=0,"",ROUND(X5/T5*100,1)) | Z5: =X5*Assumptions!$B$4 | AA5: =IF(T5=0,"",ROUND(Z5/T5*100,1)) | AB5: =X5-Z5 | AC5: =IF(T5=0,"",ROUND((X5-Z5)/T5*100,1)) | AD5: ESTIMATED | AE5: https://scalzilliaj.com.br/sgc/download.php?file=files/processo_documento/processo_documento09120721032023_1_.pdf&nome=15 - Edital do art. 7º, §2º e 53 da Lei 11.101/2005 (segunda lista de credores e recebimento do plano)) | AF5: p26 r26 | AG5: p26: R$ 31.446.843,91 | AH5: AJ_LIST | AI5: 2023-03-21 | AJ5: OK_NO_TOTALS | AK5: 5012306-16.2022.8.21.0023 | AL5: TJRS | AM5: ACTIVE | AN5: 2022 | AO5: live case, no plan document yet | AP5: PORTO ALEGRE | AQ5: RS | AR5: Distribuição de energia elétrica | AS5: DEMAIS | AT5: LARGE CORP | AU5: 08467115 | AV5: 1 | AW5: ROWS:p26r26 UNRECONCILED_SOURCE
A6: HYPERA S.A. | B6: 25912508 | C6: VEV COMERCIO DE MEDICAMENTOS LTDA EM RECUPERACAO JUDICIAL | D6: NEW | I6: BRENO TOLEDO PIRES DE OLIVEIRA | J6: Presidente | K6: (62) 3878-8150 | P6: ADALMARIO GHOVATTO SATHELER DO COUTO | Q6: Diretor | R6: (62) 3878-8150 | T6: 25912508 | U6: B | V6: =IFERROR(VLOOKUP(U6,Assumptions!$A$7:$D$11,2,FALSE),0) | W6: =MAX(0.5,IFERROR(VLOOKUP(U6,Assumptions!$A$7:$D$11,3,FALSE),3)+IFERROR(VLOOKUP(U6,Assumptions!$A$7:$D$11,4,FALSE),8)/2-IF(AN6="",0,YEAR(TODAY())-AN6)) | X6: =T6*V6/(1+Assumptions!$B$3)^W6 | Y6: =IF(T6=0,"",ROUND(X6/T6*100,1)) | Z6: =X6*Assumptions!$B$4 | AA6: =IF(T6=0,"",ROUND(Z6/T6*100,1)) | AB6: =X6-Z6 | AC6: =IF(T6=0,"",ROUND((X6-Z6)/T6*100,1)) | AD6: ESTIMATED | AE6: https://marquesadmjudicial.com.br/sgc/download.php?file=files/processo_documento/processo_documento15293208032024_1_.pdf&nome=Relação Nominal de Credores da AJ-Sintética | AF6: p26 r9 | AG6: p26: R$ 25.912.507,68 | AH6: AJ_LIST | AI6: 2023-03-02 | AJ6: QUARANTINED | AK6: 0005010-98.2023.8.16.0001 | AL6: TJPR | AM6: ACTIVE | AN6: 2023 | AO6: live case, no plan document yet | AP6: SAO PAULO | AQ6: SP | AR6: Comércio atacadista de medicamentos e drogas de uso humano | AS6: DEMAIS | AT6: LARGE CORP | AU6: 02932074 | AV6: 1 | AW6: PARTIAL_DOC_CLASS_III_RECONCILED ROWS:p26r9
A7: COMPANHIA RIOGRANDENSE DE SANEAMENTO - CORSAN | B7: 18555955 | C7: ASSOCIACAO DE CARIDADE SANTA CASA DE RIO GRANDE | D7: NEW | I7: Luiz Pereira | J7: Financial Planning Manager | K7: (05) 1215-5789 | O7: rafaela.milione@corsan.com.br | P7: Rafaela Milione | Q7: Especialista de Tesouraria | S7: rafaela.milione@corsan.com.br | T7: 18555955 | U7: B | V7: =IFERROR(VLOOKUP(U7,Assumptions!$A$7:$D$11,2,FALSE),0) | W7: =MAX(0.5,IFERROR(VLOOKUP(U7,Assumptions!$A$7:$D$11,3,FALSE),3)+IFERROR(VLOOKUP(U7,Assumptions!$A$7:$D$11,4,FALSE),8)/2-IF(AN7="",0,YEAR(TODAY())-AN7)) | X7: =T7*V7/(1+Assumptions!$B$3)^W7 | Y7: =IF(T7=0,"",ROUND(X7/T7*100,1)) | Z7: =X7*Assumptions!$B$4 | AA7: =IF(T7=0,"",ROUND(Z7/T7*100,1)) | AB7: =X7-Z7 | AC7: =IF(T7=0,"",ROUND((X7-Z7)/T7*100,1)) | AD7: ESTIMATED | AE7: https://scalzilliaj.com.br/sgc/download.php?file=files/processo_documento/processo_documento09120721032023_1_.pdf&nome=15 - Edital do art. 7º, §2º e 53 da Lei 11.101/2005 (segunda lista de credores e recebimento do plano)) | AF7: p26 r27 | AG7: p26: R$ 18.555.954,55 | AH7: AJ_LIST | AI7: 2023-03-21 | AJ7: OK_NO_TOTALS | AK7: 5012306-16.2022.8.21.0023 | AL7: TJRS | AM7: ACTIVE | AN7: 2022 | AO7: live case, no plan document yet | AP7: PORTO ALEGRE | AQ7: RS | AR7: Captação, tratamento e distribuição de água | AS7: DEMAIS | AT7: LARGE CORP | AU7: 92802784 | AV7: 1 | AW7: ROWS:p26r27 UNRECONCILED_SOURCE
A8: ADLIM-TERCEIRIZACAO EM SERVICOS LTDA - EM RECUPERACAO JUDICIAL | B8: 20647588 | C8: GRUPO ADLIM – LRF Líderes em Recuperação Judicial e Falência | D8: NEW | I8: Santana Leoterio | J8: Analyst | N8: santana.leoterio@adlim.com.br | T8: 20647588 | U8: B | V8: =IFERROR(VLOOKUP(U8,Assumptions!$A$7:$D$11,2,FALSE),0) | W8: =MAX(0.5,IFERROR(VLOOKUP(U8,Assumptions!$A$7:$D$11,3,FALSE),3)+IFERROR(VLOOKUP(U8,Assumptions!$A$7:$D$11,4,FALSE),8)/2-IF(AN8="",0,YEAR(TODAY())-AN8)) | X8: =T8*V8/(1+Assumptions!$B$3)^W8 | Y8: =IF(T8=0,"",ROUND(X8/T8*100,1)) | Z8: =X8*Assumptions!$B$4 | AA8: =IF(T8=0,"",ROUND(Z8/T8*100,1)) | AB8: =X8-Z8 | AC8: =IF(T8=0,"",ROUND((X8-Z8)/T8*100,1)) | AD8: ESTIMATED | AE8: https://lrflideres.com.br/wp-content/plugins/download-attachments/includes/download.php?id=6051 | AF8: p85 r37; p97 r26 | AG8: p85: R$ 13674501,07; p97: R$ 6973087,07 | AH8: AJ_LIST | AI8: 2024-08-12 | AJ8: QUARANTINED | AK8: 0019761-43.2024.8.17.2001 | AL8: TJPE | AM8: ACTIVE | AN8: 2024 | AO8: live case, no plan document yet | AP8: BEZERROS | AQ8: PE | AR8: Fornecimento e gestão de recursos humanos para terceiros | AS8: DEMAIS | AT8: MID-MARKET | AU8: 11436813 | AV8: 2 | AW8: PARTIAL_DOC_CLASS_III_RECONCILED ROWS:p85r37,p97r26
A9: IBIPORA NEGOCIOS IMOBILIARIOS S.A. | B9: 45075483 | C9: EGESA ENGENHARIA S/A (Consórcio ETDI) | D9: NEW | I9: JOSE JULIO COSTA NETO | J9: Presidente | K9: (31) 3586-9418 | P9: BRUNA GODINHO RESENDE FERREIRA | Q9: Diretor | R9: (31) 3586-9418 | T9: 45075483 | U9: ? | V9: =IFERROR(VLOOKUP(U9,Assumptions!$A$7:$D$11,2,FALSE),0) | W9: =MAX(0.5,IFERROR(VLOOKUP(U9,Assumptions!$A$7:$D$11,3,FALSE),3)+IFERROR(VLOOKUP(U9,Assumptions!$A$7:$D$11,4,FALSE),8)/2-IF(AN9="",0,YEAR(TODAY())-AN9)) | X9: =T9*V9/(1+Assumptions!$B$3)^W9 | Y9: =IF(T9=0,"",ROUND(X9/T9*100,1)) | Z9: =X9*Assumptions!$B$4 | AA9: =IF(T9=0,"",ROUND(Z9/T9*100,1)) | AB9: =X9-Z9 | AC9: =IF(T9=0,"",ROUND((X9-Z9)/T9*100,1)) | AD9: UNKNOWN | AE9: https://scalzilliaj.com.br/sgc/download.php?file=files/processo_documento/processo_documento09514021082025_1_.pdf&nome=04 - Relação de credores das Recuperandas | AF9: p68 r4 | AG9: p68: R$ 45.075.482,57 | AH9: DEBTOR_LIST | AJ9: OK | AK9: (not printed) | AO9: RJ case number not identified on the document | AP9: NOVA LIMA | AQ9: MG | AR9: Compra e venda de imóveis próprios | AS9: DEMAIS | AT9: MID-MARKET | AU9: 19256534 | AV9: 1 | AW9: ROWS:p68r4 VALUE_COL:Valor_Atualizado CASE_NUMBER_CORRECTED
A10: DC COMERCIO, REPRESENTACOES, INVESTIMENTOS E PARTICIPACOES LTDA. | B10: 11125000 | C10: R W CONSTRUCOES LTDA | D10: NEW | I10: FERNANDO MELO CATAO | J10: Sócio-Administrador | K10: (81) 3032-8400 | L10: (81) 3419-8550 | T10: 11125000 | U10: B | V10: =IFERROR(VLOOKUP(U10,Assumptions!$A$7:$D$11,2,FALSE),0) | W10: =MAX(0.5,IFERROR(VLOOKUP(U10,Assumptions!$A$7:$D$11,3,FALSE),3)+IFERROR(VLOOKUP(U10,Assumptions!$A$7:$D$11,4,FALSE),8)/2-IF(AN10="",0,YEAR(TODAY())-AN10)) | X10: =T10*V10/(1+Assumptions!$B$3)^W10 | Y10: =IF(T10=0,"",ROUND(X10/T10*100,1)) | Z10: =X10*Assumptions!$B$4 | AA10: =IF(T10=0,"",ROUND(Z10/T10*100,1)) | AB10: =X10-Z10 | AC10: =IF(T10=0,"",ROUND((X10-Z10)/T10*100,1)) | AD10: ESTIMATED | AE10: https://lrflideres.com.br/wp-content/plugins/download-attachments/includes/download.php?id=4023 | AF10: p4 r68; p7 r92; p9 r68 | AG10: p4: R$ 1.150.000,00; p7: R$ 9.715.000,00; p9: R$ 260.000,00 | AH10: DEBTOR_LIST | AJ10: QUARANTINED | AK10: 0002484-82.2022.8.17.2001 | AL10: TJPE | AM10: ACTIVE | AN10: 2022 | AO10: live case, no plan document yet | AP10: RECIFE | AQ10: PE | AR10: Aluguel de imóveis próprios | AS10: DEMAIS | AT10: MID-MARKET | AU10: 09036221 | AV10: 3 | AW10: PARTIAL_DOC_CLASS_III_RECONCILED ROWS:p4r68,p7r92,p9r68
A11: GREE ELECTRIC APPLIANCES DO BRASIL LTDA. | B11: 13499976 | C11: REAL DISTRIBUIDORA ÚNICA RIO COMÉRCIO DE REFRIGERAÇÃO LTDA | D11: NEW | I11: Nicolaus Cheng | J11: Commercial Director | K11: (92) 2123-6900 | N11: nicolaus@gree.com.br | O11: carlos.murano@gree-am.com.br | P11: Carlos Murano | Q11: Executive Sales Manager | S11: carlos.murano@gree-am.com.br | T11: 13499976 | U11: B | V11: =IFERROR(VLOOKUP(U11,Assumptions!$A$7:$D$11,2,FALSE),0) | W11: =MAX(0.5,IFERROR(VLOOKUP(U11,Assumptions!$A$7:$D$11,3,FALSE),3)+IFERROR(VLOOKUP(U11,Assumptions!$A$7:$D$11,4,FALSE),8)/2-IF(AN11="",0,YEAR(TODAY())-AN11)) | X11: =T11*V11/(1+Assumptions!$B$3)^W11 | Y11: =IF(T11=0,"",ROUND(X11/T11*100,1)) | Z11: =X11*Assumptions!$B$4 | AA11: =IF(T11=0,"",ROUND(Z11/T11*100,1)) | AB11: =X11-Z11 | AC11: =IF(T11=0,"",ROUND((X11-Z11)/T11*100,1)) | AD11: UNKNOWN | AE11: https://inova-aj.com.br/wp-content/uploads/2026/08/1a-Relacao-de-Credores-Real.pdf | AF11: p1 r32 | AG11: p1: R$ 13.499.976,37 | AH11: AJ_LIST | AI11: 2023-06-05 | AJ11: OK | AK11: 0873061-47.2023.8.19.0001 | AL11: TJ | AN11: 2023 | AO11: live case, no plan document yet | AP11: MANAUS | AQ11: AM | AR11: Fabricação de aparelhos e equipamentos de ar condicionado para uso não-industrial | AS11: DEMAIS | AT11: LARGE CORP | AU11: 03519135 | AV11: 1 | AW11: ALT_VALUE:R$9.815.941,50 ROWS:p1r32
A12: LOUIS DREYFUS COMPANY SUCOS S.A | B12: 13129218 | D12: NEW | I12: Paula Peixoto | J12: Gerente Adm Controladoria - Originação Sucos | K12: (11) 3039-7160 | L12: (13) 2127-9893 | N12: paula.peixoto@ldc.com | O12: bruno.nunes@ldc.com | P12: Bruno Nunes | Q12: Gerente Executivo de Engenharia & Projetos - Plataforma Sucos | S12: bruno.nunes@ldc.com | T12: 13129218 | U12: C | V12: =IFERROR(VLOOKUP(U12,Assumptions!$A$7:$D$11,2,FALSE),0) | W12: =MAX(0.5,IFERROR(VLOOKUP(U12,Assumptions!$A$7:$D$11,3,FALSE),3)+IFERROR(VLOOKUP(U12,Assumptions!$A$7:$D$11,4,FALSE),8)/2-IF(AN12="",0,YEAR(TODAY())-AN12)) | X12: =T12*V12/(1+Assumptions!$B$3)^W12 | Y12: =IF(T12=0,"",ROUND(X12/T12*100,1)) | Z12: =X12*Assumptions!$B$4 | AA12: =IF(T12=0,"",ROUND(Z12/T12*100,1)) | AB12: =X12-Z12 | AC12: =IF(T12=0,"",ROUND((X12-Z12)/T12*100,1)) | AD12: UNKNOWN | AE12: https://violet-wolf-754008.hostingersite.com/wp-content/uploads/2022/10/Primeiro-Edital-de-Credores-Integral-com-creditos.pdf | AF12: p4 r1 | AG12: p4: R$ 13.129.217,80 | AH12: UNKNOWN | AJ12: OK | AK12: 0000941-21.2012.8.26.0101 | AL12: TJ | AN12: 2012 | AO12: 14y since filing, no plan document | AP12: SAO PAULO | AQ12: SP | AR12: Fabricação de sucos concentrados de frutas, hortaliças e legumes | AS12: DEMAIS | AT12: LARGE CORP | AU12: 00831373 | AV12: 1 | AW12: ROWS:p4r1 VALUE_COL:Valor
A13: AGUIA SERVICOS DE VIGILANCIA LTDA - EM RECUPERACAO JUDICIAL | B13: 13645092 | C13: GRUPO ADLIM – LRF Líderes em Recuperação Judicial e Falência | D13: NEW | I13: JONAS ALVARENGA DA SILVA | J13: Sócio-Administrador | K13: (81) 3252-6115 | L13: (81) 3252-6117 | T13: 13645092 | U13: B | V13: =IFERROR(VLOOKUP(U13,Assumptions!$A$7:$D$11,2,FALSE),0) | W13: =MAX(0.5,IFERROR(VLOOKUP(U13,Assumptions!$A$7:$D$11,3,FALSE),3)+IFERROR(VLOOKUP(U13,Assumptions!$A$7:$D$11,4,FALSE),8)/2-IF(AN13="",0,YEAR(TODAY())-AN13)) | X13: =T13*V13/(1+Assumptions!$B$3)^W13 | Y13: =IF(T13=0,"",ROUND(X13/T13*100,1)) | Z13: =X13*Assumptions!$B$4 | AA13: =IF(T13=0,"",ROUND(Z13/T13*100,1)) | AB13: =X13-Z13 | AC13: =IF(T13=0,"",ROUND((X13-Z13)/T13*100,1)) | AD13: ESTIMATED | AE13: https://lrflideres.com.br/wp-content/plugins/download-attachments/includes/download.php?id=6051 | AF13: p97 r27 | AG13: p97: R$ 13645091,92 | AH13: AJ_LIST | AI13: 2024-08-12 | AJ13: QUARANTINED | AK13: 0019761-43.2024.8.17.2001 | AL13: TJPE | AM13: ACTIVE | AN13: 2024 | AO13: live case, no plan document yet | AP13: RECIFE | AQ13: PE | AR13: Atividades de vigilância e segurança privada | AS13: DEMAIS | AT13: MID-MARKET | AU13: 11516861 | AV13: 1 | AW13: PARTIAL_DOC_CLASS_III_RECONCILED ROWS:p97r27
A14: SANDOZ DO BRASIL INDUSTRIA FARMACEUTICA LTDA. | B14: 10696834 | C14: VEV COMERCIO DE MEDICAMENTOS LTDA EM RECUPERACAO JUDICIAL | D14: NEW | I14: BRUNO PETENUCI | J14: Administrador | K14: (43) 3174-8000 | P14: DANIELA DE ALMEIDA COUTO BONCIANI | Q14: Administrador | R14: (43) 3174-8000 | T14: 10696834 | U14: B | V14: =IFERROR(VLOOKUP(U14,Assumptions!$A$7:$D$11,2,FALSE),0) | W14: =MAX(0.5,IFERROR(VLOOKUP(U14,Assumptions!$A$7:$D$11,3,FALSE),3)+IFERROR(VLOOKUP(U14,Assumptions!$A$7:$D$11,4,FALSE),8)/2-IF(AN14="",0,YEAR(TODAY())-AN14)) | X14: =T14*V14/(1+Assumptions!$B$3)^W14 | Y14: =IF(T14=0,"",ROUND(X14/T14*100,1)) | Z14: =X14*Assumptions!$B$4 | AA14: =IF(T14=0,"",ROUND(Z14/T14*100,1)) | AB14: =X14-Z14 | AC14: =IF(T14=0,"",ROUND((X14-Z14)/T14*100,1)) | AD14: ESTIMATED | AE14: https://marquesadmjudicial.com.br/sgc/download.php?file=files/processo_documento/processo_documento15293208032024_1_.pdf&nome=Relação Nominal de Credores da AJ-Sintética | AF14: p31 r4 | AG14: p31: R$ 10.696.833,99 | AH14: AJ_LIST | AI14: 2023-03-02 | AJ14: QUARANTINED | AK14: 0005010-98.2023.8.16.0001 | AL14: TJPR | AM14: ACTIVE | AN14: 2023 | AO14: live case, no plan document yet | AP14: CAMBE | AQ14: PR | AR14: Fabricação de medicamentos alopáticos para uso humano | AS14: DEMAIS | AT14: LARGE CORP | AU14: 61286647 | AV14: 1 | AW14: PARTIAL_DOC_CLASS_III_RECONCILED ROWS:p31r4
A15: BASTON INDUSTRIA DE AEROSSOIS LTDA | B15: 10636330 | C15: VEV COMERCIO DE MEDICAMENTOS LTDA EM RECUPERACAO JUDICIAL | D15: NEW | I15: Ronaldo Santos | J15: Chief Financial Officer | K15: (42) 3252-8120 | L15: (42) 3252-1705 | O15: filipe.lusana@baston.com.br | P15: Filipe Lusana | Q15: Vice Presidente Comercial | S15: filipe.lusana@baston.com.br | T15: 10636330 | U15: B | V15: =IFERROR(VLOOKUP(U15,Assumptions!$A$7:$D$11,2,FALSE),0) | W15: =MAX(0.5,IFERROR(VLOOKUP(U15,Assumptions!$A$7:$D$11,3,FALSE),3)+IFERROR(VLOOKUP(U15,Assumptions!$A$7:$D$11,4,FALSE),8)/2-IF(AN15="",0,YEAR(TODAY())-AN15)) | X15: =T15*V15/(1+Assumptions!$B$3)^W15 | Y15: =IF(T15=0,"",ROUND(X15/T15*100,1)) | Z15: =X15*Assumptions!$B$4 | AA15: =IF(T15=0,"",ROUND(Z15/T15*100,1)) | AB15: =X15-Z15 | AC15: =IF(T15=0,"",ROUND((X15-Z15)/T15*100,1)) | AD15: ESTIMATED | AE15: https://marquesadmjudicial.com.br/sgc/download.php?file=files/processo_documento/processo_documento15293208032024_1_.pdf&nome=Relação Nominal de Credores da AJ-Sintética | AF15: p21 r8 | AG15: p21: R$ 10.636.330,31 | AH15: AJ_LIST | AI15: 2023-03-02 | AJ15: QUARANTINED | AK15: 0005010-98.2023.8.16.0001 | AL15: TJPR | AM15: ACTIVE | AN15: 2023 | AO15: live case, no plan document yet | AP15: PALMEIRA | AQ15: PR | AR15: Fabricação de outros produtos químicos não especificados anteriormente | AS15: DEMAIS | AT15: LARGE CORP | AU15: 05855974 | AV15: 1 | AW15: PARTIAL_DOC_CLASS_III_RECONCILED ROWS:p21r8
A16: SPC BRASIL S.A. | B16: 18875474 | C16: E FALENCIA | D16: NEW | I16: Yago Nunes | J16: Analista de Controladoria e Pricing Sênior | K16: (11) 3549-6800 | N16: yago.nunes@spcbrasil.com.br | O16: marcio.bauer@spcbrasil.com.br | P16: Marcio Bauer | Q16: Head Comercial Sul no SPC Brasil | S16: marcio.bauer@spcbrasil.com.br | T16: 18875474 | U16: B | V16: =IFERROR(VLOOKUP(U16,Assumptions!$A$7:$D$11,2,FALSE),0) | W16: =MAX(0.5,IFERROR(VLOOKUP(U16,Assumptions!$A$7:$D$11,3,FALSE),3)+IFERROR(VLOOKUP(U16,Assumptions!$A$7:$D$11,4,FALSE),8)/2-IF(AN16="",0,YEAR(TODAY())-AN16)) | X16: =T16*V16/(1+Assumptions!$B$3)^W16 | Y16: =IF(T16=0,"",ROUND(X16/T16*100,1)) | Z16: =X16*Assumptions!$B$4 | AA16: =IF(T16=0,"",ROUND(Z16/T16*100,1)) | AB16: =X16-Z16 | AC16: =IF(T16=0,"",ROUND((X16-Z16)/T16*100,1)) | AD16: ESTIMATED | AE16: https://recuperasolucoes.com/wp-content/plugins/download-attachments/includes/download.php?id=1597 | AF16: p13 r8 | AG16: p13: R$ 18.875.473,82 | AH16: DEBTOR_LIST | AI16: 2026-05-21 | AJ16: OK | AK16: 0001639-09.2026.8.17.2810 | AL16: TJPE | AM16: ACTIVE | AN16: 2026 | AO16: live case, no plan document yet | AP16: BARUERI | AQ16: SP | AR16: Portais, provedores de conteúdo e outros serviços de informação na internet | AS16: DEMAIS | AT16: MID-MARKET | AU16: 29341643 | AV16: 1 | AW16: ROWS:p13r8
A17: DANONE LTDA | B17: 9093937.7 | C17: VEV COMERCIO DE MEDICAMENTOS LTDA EM RECUPERACAO JUDICIAL | D17: NEW | I17: GEOVANI VIEIRA MANZANO | J17: Administrador | K17: (35) 3729-7901 | P17: TIAGO CARNEIRO DOS SANTOS | Q17: Administrador | R17: (35) 3729-7901 | T17: 9093937.7 | U17: B | V17: =IFERROR(VLOOKUP(U17,Assumptions!$A$7:$D$11,2,FALSE),0) | W17: =MAX(0.5,IFERROR(VLOOKUP(U17,Assumptions!$A$7:$D$11,3,FALSE),3)+IFERROR(VLOOKUP(U17,Assumptions!$A$7:$D$11,4,FALSE),8)/2-IF(AN17="",0,YEAR(TODAY())-AN17)) | X17: =T17*V17/(1+Assumptions!$B$3)^W17 | Y17: =IF(T17=0,"",ROUND(X17/T17*100,1)) | Z17: =X17*Assumptions!$B$4 | AA17: =IF(T17=0,"",ROUND(Z17/T17*100,1)) | AB17: =X17-Z17 | AC17: =IF(T17=0,"",ROUND((X17-Z17)/T17*100,1)) | AD17: ESTIMATED | AE17: https://marquesadmjudicial.com.br/sgc/download.php?file=files/processo_documento/processo_documento15293208032024_1_.pdf&nome=Relação Nominal de Credores da AJ-Sintética | AF17: p24 r6 | AG17: p24: R$ 9.093.937,71 | AH17: AJ_LIST | AI17: 2023-03-02 | AJ17: QUARANTINED | AK17: 0005010-98.2023.8.16.0001 | AL17: TJPR | AM17: ACTIVE | AN17: 2023 | AO17: live case, no plan document yet | AP17: SAO PAULO | AQ17: SP | AR17: Fabricação de laticínios | AS17: DEMAIS | AT17: LARGE CORP | AU17: 23643315 | AV17: 1 | AW17: PARTIAL_DOC_CLASS_III_RECONCILED ROWS:p24r6
A18: VINICOLA CAMPESTRE LTDA | B18: 13980346 | C18: ARRUDA & MELO COMERCIO E DISTRIBUICAO DE ALIMENTOS E BEBIDAS LTDA | D18: NEW | I18: Carlos Quintus | J18: Commercial Director | K18: (54) 3511-6050 | L18: (54) 3511-6052 | N18: carlos.quintus@pergola.com.br | P18: Camila Treptow | Q18: Financial Analyst | T18: 13980346 | U18: B | V18: =IFERROR(VLOOKUP(U18,Assumptions!$A$7:$D$11,2,FALSE),0) | W18: =MAX(0.5,IFERROR(VLOOKUP(U18,Assumptions!$A$7:$D$11,3,FALSE),3)+IFERROR(VLOOKUP(U18,Assumptions!$A$7:$D$11,4,FALSE),8)/2-IF(AN18="",0,YEAR(TODAY())-AN18)) | X18: =T18*V18/(1+Assumptions!$B$3)^W18 | Y18: =IF(T18=0,"",ROUND(X18/T18*100,1)) | Z18: =X18*Assumptions!$B$4 | AA18: =IF(T18=0,"",ROUND(Z18/T18*100,1)) | AB18: =X18-Z18 | AC18: =IF(T18=0,"",ROUND((X18-Z18)/T18*100,1)) | AD18: ESTIMATED | AE18: https://diligence.adm.br/wp-content/uploads/2025/06/Edital-1a-Lista-de-Credores.pdf | AF18: p5 r60; p5 r61 | AG18: p5: R$ 4.421.862,65; p5: R$ 9.558.482,85 | AH18: DEBTOR_LIST | AI18: 2025-06-10 | AJ18: OK | AK18: 0008526-45.2025.8.17.2001 | AL18: TJPE | AM18: ACTIVE | AN18: 2025 | AO18: live case, no plan document yet | AP18: CAMPESTRE DA SERRA | AQ18: RS | AR18: Fabricação de vinho | AS18: DEMAIS | AT18: LARGE CORP | AU18: 98521909 | AV18: 2 | AW18: ROWS:p5r60,p5r61
A19: CLIMAZON INDUSTRIAL LTDA | B19: 8012248.6 | C19: REAL DISTRIBUIDORA ÚNICA RIO COMÉRCIO DE REFRIGERAÇÃO LTDA | D19: NEW | I19: ADRIANO ZACCARI FORTUNA | J19: Administrador | K19: (51) 3477-9873 | L19: (51) 3477-9684 | P19: LUCIANO FREITAS DE OLIVEIRA | Q19: Administrador | R19: (51) 3477-9684 | T19: 8012248.6 | U19: B | V19: =IFERROR(VLOOKUP(U19,Assumptions!$A$7:$D$11,2,FALSE),0) | W19: =MAX(0.5,IFERROR(VLOOKUP(U19,Assumptions!$A$7:$D$11,3,FALSE),3)+IFERROR(VLOOKUP(U19,Assumptions!$A$7:$D$11,4,FALSE),8)/2-IF(AN19="",0,YEAR(TODAY())-AN19)) | X19: =T19*V19/(1+Assumptions!$B$3)^W19 | Y19: =IF(T19=0,"",ROUND(X19/T19*100,1)) | Z19: =X19*Assumptions!$B$4 | AA19: =IF(T19=0,"",ROUND(Z19/T19*100,1)) | AB19: =X19-Z19 | AC19: =IF(T19=0,"",ROUND((X19-Z19)/T19*100,1)) | AD19: UNKNOWN | AE19: https://inova-aj.com.br/wp-content/uploads/2026/08/1a-Relacao-de-Credores-Real.pdf | AF19: p1 r25 | AG19: p1: R$ 8.012.248,57 | AH19: AJ_LIST | AI19: 2023-06-05 | AJ19: OK | AK19: 0873061-47.2023.8.19.0001 | AL19: TJ | AN19: 2023 | AO19: live case, no plan document yet | AP19: MANAUS | AQ19: AM | AR19: Fabricação de aparelhos e equipamentos de ar condicionado para uso não-industrial | AS19: DEMAIS | AT19: MID-MARKET | AU19: 04222931 | AV19: 1 | AW19: ALT_VALUE:R$5.825.770,44 ROWS:p1r25
A20: LEGRAND PHARMA INDUSTRIA FARMACEUTICA LTDA | B20: 7715049.7 | C20: VEV COMERCIO DE MEDICAMENTOS LTDA EM RECUPERACAO JUDICIAL | D20: NEW | I20: Edgar Figueiredo | J20: Gerente Nacional de Distribuição | K20: (19) 3887-9800 | N20: edgar.figueiredo@legrandpharma.com.br | P20: TATIANA AZEVEDO VILLELA SANTOS FONTES | Q20: Administrador | R20: (19) 3887-9800 | T20: 7715049.7 | U20: B | V20: =IFERROR(VLOOKUP(U20,Assumptions!$A$7:$D$11,2,FALSE),0) | W20: =MAX(0.5,IFERROR(VLOOKUP(U20,Assumptions!$A$7:$D$11,3,FALSE),3)+IFERROR(VLOOKUP(U20,Assumptions!$A$7:$D$11,4,FALSE),8)/2-IF(AN20="",0,YEAR(TODAY())-AN20)) | X20: =T20*V20/(1+Assumptions!$B$3)^W20 | Y20: =IF(T20=0,"",ROUND(X20/T20*100,1)) | Z20: =X20*Assumptions!$B$4 | AA20: =IF(T20=0,"",ROUND(Z20/T20*100,1)) | AB20: =X20-Z20 | AC20: =IF(T20=0,"",ROUND((X20-Z20)/T20*100,1)) | AD20: ESTIMATED | AE20: https://marquesadmjudicial.com.br/sgc/download.php?file=files/processo_documento/processo_documento15293208032024_1_.pdf&nome=Relação Nominal de Credores da AJ-Sintética | AF20: p28 r5 | AG20: p28: R$ 7.715.049,72 | AH20: AJ_LIST | AI20: 2023-03-02 | AJ20: QUARANTINED | AK20: 0005010-98.2023.8.16.0001 | AL20: TJPR | AM20: ACTIVE | AN20: 2023 | AO20: live case, no plan document yet | AP20: HORTOLANDIA | AQ20: SP | AR20: Fabricação de medicamentos alopáticos para uso humano | AS20: DEMAIS | AT20: MID-MARKET | AU20: 05044984 | AV20: 1 | AW20: PARTIAL_DOC_CLASS_III_RECONCILED ROWS:p28r5
A21: ALBAUGH AGRO BRASIL LTDA. | B21: 11525550 | C21: NORTESUL COMERCIAL AGRICOLA LTDA EM RECUPERACAO JUDICIAL | D21: NEW | I21: CESAR EMILIANO ROJAS RUIZ | J21: Administrador | K21: (11) 3076-4243 | P21: MARCELO PACE | Q21: Administrador | R21: (11) 3076-4243 | T21: 11525550 | U21: B | V21: =IFERROR(VLOOKUP(U21,Assumptions!$A$7:$D$11,2,FALSE),0) | W21: =MAX(0.5,IFERROR(VLOOKUP(U21,Assumptions!$A$7:$D$11,3,FALSE),3)+IFERROR(VLOOKUP(U21,Assumptions!$A$7:$D$11,4,FALSE),8)/2-IF(AN21="",0,YEAR(TODAY())-AN21)) | X21: =T21*V21/(1+Assumptions!$B$3)^W21 | Y21: =IF(T21=0,"",ROUND(X21/T21*100,1)) | Z21: =X21*Assumptions!$B$4 | AA21: =IF(T21=0,"",ROUND(Z21/T21*100,1)) | AB21: =X21-Z21 | AC21: =IF(T21=0,"",ROUND((X21-Z21)/T21*100,1)) | AD21: ESTIMATED | AE21: https://lrflideres.com.br/wp-content/plugins/download-attachments/includes/download.php?id=6879 | AF21: p1 r4 | AG21: p1: R$ 11.525.550,26 | AH21: AJ_LIST | AI21: 2026-01-15 | AJ21: OK | AK21: 0804401-51.2025.8.14.0039 | AL21: TJPA | AM21: ACTIVE | AN21: 2025 | AO21: live case, no plan document yet | AP21: SAO PAULO | AQ21: SP | AR21: Fabricação de defensivos agrícolas | AS21: DEMAIS | AT21: LARGE CORP | AU21: 01789121 | AV21: 1 | AW21: ROWS:p1r4
A22: CATAO CONFECCOES LTDA - EM RECUPERACAO JUDICIAL | B22: 5843155.8 | C22: R W CONSTRUCOES LTDA | D22: NEW | I22: FLAVIO DANTAS CATAO | J22: Sócio-Administrador | K22: 000000000000 | T22: 5843155.8 | U22: B | V22: =IFERROR(VLOOKUP(U22,Assumptions!$A$7:$D$11,2,FALSE),0) | W22: =MAX(0.5,IFERROR(VLOOKUP(U22,Assumptions!$A$7:$D$11,3,FALSE),3)+IFERROR(VLOOKUP(U22,Assumptions!$A$7:$D$11,4,FALSE),8)/2-IF(AN22="",0,YEAR(TODAY())-AN22)) | X22: =T22*V22/(1+Assumptions!$B$3)^W22 | Y22: =IF(T22=0,"",ROUND(X22/T22*100,1)) | Z22: =X22*Assumptions!$B$4 | AA22: =IF(T22=0,"",ROUND(Z22/T22*100,1)) | AB22: =X22-Z22 | AC22: =IF(T22=0,"",ROUND((X22-Z22)/T22*100,1)) | AD22: ESTIMATED | AE22: https://lrflideres.com.br/wp-content/plugins/download-attachments/includes/download.php?id=4023 | AF22: p4 r60; p9 r62 | AG22: p4: R$ 1.447.463,41; p9: R$ 4.395.692,34 | AH22: DEBTOR_LIST | AJ22: QUARANTINED | AK22: 0002484-82.2022.8.17.2001 | AL22: TJPE | AM22: ACTIVE | AN22: 2022 | AO22: live case, no plan document yet | AP22: RECIFE | AQ22: PE | AR22: Comércio varejista de artigos do vestuário e acessórios | AS22: DEMAIS | AT22: MID-MARKET | AU22: 10775286 | AV22: 2 | AW22: PARTIAL_DOC_CLASS_III_RECONCILED ROWS:p4r60,p9r62
A23: FEDERACAO PERNAMBUCANA DE FUTEBOL | B23: 7251967.1 | C23: CLUBE NAUTICO CAPIBARIBE - EM RECUPERACAO JUDICIAL | D23: NEW | I23: Pedro Lacerda | J23: Diretor de Governança e Compliance | N23: pedro.lacerda@fpf-pe.com.br | T23: 7251967.1 | U23: B | V23: =IFERROR(VLOOKUP(U23,Assumptions!$A$7:$D$11,2,FALSE),0) | W23: =MAX(0.5,IFERROR(VLOOKUP(U23,Assumptions!$A$7:$D$11,3,FALSE),3)+IFERROR(VLOOKUP(U23,Assumptions!$A$7:$D$11,4,FALSE),8)/2-IF(AN23="",0,YEAR(TODAY())-AN23)) | X23: =T23*V23/(1+Assumptions!$B$3)^W23 | Y23: =IF(T23=0,"",ROUND(X23/T23*100,1)) | Z23: =X23*Assumptions!$B$4 | AA23: =IF(T23=0,"",ROUND(Z23/T23*100,1)) | AB23: =X23-Z23 | AC23: =IF(T23=0,"",ROUND((X23-Z23)/T23*100,1)) | AD23: ESTIMATED | AE23: https://lrflideres.com.br/wp-content/plugins/download-attachments/includes/download.php?id=5589 | AF23: p12 r9 | AG23: p12: R$ 7.251.967,09 | AH23: AJ_LIST | AI23: 2023-11-27 | AJ23: QUARANTINED | AK23: 0011283-80.2023.8.17.2001 | AL23: TJPE | AM23: ACTIVE | AN23: 2023 | AO23: live case, no plan document yet | AP23: RECIFE | AQ23: PE | AR23: Produção e promoção de eventos esportivos | AS23: DEMAIS | AT23: MID-MARKET | AU23: 10956258 | AV23: 1 | AW23: PARTIAL_DOC_CLASS_III_RECONCILED ROWS:p12r9
A24: TABLEROS IND. E COM. DE PAINEIS LTDA | B24: 12966350 | C24: FORMAPLAN FORMAS PLANEJADAS INDUSTRIA E COMERCIO LTDA EM RECUPERACAO JUDICIAL | D24: NEW | I24: MARCIO GERALDO ROSA | J24: Sócio-Administrador | K24: (46) 3263-8500 | T24: 12966350 | U24: C | V24: =IFERROR(VLOOKUP(U24,Assumptions!$A$7:$D$11,2,FALSE),0) | W24: =MAX(0.5,IFERROR(VLOOKUP(U24,Assumptions!$A$7:$D$11,3,FALSE),3)+IFERROR(VLOOKUP(U24,Assumptions!$A$7:$D$11,4,FALSE),8)/2-IF(AN24="",0,YEAR(TODAY())-AN24)) | X24: =T24*V24/(1+Assumptions!$B$3)^W24 | Y24: =IF(T24=0,"",ROUND(X24/T24*100,1)) | Z24: =X24*Assumptions!$B$4 | AA24: =IF(T24=0,"",ROUND(Z24/T24*100,1)) | AB24: =X24-Z24 | AC24: =IF(T24=0,"",ROUND((X24-Z24)/T24*100,1)) | AD24: ESTIMATED | AE24: https://marquesadmjudicial.com.br/sgc/download.php?file=files/processo_documento/processo_documento15232121112024_1_.pdf&nome=Relação de Credores | AF24: p16 r3 | AG24: p16: R$ 12.966.349,62 | AH24: AJ_LIST | AI24: 2021-01-22 | AJ24: QUARANTINED | AK24: 0000410-68.2021.8.16.0174 | AL24: TJPR | AM24: ACTIVE | AN24: 2021 | AO24: 5y since filing, no plan document | AP24: PALMAS | AQ24: PR | AR24: Fabricação de madeira laminada e de chapas de madeira compensada, prensada e aglomerada | AS24: DEMAIS | AT24: MID-MARKET | AU24: 09402999 | AV24: 1 | AW24: PARTIAL_DOC_CLASS_III_RECONCILED ROWS:p16r3
A25: L'OREAL BRASIL COMERCIAL DE COSMETICOS LTDA | B25: 5955264.1 | C25: VEV COMERCIO DE MEDICAMENTOS LTDA EM RECUPERACAO JUDICIAL | D25: NEW | I25: MARCELO ZIMET | J25: Administrador | K25: (21) 4505-9616 | T25: 5955264.1 | U25: B | V25: =IFERROR(VLOOKUP(U25,Assumptions!$A$7:$D$11,2,FALSE),0) | W25: =MAX(0.5,IFERROR(VLOOKUP(U25,Assumptions!$A$7:$D$11,3,FALSE),3)+IFERROR(VLOOKUP(U25,Assumptions!$A$7:$D$11,4,FALSE),8)/2-IF(AN25="",0,YEAR(TODAY())-AN25)) | X25: =T25*V25/(1+Assumptions!$B$3)^W25 | Y25: =IF(T25=0,"",ROUND(X25/T25*100,1)) | Z25: =X25*Assumptions!$B$4 | AA25: =IF(T25=0,"",ROUND(Z25/T25*100,1)) | AB25: =X25-Z25 | AC25: =IF(T25=0,"",ROUND((X25-Z25)/T25*100,1)) | AD25: ESTIMATED | AE25: https://marquesadmjudicial.com.br/sgc/download.php?file=files/processo_documento/processo_documento15293208032024_1_.pdf&nome=Relação Nominal de Credores da AJ-Sintética | AF25: p28 r10 | AG25: p28: R$ 5.955.264,10 | AH25: AJ_LIST | AI25: 2023-03-02 | AJ25: QUARANTINED | AK25: 0005010-98.2023.8.16.0001 | AL25: TJPR | AM25: ACTIVE | AN25: 2023 | AO25: live case, no plan document yet | AP25: RIO DE JANEIRO | AQ25: RJ | AR25: Comércio atacadista de cosméticos e produtos de perfumaria | AS25: DEMAIS | AT25: LARGE CORP | AU25: 30278428 | AV25: 1 | AW25: PARTIAL_DOC_CLASS_III_RECONCILED ROWS:p28r10
A26: AGROFIELD ASSESSORIA ADMINISTRATIVA LTDA | B26: 6434083.2 | C26: E FALENCIA | D26: NEW | I26: SERGIO LUIZ SILVA DA FONSECA LINS | J26: Sócio-Administrador | K26: (81) 3339-1977 | T26: 6434083.2 | U26: C | V26: =IFERROR(VLOOKUP(U26,Assumptions!$A$7:$D$11,2,FALSE),0) | W26: =MAX(0.5,IFERROR(VLOOKUP(U26,Assumptions!$A$7:$D$11,3,FALSE),3)+IFERROR(VLOOKUP(U26,Assumptions!$A$7:$D$11,4,FALSE),8)/2-IF(AN26="",0,YEAR(TODAY())-AN26)) | X26: =T26*V26/(1+Assumptions!$B$3)^W26 | Y26: =IF(T26=0,"",ROUND(X26/T26*100,1)) | Z26: =X26*Assumptions!$B$4 | AA26: =IF(T26=0,"",ROUND(Z26/T26*100,1)) | AB26: =X26-Z26 | AC26: =IF(T26=0,"",ROUND((X26-Z26)/T26*100,1)) | AD26: UNKNOWN | AE26: https://diligence.adm.br/wp-content/plugins/download-attachments/includes/download.php?id=4579 | AF26: p8 r2 | AG26: p8: R$ 6.434.083,18 | AH26: AJ_LIST | AI26: 2024-06-11 | AJ26: OK_NO_TOTALS | AK26: 0032731-52.2010.8.17.0001 | AL26: TJ | AN26: 2010 | AO26: 16y since filing, no plan document | AP26: RECIFE | AQ26: PE | AR26: Atividades de intermediação e agenciamento de serviços e negócios em geral, exceto imobiliários | AS26: DEMAIS | AT26: MID-MARKET | AU26: 06284974 | AV26: 1 | AW26: ROWS:p8r2 UNRECONCILED_SOURCE VALUE_COL:Crédito_1ª_Lista
A27: FIRST S/A | B27: 8354815.1 | D27: NEW | I27: NATANAEL SANTOS DE SOUZA | J27: Presidente | K27: (11) 5054-8110 | P27: MARA HELENA MARTINI DE SOUZA | Q27: Diretor | R27: (11) 5054-8110 | T27: 8354815.1 | U27: B | V27: =IFERROR(VLOOKUP(U27,Assumptions!$A$7:$D$11,2,FALSE),0) | W27: =MAX(0.5,IFERROR(VLOOKUP(U27,Assumptions!$A$7:$D$11,3,FALSE),3)+IFERROR(VLOOKUP(U27,Assumptions!$A$7:$D$11,4,FALSE),8)/2-IF(AN27="",0,YEAR(TODAY())-AN27)) | X27: =T27*V27/(1+Assumptions!$B$3)^W27 | Y27: =IF(T27=0,"",ROUND(X27/T27*100,1)) | Z27: =X27*Assumptions!$B$4 | AA27: =IF(T27=0,"",ROUND(Z27/T27*100,1)) | AB27: =X27-Z27 | AC27: =IF(T27=0,"",ROUND((X27-Z27)/T27*100,1)) | AD27: UNKNOWN | AE27: https://credibilita.com.br/wp-content/uploads/2025/09/Relacao-Credores-29.04.2026.pdf | AF27: p1 r23 | AG27: p1: R$ 8.354.815,13 | AH27: UNKNOWN | AJ27: OK_NO_TOTALS | AK27: 5057720-48.2025.8.24.0023 | AL27: TJ | AN27: 2025 | AO27: live case, no plan document yet | AP27: SAO PAULO | AQ27: SP | AR27: Comércio atacadista especializado em outros produtos intermediários não especificados anteriormente | AS27: DEMAIS | AT27: MID-MARKET | AU27: 00802235 | AV27: 1 | AW27: ROWS:p1r23 UNRECONCILED_SOURCE VALUE_COL:Valor_Após_Analise
A28: IPESA DO BRASIL COMERCIO DE PRODUTOS PLASTICOS LTDA | B28: 8353250 | D28: NEW | I28: Virginia Kumvich | J28: Diretora Comercial, de Negócios & Estratégia | K28: (11) 5524-2877 | P28: Pedro Santos | Q28: Financial Analyst | T28: 8353250 | U28: B | V28: =IFERROR(VLOOKUP(U28,Assumptions!$A$7:$D$11,2,FALSE),0) | W28: =MAX(0.5,IFERROR(VLOOKUP(U28,Assumptions!$A$7:$D$11,3,FALSE),3)+IFERROR(VLOOKUP(U28,Assumptions!$A$7:$D$11,4,FALSE),8)/2-IF(AN28="",0,YEAR(TODAY())-AN28)) | X28: =T28*V28/(1+Assumptions!$B$3)^W28 | Y28: =IF(T28=0,"",ROUND(X28/T28*100,1)) | Z28: =X28*Assumptions!$B$4 | AA28: =IF(T28=0,"",ROUND(Z28/T28*100,1)) | AB28: =X28-Z28 | AC28: =IF(T28=0,"",ROUND((X28-Z28)/T28*100,1)) | AD28: UNKNOWN | AE28: https://credibilita.com.br/wp-content/uploads/2025/09/Relacao-Credores-29.04.2026.pdf | AF28: p1 r27 | AG28: p1: R$ 8.353.250,00 | AH28: UNKNOWN | AJ28: OK_NO_TOTALS | AK28: 5057720-48.2025.8.24.0023 | AL28: TJ | AN28: 2025 | AO28: live case, no plan document yet | AP28: SAO PAULO | AQ28: SP | AR28: Comércio atacadista especializado em outros produtos intermediários não especificados anteriormente | AS28: DEMAIS | AT28: MID-MARKET | AU28: 05607230 | AV28: 1 | AW28: ROWS:p1r27 UNRECONCILED_SOURCE VALUE_COL:Valor_Após_Analise
A29: MINERACAO AURORA LTDA | B29: 8433590 | C29: CONSTRUTORA ANDRADE GUEDES LDTA – Diligence Administração em Recuperação Judicial e Falência | D29: NEW | I29: Jorge Ferraz | J29: Administrator | K29: (81) 3972-4964 | P29: Raphael Calafange | Q29: Sales Manager | T29: 8433590 | U29: C | V29: =IFERROR(VLOOKUP(U29,Assumptions!$A$7:$D$11,2,FALSE),0) | W29: =MAX(0.5,IFERROR(VLOOKUP(U29,Assumptions!$A$7:$D$11,3,FALSE),3)+IFERROR(VLOOKUP(U29,Assumptions!$A$7:$D$11,4,FALSE),8)/2-IF(AN29="",0,YEAR(TODAY())-AN29)) | X29: =T29*V29/(1+Assumptions!$B$3)^W29 | Y29: =IF(T29=0,"",ROUND(X29/T29*100,1)) | Z29: =X29*Assumptions!$B$4 | AA29: =IF(T29=0,"",ROUND(Z29/T29*100,1)) | AB29: =X29-Z29 | AC29: =IF(T29=0,"",ROUND((X29-Z29)/T29*100,1)) | AD29: ESTIMATED | AE29: https://diligence.adm.br/wp-content/plugins/download-attachments/includes/download.php?id=4599 | AF29: p10 r60 | AG29: p10: R$ 8.433.590,01 | AH29: AJ_LIST | AI29: 2024-06-25 | AJ29: OK_NO_TOTALS | AK29: 0000880-57.2020.8.17.2001 | AL29: TJPE | AM29: ACTIVE | AN29: 2020 | AO29: 6y since filing, no plan document | AP29: JABOATAO DOS GUARARAPES | AQ29: PE | AR29: Extração e britamento de pedras e outros materiais para construção e beneficiamento associado | AS29: DEMAIS | AT29: MID-MARKET | AU29: 10509915 | AV29: 1 | AW29: ALT_VALUE:R$2.710.146,67 ALT_VALUE:R$5.723.443,34 ROWS:p10r60 UNRECONCILED_SOURCE VALUE_COL:2ª_Lista
A30: DREYMOOR BRASIL COMERCIO DE FERTILIZANTES LTDA | B30: 15134865 | D30: NEW | I30: MAURICIO GIORDANI BODANESE | J30: Administrador | K30: (41) 3209-6613 | T30: 15134865 | U30: ? | V30: =IFERROR(VLOOKUP(U30,Assumptions!$A$7:$D$11,2,FALSE),0) | W30: =MAX(0.5,IFERROR(VLOOKUP(U30,Assumptions!$A$7:$D$11,3,FALSE),3)+IFERROR(VLOOKUP(U30,Assumptions!$A$7:$D$11,4,FALSE),8)/2-IF(AN30="",0,YEAR(TODAY())-AN30)) | X30: =T30*V30/(1+Assumptions!$B$3)^W30 | Y30: =IF(T30=0,"",ROUND(X30/T30*100,1)) | Z30: =X30*Assumptions!$B$4 | AA30: =IF(T30=0,"",ROUND(Z30/T30*100,1)) | AB30: =X30-Z30 | AC30: =IF(T30=0,"",ROUND((X30-Z30)/T30*100,1)) | AD30: UNKNOWN | AE30: https://scalzilliaj.com.br/sgc/download.php?file=files/processo_documento/processo_documento13183320052026_1_.pdf&nome=10 - QGC Provisório - atualizado até Maio de 2026 | AF30: p1 r9 | AG30: p1: R$ 15.134.865,10 | AH30: QGC | AJ30: OK_NO_TOTALS | AK30: (not printed) | AO30: RJ case number not identified on the document | AP30: CURITIBA | AQ30: PR | AR30: Comércio atacadista de defensivos agrícolas, adubos, fertilizantes e corretivos do solo | AS30: DEMAIS | AT30: MID-MARKET | AU30: 26419229 | AV30: 1 | AW30: CASE_NUMBER_MISSING ROWS:p1r9 UNRECONCILED_SOURCE VALUE_COL:Valor_Do_Crédito
A31: BOSCH HOME COMFORT DO BRASIL LTDA | B31: 5064633.8 | C31: REAL DISTRIBUIDORA ÚNICA RIO COMÉRCIO DE REFRIGERAÇÃO LTDA | D31: NEW | I31: Jaqueline Santos | J31: Finance Director Latam | K31: (92) 3301-5000 | O31: vanessa.idalgo@bosch-hcgroup.com | P31: Vanessa Leite | Q31: Gerente de Tesouraria, Finanças e Compliance | S31: vanessa.idalgo@bosch-hcgroup.com | T31: 5064633.8 | U31: B | V31: =IFERROR(VLOOKUP(U31,Assumptions!$A$7:$D$11,2,FALSE),0) | W31: =MAX(0.5,IFERROR(VLOOKUP(U31,Assumptions!$A$7:$D$11,3,FALSE),3)+IFERROR(VLOOKUP(U31,Assumptions!$A$7:$D$11,4,FALSE),8)/2-IF(AN31="",0,YEAR(TODAY())-AN31)) | X31: =T31*V31/(1+Assumptions!$B$3)^W31 | Y31: =IF(T31=0,"",ROUND(X31/T31*100,1)) | Z31: =X31*Assumptions!$B$4 | AA31: =IF(T31=0,"",ROUND(Z31/T31*100,1)) | AB31: =X31-Z31 | AC31: =IF(T31=0,"",ROUND((X31-Z31)/T31*100,1)) | AD31: UNKNOWN | AE31: https://inova-aj.com.br/wp-content/uploads/2026/08/1a-Relacao-de-Credores-Real.pdf | AF31: p1 r35 | AG31: p1: R$ 5.064.633,83 | AH31: AJ_LIST | AI31: 2023-06-05 | AJ31: OK | AK31: 0873061-47.2023.8.19.0001 | AL31: TJ | AN31: 2023 | AO31: live case, no plan document yet | AP31: MANAUS | AQ31: AM | AR31: Serviços combinados de escritório e apoio administrativo | AS31: DEMAIS | AT31: LARGE CORP | AU31: 33284522 | AV31: 1 | AW31: ALT_VALUE:R$3.682.536,03 ROWS:p1r35
